2025-04-22 18:06:00,318 ERROR scheduler Exception in Enqueue Events for Site library.localhost
Traceback (most recent call last):
  File "/home/pearl/alumnimgmtsystem/apps/frappe/frappe/utils/scheduler.py", line 117, in enqueue_events_for_site
    if is_scheduler_inactive():
       ^^^^^^^^^^^^^^^^^^^^^^^
  File "/home/pearl/alumnimgmtsystem/apps/frappe/frappe/utils/scheduler.py", line 161, in is_scheduler_inactive
    if is_scheduler_disabled(verbose=verbose):
       ^^^^^^^^^^^^^^^^^^^^^^^^^^^^^^^^^^^^^^
  File "/home/pearl/alumnimgmtsystem/apps/frappe/frappe/utils/scheduler.py", line 174, in is_scheduler_disabled
    frappe.db.get_single_value("System Settings", "enable_scheduler")
  File "/home/pearl/alumnimgmtsystem/apps/frappe/frappe/database/database.py", line 884, in get_single_value
    ).run()
      ^^^^^
  File "/home/pearl/alumnimgmtsystem/apps/frappe/frappe/query_builder/utils.py", line 80, in execute_query
    result = frappe.db.sql(query, params, *args, **kwargs)  # nosemgrep
             ^^^^^^^^^^^^^^^^^^^^^^^^^^^^^^^^^^^^^^^^^^^^^
  File "/home/pearl/alumnimgmtsystem/apps/frappe/frappe/database/database.py", line 237, in sql
    self.connect()
  File "/home/pearl/alumnimgmtsystem/apps/frappe/frappe/database/database.py", line 135, in connect
    self.get_connection()
  File "/home/pearl/alumnimgmtsystem/apps/frappe/frappe/database/mariadb/database.py", line 105, in get_connection
    conn = self._get_connection()
           ^^^^^^^^^^^^^^^^^^^^^^
  File "/home/pearl/alumnimgmtsystem/apps/frappe/frappe/database/mariadb/database.py", line 111, in _get_connection
    return self.create_connection()
           ^^^^^^^^^^^^^^^^^^^^^^^^
  File "/home/pearl/alumnimgmtsystem/apps/frappe/frappe/database/mariadb/database.py", line 114, in create_connection
    return pymysql.connect(**self.get_connection_settings())
           ^^^^^^^^^^^^^^^^^^^^^^^^^^^^^^^^^^^^^^^^^^^^^^^^^
  File "/home/pearl/alumnimgmtsystem/env/lib/python3.12/site-packages/pymysql/connections.py", line 361, in __init__
    self.connect()
  File "/home/pearl/alumnimgmtsystem/env/lib/python3.12/site-packages/pymysql/connections.py", line 669, in connect
    self._request_authentication()
  File "/home/pearl/alumnimgmtsystem/env/lib/python3.12/site-packages/pymysql/connections.py", line 957, in _request_authentication
    auth_packet = self._read_packet()
                  ^^^^^^^^^^^^^^^^^^^
  File "/home/pearl/alumnimgmtsystem/env/lib/python3.12/site-packages/pymysql/connections.py", line 775, in _read_packet
    packet.raise_for_error()
  File "/home/pearl/alumnimgmtsystem/env/lib/python3.12/site-packages/pymysql/protocol.py", line 219, in raise_for_error
    err.raise_mysql_exception(self._data)
  File "/home/pearl/alumnimgmtsystem/env/lib/python3.12/site-packages/pymysql/err.py", line 150, in raise_mysql_exception
    raise errorclass(errno, errval)
pymysql.err.OperationalError: (1045, "Access denied for user '_9a54aa6450761df8'@'localhost' (using password: YES)")
2025-04-22 18:10:00,329 ERROR scheduler Exception in Enqueue Events for Site library.localhost
Traceback (most recent call last):
  File "/home/pearl/alumnimgmtsystem/apps/frappe/frappe/utils/scheduler.py", line 117, in enqueue_events_for_site
    if is_scheduler_inactive():
       ^^^^^^^^^^^^^^^^^^^^^^^
  File "/home/pearl/alumnimgmtsystem/apps/frappe/frappe/utils/scheduler.py", line 161, in is_scheduler_inactive
    if is_scheduler_disabled(verbose=verbose):
       ^^^^^^^^^^^^^^^^^^^^^^^^^^^^^^^^^^^^^^
  File "/home/pearl/alumnimgmtsystem/apps/frappe/frappe/utils/scheduler.py", line 174, in is_scheduler_disabled
    frappe.db.get_single_value("System Settings", "enable_scheduler")
  File "/home/pearl/alumnimgmtsystem/apps/frappe/frappe/database/database.py", line 884, in get_single_value
    ).run()
      ^^^^^
  File "/home/pearl/alumnimgmtsystem/apps/frappe/frappe/query_builder/utils.py", line 80, in execute_query
    result = frappe.db.sql(query, params, *args, **kwargs)  # nosemgrep
             ^^^^^^^^^^^^^^^^^^^^^^^^^^^^^^^^^^^^^^^^^^^^^
  File "/home/pearl/alumnimgmtsystem/apps/frappe/frappe/database/database.py", line 237, in sql
    self.connect()
  File "/home/pearl/alumnimgmtsystem/apps/frappe/frappe/database/database.py", line 135, in connect
    self.get_connection()
  File "/home/pearl/alumnimgmtsystem/apps/frappe/frappe/database/mariadb/database.py", line 105, in get_connection
    conn = self._get_connection()
           ^^^^^^^^^^^^^^^^^^^^^^
  File "/home/pearl/alumnimgmtsystem/apps/frappe/frappe/database/mariadb/database.py", line 111, in _get_connection
    return self.create_connection()
           ^^^^^^^^^^^^^^^^^^^^^^^^
  File "/home/pearl/alumnimgmtsystem/apps/frappe/frappe/database/mariadb/database.py", line 114, in create_connection
    return pymysql.connect(**self.get_connection_settings())
           ^^^^^^^^^^^^^^^^^^^^^^^^^^^^^^^^^^^^^^^^^^^^^^^^^
  File "/home/pearl/alumnimgmtsystem/env/lib/python3.12/site-packages/pymysql/connections.py", line 361, in __init__
    self.connect()
  File "/home/pearl/alumnimgmtsystem/env/lib/python3.12/site-packages/pymysql/connections.py", line 669, in connect
    self._request_authentication()
  File "/home/pearl/alumnimgmtsystem/env/lib/python3.12/site-packages/pymysql/connections.py", line 957, in _request_authentication
    auth_packet = self._read_packet()
                  ^^^^^^^^^^^^^^^^^^^
  File "/home/pearl/alumnimgmtsystem/env/lib/python3.12/site-packages/pymysql/connections.py", line 775, in _read_packet
    packet.raise_for_error()
  File "/home/pearl/alumnimgmtsystem/env/lib/python3.12/site-packages/pymysql/protocol.py", line 219, in raise_for_error
    err.raise_mysql_exception(self._data)
  File "/home/pearl/alumnimgmtsystem/env/lib/python3.12/site-packages/pymysql/err.py", line 150, in raise_mysql_exception
    raise errorclass(errno, errval)
pymysql.err.OperationalError: (1045, "Access denied for user '_9a54aa6450761df8'@'localhost' (using password: YES)")
2025-04-22 18:14:00,381 ERROR scheduler Exception in Enqueue Events for Site library.localhost
Traceback (most recent call last):
  File "/home/pearl/alumnimgmtsystem/apps/frappe/frappe/utils/scheduler.py", line 117, in enqueue_events_for_site
    if is_scheduler_inactive():
       ^^^^^^^^^^^^^^^^^^^^^^^
  File "/home/pearl/alumnimgmtsystem/apps/frappe/frappe/utils/scheduler.py", line 161, in is_scheduler_inactive
    if is_scheduler_disabled(verbose=verbose):
       ^^^^^^^^^^^^^^^^^^^^^^^^^^^^^^^^^^^^^^
  File "/home/pearl/alumnimgmtsystem/apps/frappe/frappe/utils/scheduler.py", line 174, in is_scheduler_disabled
    frappe.db.get_single_value("System Settings", "enable_scheduler")
  File "/home/pearl/alumnimgmtsystem/apps/frappe/frappe/database/database.py", line 884, in get_single_value
    ).run()
      ^^^^^
  File "/home/pearl/alumnimgmtsystem/apps/frappe/frappe/query_builder/utils.py", line 80, in execute_query
    result = frappe.db.sql(query, params, *args, **kwargs)  # nosemgrep
             ^^^^^^^^^^^^^^^^^^^^^^^^^^^^^^^^^^^^^^^^^^^^^
  File "/home/pearl/alumnimgmtsystem/apps/frappe/frappe/database/database.py", line 237, in sql
    self.connect()
  File "/home/pearl/alumnimgmtsystem/apps/frappe/frappe/database/database.py", line 135, in connect
    self.get_connection()
  File "/home/pearl/alumnimgmtsystem/apps/frappe/frappe/database/mariadb/database.py", line 105, in get_connection
    conn = self._get_connection()
           ^^^^^^^^^^^^^^^^^^^^^^
  File "/home/pearl/alumnimgmtsystem/apps/frappe/frappe/database/mariadb/database.py", line 111, in _get_connection
    return self.create_connection()
           ^^^^^^^^^^^^^^^^^^^^^^^^
  File "/home/pearl/alumnimgmtsystem/apps/frappe/frappe/database/mariadb/database.py", line 114, in create_connection
    return pymysql.connect(**self.get_connection_settings())
           ^^^^^^^^^^^^^^^^^^^^^^^^^^^^^^^^^^^^^^^^^^^^^^^^^
  File "/home/pearl/alumnimgmtsystem/env/lib/python3.12/site-packages/pymysql/connections.py", line 361, in __init__
    self.connect()
  File "/home/pearl/alumnimgmtsystem/env/lib/python3.12/site-packages/pymysql/connections.py", line 669, in connect
    self._request_authentication()
  File "/home/pearl/alumnimgmtsystem/env/lib/python3.12/site-packages/pymysql/connections.py", line 957, in _request_authentication
    auth_packet = self._read_packet()
                  ^^^^^^^^^^^^^^^^^^^
  File "/home/pearl/alumnimgmtsystem/env/lib/python3.12/site-packages/pymysql/connections.py", line 775, in _read_packet
    packet.raise_for_error()
  File "/home/pearl/alumnimgmtsystem/env/lib/python3.12/site-packages/pymysql/protocol.py", line 219, in raise_for_error
    err.raise_mysql_exception(self._data)
  File "/home/pearl/alumnimgmtsystem/env/lib/python3.12/site-packages/pymysql/err.py", line 150, in raise_mysql_exception
    raise errorclass(errno, errval)
pymysql.err.OperationalError: (1045, "Access denied for user '_9a54aa6450761df8'@'localhost' (using password: YES)")
2025-04-22 18:18:00,506 ERROR scheduler Exception in Enqueue Events for Site library.localhost
Traceback (most recent call last):
  File "/home/pearl/alumnimgmtsystem/apps/frappe/frappe/utils/scheduler.py", line 117, in enqueue_events_for_site
    if is_scheduler_inactive():
       ^^^^^^^^^^^^^^^^^^^^^^^
  File "/home/pearl/alumnimgmtsystem/apps/frappe/frappe/utils/scheduler.py", line 161, in is_scheduler_inactive
    if is_scheduler_disabled(verbose=verbose):
       ^^^^^^^^^^^^^^^^^^^^^^^^^^^^^^^^^^^^^^
  File "/home/pearl/alumnimgmtsystem/apps/frappe/frappe/utils/scheduler.py", line 174, in is_scheduler_disabled
    frappe.db.get_single_value("System Settings", "enable_scheduler")
  File "/home/pearl/alumnimgmtsystem/apps/frappe/frappe/database/database.py", line 884, in get_single_value
    ).run()
      ^^^^^
  File "/home/pearl/alumnimgmtsystem/apps/frappe/frappe/query_builder/utils.py", line 80, in execute_query
    result = frappe.db.sql(query, params, *args, **kwargs)  # nosemgrep
             ^^^^^^^^^^^^^^^^^^^^^^^^^^^^^^^^^^^^^^^^^^^^^
  File "/home/pearl/alumnimgmtsystem/apps/frappe/frappe/database/database.py", line 237, in sql
    self.connect()
  File "/home/pearl/alumnimgmtsystem/apps/frappe/frappe/database/database.py", line 135, in connect
    self.get_connection()
  File "/home/pearl/alumnimgmtsystem/apps/frappe/frappe/database/mariadb/database.py", line 105, in get_connection
    conn = self._get_connection()
           ^^^^^^^^^^^^^^^^^^^^^^
  File "/home/pearl/alumnimgmtsystem/apps/frappe/frappe/database/mariadb/database.py", line 111, in _get_connection
    return self.create_connection()
           ^^^^^^^^^^^^^^^^^^^^^^^^
  File "/home/pearl/alumnimgmtsystem/apps/frappe/frappe/database/mariadb/database.py", line 114, in create_connection
    return pymysql.connect(**self.get_connection_settings())
           ^^^^^^^^^^^^^^^^^^^^^^^^^^^^^^^^^^^^^^^^^^^^^^^^^
  File "/home/pearl/alumnimgmtsystem/env/lib/python3.12/site-packages/pymysql/connections.py", line 361, in __init__
    self.connect()
  File "/home/pearl/alumnimgmtsystem/env/lib/python3.12/site-packages/pymysql/connections.py", line 669, in connect
    self._request_authentication()
  File "/home/pearl/alumnimgmtsystem/env/lib/python3.12/site-packages/pymysql/connections.py", line 957, in _request_authentication
    auth_packet = self._read_packet()
                  ^^^^^^^^^^^^^^^^^^^
  File "/home/pearl/alumnimgmtsystem/env/lib/python3.12/site-packages/pymysql/connections.py", line 775, in _read_packet
    packet.raise_for_error()
  File "/home/pearl/alumnimgmtsystem/env/lib/python3.12/site-packages/pymysql/protocol.py", line 219, in raise_for_error
    err.raise_mysql_exception(self._data)
  File "/home/pearl/alumnimgmtsystem/env/lib/python3.12/site-packages/pymysql/err.py", line 150, in raise_mysql_exception
    raise errorclass(errno, errval)
pymysql.err.OperationalError: (1045, "Access denied for user '_9a54aa6450761df8'@'localhost' (using password: YES)")
2025-04-22 18:22:00,515 ERROR scheduler Exception in Enqueue Events for Site library.localhost
Traceback (most recent call last):
  File "/home/pearl/alumnimgmtsystem/apps/frappe/frappe/utils/scheduler.py", line 117, in enqueue_events_for_site
    if is_scheduler_inactive():
       ^^^^^^^^^^^^^^^^^^^^^^^
  File "/home/pearl/alumnimgmtsystem/apps/frappe/frappe/utils/scheduler.py", line 161, in is_scheduler_inactive
    if is_scheduler_disabled(verbose=verbose):
       ^^^^^^^^^^^^^^^^^^^^^^^^^^^^^^^^^^^^^^
  File "/home/pearl/alumnimgmtsystem/apps/frappe/frappe/utils/scheduler.py", line 174, in is_scheduler_disabled
    frappe.db.get_single_value("System Settings", "enable_scheduler")
  File "/home/pearl/alumnimgmtsystem/apps/frappe/frappe/database/database.py", line 884, in get_single_value
    ).run()
      ^^^^^
  File "/home/pearl/alumnimgmtsystem/apps/frappe/frappe/query_builder/utils.py", line 80, in execute_query
    result = frappe.db.sql(query, params, *args, **kwargs)  # nosemgrep
             ^^^^^^^^^^^^^^^^^^^^^^^^^^^^^^^^^^^^^^^^^^^^^
  File "/home/pearl/alumnimgmtsystem/apps/frappe/frappe/database/database.py", line 237, in sql
    self.connect()
  File "/home/pearl/alumnimgmtsystem/apps/frappe/frappe/database/database.py", line 135, in connect
    self.get_connection()
  File "/home/pearl/alumnimgmtsystem/apps/frappe/frappe/database/mariadb/database.py", line 105, in get_connection
    conn = self._get_connection()
           ^^^^^^^^^^^^^^^^^^^^^^
  File "/home/pearl/alumnimgmtsystem/apps/frappe/frappe/database/mariadb/database.py", line 111, in _get_connection
    return self.create_connection()
           ^^^^^^^^^^^^^^^^^^^^^^^^
  File "/home/pearl/alumnimgmtsystem/apps/frappe/frappe/database/mariadb/database.py", line 114, in create_connection
    return pymysql.connect(**self.get_connection_settings())
           ^^^^^^^^^^^^^^^^^^^^^^^^^^^^^^^^^^^^^^^^^^^^^^^^^
  File "/home/pearl/alumnimgmtsystem/env/lib/python3.12/site-packages/pymysql/connections.py", line 361, in __init__
    self.connect()
  File "/home/pearl/alumnimgmtsystem/env/lib/python3.12/site-packages/pymysql/connections.py", line 669, in connect
    self._request_authentication()
  File "/home/pearl/alumnimgmtsystem/env/lib/python3.12/site-packages/pymysql/connections.py", line 957, in _request_authentication
    auth_packet = self._read_packet()
                  ^^^^^^^^^^^^^^^^^^^
  File "/home/pearl/alumnimgmtsystem/env/lib/python3.12/site-packages/pymysql/connections.py", line 775, in _read_packet
    packet.raise_for_error()
  File "/home/pearl/alumnimgmtsystem/env/lib/python3.12/site-packages/pymysql/protocol.py", line 219, in raise_for_error
    err.raise_mysql_exception(self._data)
  File "/home/pearl/alumnimgmtsystem/env/lib/python3.12/site-packages/pymysql/err.py", line 150, in raise_mysql_exception
    raise errorclass(errno, errval)
pymysql.err.OperationalError: (1045, "Access denied for user '_9a54aa6450761df8'@'localhost' (using password: YES)")
2025-04-22 18:26:00,580 ERROR scheduler Exception in Enqueue Events for Site library.localhost
Traceback (most recent call last):
  File "/home/pearl/alumnimgmtsystem/apps/frappe/frappe/utils/scheduler.py", line 117, in enqueue_events_for_site
    if is_scheduler_inactive():
       ^^^^^^^^^^^^^^^^^^^^^^^
  File "/home/pearl/alumnimgmtsystem/apps/frappe/frappe/utils/scheduler.py", line 161, in is_scheduler_inactive
    if is_scheduler_disabled(verbose=verbose):
       ^^^^^^^^^^^^^^^^^^^^^^^^^^^^^^^^^^^^^^
  File "/home/pearl/alumnimgmtsystem/apps/frappe/frappe/utils/scheduler.py", line 174, in is_scheduler_disabled
    frappe.db.get_single_value("System Settings", "enable_scheduler")
  File "/home/pearl/alumnimgmtsystem/apps/frappe/frappe/database/database.py", line 884, in get_single_value
    ).run()
      ^^^^^
  File "/home/pearl/alumnimgmtsystem/apps/frappe/frappe/query_builder/utils.py", line 80, in execute_query
    result = frappe.db.sql(query, params, *args, **kwargs)  # nosemgrep
             ^^^^^^^^^^^^^^^^^^^^^^^^^^^^^^^^^^^^^^^^^^^^^
  File "/home/pearl/alumnimgmtsystem/apps/frappe/frappe/database/database.py", line 237, in sql
    self.connect()
  File "/home/pearl/alumnimgmtsystem/apps/frappe/frappe/database/database.py", line 135, in connect
    self.get_connection()
  File "/home/pearl/alumnimgmtsystem/apps/frappe/frappe/database/mariadb/database.py", line 105, in get_connection
    conn = self._get_connection()
           ^^^^^^^^^^^^^^^^^^^^^^
  File "/home/pearl/alumnimgmtsystem/apps/frappe/frappe/database/mariadb/database.py", line 111, in _get_connection
    return self.create_connection()
           ^^^^^^^^^^^^^^^^^^^^^^^^
  File "/home/pearl/alumnimgmtsystem/apps/frappe/frappe/database/mariadb/database.py", line 114, in create_connection
    return pymysql.connect(**self.get_connection_settings())
           ^^^^^^^^^^^^^^^^^^^^^^^^^^^^^^^^^^^^^^^^^^^^^^^^^
  File "/home/pearl/alumnimgmtsystem/env/lib/python3.12/site-packages/pymysql/connections.py", line 361, in __init__
    self.connect()
  File "/home/pearl/alumnimgmtsystem/env/lib/python3.12/site-packages/pymysql/connections.py", line 669, in connect
    self._request_authentication()
  File "/home/pearl/alumnimgmtsystem/env/lib/python3.12/site-packages/pymysql/connections.py", line 957, in _request_authentication
    auth_packet = self._read_packet()
                  ^^^^^^^^^^^^^^^^^^^
  File "/home/pearl/alumnimgmtsystem/env/lib/python3.12/site-packages/pymysql/connections.py", line 775, in _read_packet
    packet.raise_for_error()
  File "/home/pearl/alumnimgmtsystem/env/lib/python3.12/site-packages/pymysql/protocol.py", line 219, in raise_for_error
    err.raise_mysql_exception(self._data)
  File "/home/pearl/alumnimgmtsystem/env/lib/python3.12/site-packages/pymysql/err.py", line 150, in raise_mysql_exception
    raise errorclass(errno, errval)
pymysql.err.OperationalError: (1045, "Access denied for user '_9a54aa6450761df8'@'localhost' (using password: YES)")
2025-04-22 18:30:00,624 ERROR scheduler Exception in Enqueue Events for Site library.localhost
Traceback (most recent call last):
  File "/home/pearl/alumnimgmtsystem/apps/frappe/frappe/utils/scheduler.py", line 117, in enqueue_events_for_site
    if is_scheduler_inactive():
       ^^^^^^^^^^^^^^^^^^^^^^^
  File "/home/pearl/alumnimgmtsystem/apps/frappe/frappe/utils/scheduler.py", line 161, in is_scheduler_inactive
    if is_scheduler_disabled(verbose=verbose):
       ^^^^^^^^^^^^^^^^^^^^^^^^^^^^^^^^^^^^^^
  File "/home/pearl/alumnimgmtsystem/apps/frappe/frappe/utils/scheduler.py", line 174, in is_scheduler_disabled
    frappe.db.get_single_value("System Settings", "enable_scheduler")
  File "/home/pearl/alumnimgmtsystem/apps/frappe/frappe/database/database.py", line 884, in get_single_value
    ).run()
      ^^^^^
  File "/home/pearl/alumnimgmtsystem/apps/frappe/frappe/query_builder/utils.py", line 80, in execute_query
    result = frappe.db.sql(query, params, *args, **kwargs)  # nosemgrep
             ^^^^^^^^^^^^^^^^^^^^^^^^^^^^^^^^^^^^^^^^^^^^^
  File "/home/pearl/alumnimgmtsystem/apps/frappe/frappe/database/database.py", line 237, in sql
    self.connect()
  File "/home/pearl/alumnimgmtsystem/apps/frappe/frappe/database/database.py", line 135, in connect
    self.get_connection()
  File "/home/pearl/alumnimgmtsystem/apps/frappe/frappe/database/mariadb/database.py", line 105, in get_connection
    conn = self._get_connection()
           ^^^^^^^^^^^^^^^^^^^^^^
  File "/home/pearl/alumnimgmtsystem/apps/frappe/frappe/database/mariadb/database.py", line 111, in _get_connection
    return self.create_connection()
           ^^^^^^^^^^^^^^^^^^^^^^^^
  File "/home/pearl/alumnimgmtsystem/apps/frappe/frappe/database/mariadb/database.py", line 114, in create_connection
    return pymysql.connect(**self.get_connection_settings())
           ^^^^^^^^^^^^^^^^^^^^^^^^^^^^^^^^^^^^^^^^^^^^^^^^^
  File "/home/pearl/alumnimgmtsystem/env/lib/python3.12/site-packages/pymysql/connections.py", line 361, in __init__
    self.connect()
  File "/home/pearl/alumnimgmtsystem/env/lib/python3.12/site-packages/pymysql/connections.py", line 669, in connect
    self._request_authentication()
  File "/home/pearl/alumnimgmtsystem/env/lib/python3.12/site-packages/pymysql/connections.py", line 957, in _request_authentication
    auth_packet = self._read_packet()
                  ^^^^^^^^^^^^^^^^^^^
  File "/home/pearl/alumnimgmtsystem/env/lib/python3.12/site-packages/pymysql/connections.py", line 775, in _read_packet
    packet.raise_for_error()
  File "/home/pearl/alumnimgmtsystem/env/lib/python3.12/site-packages/pymysql/protocol.py", line 219, in raise_for_error
    err.raise_mysql_exception(self._data)
  File "/home/pearl/alumnimgmtsystem/env/lib/python3.12/site-packages/pymysql/err.py", line 150, in raise_mysql_exception
    raise errorclass(errno, errval)
pymysql.err.OperationalError: (1045, "Access denied for user '_9a54aa6450761df8'@'localhost' (using password: YES)")
2025-04-22 18:34:00,757 ERROR scheduler Exception in Enqueue Events for Site library.localhost
Traceback (most recent call last):
  File "/home/pearl/alumnimgmtsystem/apps/frappe/frappe/utils/scheduler.py", line 117, in enqueue_events_for_site
    if is_scheduler_inactive():
       ^^^^^^^^^^^^^^^^^^^^^^^
  File "/home/pearl/alumnimgmtsystem/apps/frappe/frappe/utils/scheduler.py", line 161, in is_scheduler_inactive
    if is_scheduler_disabled(verbose=verbose):
       ^^^^^^^^^^^^^^^^^^^^^^^^^^^^^^^^^^^^^^
  File "/home/pearl/alumnimgmtsystem/apps/frappe/frappe/utils/scheduler.py", line 174, in is_scheduler_disabled
    frappe.db.get_single_value("System Settings", "enable_scheduler")
  File "/home/pearl/alumnimgmtsystem/apps/frappe/frappe/database/database.py", line 884, in get_single_value
    ).run()
      ^^^^^
  File "/home/pearl/alumnimgmtsystem/apps/frappe/frappe/query_builder/utils.py", line 80, in execute_query
    result = frappe.db.sql(query, params, *args, **kwargs)  # nosemgrep
             ^^^^^^^^^^^^^^^^^^^^^^^^^^^^^^^^^^^^^^^^^^^^^
  File "/home/pearl/alumnimgmtsystem/apps/frappe/frappe/database/database.py", line 237, in sql
    self.connect()
  File "/home/pearl/alumnimgmtsystem/apps/frappe/frappe/database/database.py", line 135, in connect
    self.get_connection()
  File "/home/pearl/alumnimgmtsystem/apps/frappe/frappe/database/mariadb/database.py", line 105, in get_connection
    conn = self._get_connection()
           ^^^^^^^^^^^^^^^^^^^^^^
  File "/home/pearl/alumnimgmtsystem/apps/frappe/frappe/database/mariadb/database.py", line 111, in _get_connection
    return self.create_connection()
           ^^^^^^^^^^^^^^^^^^^^^^^^
  File "/home/pearl/alumnimgmtsystem/apps/frappe/frappe/database/mariadb/database.py", line 114, in create_connection
    return pymysql.connect(**self.get_connection_settings())
           ^^^^^^^^^^^^^^^^^^^^^^^^^^^^^^^^^^^^^^^^^^^^^^^^^
  File "/home/pearl/alumnimgmtsystem/env/lib/python3.12/site-packages/pymysql/connections.py", line 361, in __init__
    self.connect()
  File "/home/pearl/alumnimgmtsystem/env/lib/python3.12/site-packages/pymysql/connections.py", line 669, in connect
    self._request_authentication()
  File "/home/pearl/alumnimgmtsystem/env/lib/python3.12/site-packages/pymysql/connections.py", line 957, in _request_authentication
    auth_packet = self._read_packet()
                  ^^^^^^^^^^^^^^^^^^^
  File "/home/pearl/alumnimgmtsystem/env/lib/python3.12/site-packages/pymysql/connections.py", line 775, in _read_packet
    packet.raise_for_error()
  File "/home/pearl/alumnimgmtsystem/env/lib/python3.12/site-packages/pymysql/protocol.py", line 219, in raise_for_error
    err.raise_mysql_exception(self._data)
  File "/home/pearl/alumnimgmtsystem/env/lib/python3.12/site-packages/pymysql/err.py", line 150, in raise_mysql_exception
    raise errorclass(errno, errval)
pymysql.err.OperationalError: (1045, "Access denied for user '_9a54aa6450761df8'@'localhost' (using password: YES)")
2025-04-22 18:38:00,767 ERROR scheduler Exception in Enqueue Events for Site library.localhost
Traceback (most recent call last):
  File "/home/pearl/alumnimgmtsystem/apps/frappe/frappe/utils/scheduler.py", line 117, in enqueue_events_for_site
    if is_scheduler_inactive():
       ^^^^^^^^^^^^^^^^^^^^^^^
  File "/home/pearl/alumnimgmtsystem/apps/frappe/frappe/utils/scheduler.py", line 161, in is_scheduler_inactive
    if is_scheduler_disabled(verbose=verbose):
       ^^^^^^^^^^^^^^^^^^^^^^^^^^^^^^^^^^^^^^
  File "/home/pearl/alumnimgmtsystem/apps/frappe/frappe/utils/scheduler.py", line 174, in is_scheduler_disabled
    frappe.db.get_single_value("System Settings", "enable_scheduler")
  File "/home/pearl/alumnimgmtsystem/apps/frappe/frappe/database/database.py", line 884, in get_single_value
    ).run()
      ^^^^^
  File "/home/pearl/alumnimgmtsystem/apps/frappe/frappe/query_builder/utils.py", line 80, in execute_query
    result = frappe.db.sql(query, params, *args, **kwargs)  # nosemgrep
             ^^^^^^^^^^^^^^^^^^^^^^^^^^^^^^^^^^^^^^^^^^^^^
  File "/home/pearl/alumnimgmtsystem/apps/frappe/frappe/database/database.py", line 237, in sql
    self.connect()
  File "/home/pearl/alumnimgmtsystem/apps/frappe/frappe/database/database.py", line 135, in connect
    self.get_connection()
  File "/home/pearl/alumnimgmtsystem/apps/frappe/frappe/database/mariadb/database.py", line 105, in get_connection
    conn = self._get_connection()
           ^^^^^^^^^^^^^^^^^^^^^^
  File "/home/pearl/alumnimgmtsystem/apps/frappe/frappe/database/mariadb/database.py", line 111, in _get_connection
    return self.create_connection()
           ^^^^^^^^^^^^^^^^^^^^^^^^
  File "/home/pearl/alumnimgmtsystem/apps/frappe/frappe/database/mariadb/database.py", line 114, in create_connection
    return pymysql.connect(**self.get_connection_settings())
           ^^^^^^^^^^^^^^^^^^^^^^^^^^^^^^^^^^^^^^^^^^^^^^^^^
  File "/home/pearl/alumnimgmtsystem/env/lib/python3.12/site-packages/pymysql/connections.py", line 361, in __init__
    self.connect()
  File "/home/pearl/alumnimgmtsystem/env/lib/python3.12/site-packages/pymysql/connections.py", line 669, in connect
    self._request_authentication()
  File "/home/pearl/alumnimgmtsystem/env/lib/python3.12/site-packages/pymysql/connections.py", line 957, in _request_authentication
    auth_packet = self._read_packet()
                  ^^^^^^^^^^^^^^^^^^^
  File "/home/pearl/alumnimgmtsystem/env/lib/python3.12/site-packages/pymysql/connections.py", line 775, in _read_packet
    packet.raise_for_error()
  File "/home/pearl/alumnimgmtsystem/env/lib/python3.12/site-packages/pymysql/protocol.py", line 219, in raise_for_error
    err.raise_mysql_exception(self._data)
  File "/home/pearl/alumnimgmtsystem/env/lib/python3.12/site-packages/pymysql/err.py", line 150, in raise_mysql_exception
    raise errorclass(errno, errval)
pymysql.err.OperationalError: (1045, "Access denied for user '_9a54aa6450761df8'@'localhost' (using password: YES)")
2025-04-22 18:42:00,869 ERROR scheduler Exception in Enqueue Events for Site library.localhost
Traceback (most recent call last):
  File "/home/pearl/alumnimgmtsystem/apps/frappe/frappe/utils/scheduler.py", line 117, in enqueue_events_for_site
    if is_scheduler_inactive():
       ^^^^^^^^^^^^^^^^^^^^^^^
  File "/home/pearl/alumnimgmtsystem/apps/frappe/frappe/utils/scheduler.py", line 161, in is_scheduler_inactive
    if is_scheduler_disabled(verbose=verbose):
       ^^^^^^^^^^^^^^^^^^^^^^^^^^^^^^^^^^^^^^
  File "/home/pearl/alumnimgmtsystem/apps/frappe/frappe/utils/scheduler.py", line 174, in is_scheduler_disabled
    frappe.db.get_single_value("System Settings", "enable_scheduler")
  File "/home/pearl/alumnimgmtsystem/apps/frappe/frappe/database/database.py", line 884, in get_single_value
    ).run()
      ^^^^^
  File "/home/pearl/alumnimgmtsystem/apps/frappe/frappe/query_builder/utils.py", line 80, in execute_query
    result = frappe.db.sql(query, params, *args, **kwargs)  # nosemgrep
             ^^^^^^^^^^^^^^^^^^^^^^^^^^^^^^^^^^^^^^^^^^^^^
  File "/home/pearl/alumnimgmtsystem/apps/frappe/frappe/database/database.py", line 237, in sql
    self.connect()
  File "/home/pearl/alumnimgmtsystem/apps/frappe/frappe/database/database.py", line 135, in connect
    self.get_connection()
  File "/home/pearl/alumnimgmtsystem/apps/frappe/frappe/database/mariadb/database.py", line 105, in get_connection
    conn = self._get_connection()
           ^^^^^^^^^^^^^^^^^^^^^^
  File "/home/pearl/alumnimgmtsystem/apps/frappe/frappe/database/mariadb/database.py", line 111, in _get_connection
    return self.create_connection()
           ^^^^^^^^^^^^^^^^^^^^^^^^
  File "/home/pearl/alumnimgmtsystem/apps/frappe/frappe/database/mariadb/database.py", line 114, in create_connection
    return pymysql.connect(**self.get_connection_settings())
           ^^^^^^^^^^^^^^^^^^^^^^^^^^^^^^^^^^^^^^^^^^^^^^^^^
  File "/home/pearl/alumnimgmtsystem/env/lib/python3.12/site-packages/pymysql/connections.py", line 361, in __init__
    self.connect()
  File "/home/pearl/alumnimgmtsystem/env/lib/python3.12/site-packages/pymysql/connections.py", line 669, in connect
    self._request_authentication()
  File "/home/pearl/alumnimgmtsystem/env/lib/python3.12/site-packages/pymysql/connections.py", line 957, in _request_authentication
    auth_packet = self._read_packet()
                  ^^^^^^^^^^^^^^^^^^^
  File "/home/pearl/alumnimgmtsystem/env/lib/python3.12/site-packages/pymysql/connections.py", line 775, in _read_packet
    packet.raise_for_error()
  File "/home/pearl/alumnimgmtsystem/env/lib/python3.12/site-packages/pymysql/protocol.py", line 219, in raise_for_error
    err.raise_mysql_exception(self._data)
  File "/home/pearl/alumnimgmtsystem/env/lib/python3.12/site-packages/pymysql/err.py", line 150, in raise_mysql_exception
    raise errorclass(errno, errval)
pymysql.err.OperationalError: (1045, "Access denied for user '_9a54aa6450761df8'@'localhost' (using password: YES)")
2025-04-22 18:46:00,934 ERROR scheduler Exception in Enqueue Events for Site library.localhost
Traceback (most recent call last):
  File "/home/pearl/alumnimgmtsystem/apps/frappe/frappe/utils/scheduler.py", line 117, in enqueue_events_for_site
    if is_scheduler_inactive():
       ^^^^^^^^^^^^^^^^^^^^^^^
  File "/home/pearl/alumnimgmtsystem/apps/frappe/frappe/utils/scheduler.py", line 161, in is_scheduler_inactive
    if is_scheduler_disabled(verbose=verbose):
       ^^^^^^^^^^^^^^^^^^^^^^^^^^^^^^^^^^^^^^
  File "/home/pearl/alumnimgmtsystem/apps/frappe/frappe/utils/scheduler.py", line 174, in is_scheduler_disabled
    frappe.db.get_single_value("System Settings", "enable_scheduler")
  File "/home/pearl/alumnimgmtsystem/apps/frappe/frappe/database/database.py", line 884, in get_single_value
    ).run()
      ^^^^^
  File "/home/pearl/alumnimgmtsystem/apps/frappe/frappe/query_builder/utils.py", line 80, in execute_query
    result = frappe.db.sql(query, params, *args, **kwargs)  # nosemgrep
             ^^^^^^^^^^^^^^^^^^^^^^^^^^^^^^^^^^^^^^^^^^^^^
  File "/home/pearl/alumnimgmtsystem/apps/frappe/frappe/database/database.py", line 237, in sql
    self.connect()
  File "/home/pearl/alumnimgmtsystem/apps/frappe/frappe/database/database.py", line 135, in connect
    self.get_connection()
  File "/home/pearl/alumnimgmtsystem/apps/frappe/frappe/database/mariadb/database.py", line 105, in get_connection
    conn = self._get_connection()
           ^^^^^^^^^^^^^^^^^^^^^^
  File "/home/pearl/alumnimgmtsystem/apps/frappe/frappe/database/mariadb/database.py", line 111, in _get_connection
    return self.create_connection()
           ^^^^^^^^^^^^^^^^^^^^^^^^
  File "/home/pearl/alumnimgmtsystem/apps/frappe/frappe/database/mariadb/database.py", line 114, in create_connection
    return pymysql.connect(**self.get_connection_settings())
           ^^^^^^^^^^^^^^^^^^^^^^^^^^^^^^^^^^^^^^^^^^^^^^^^^
  File "/home/pearl/alumnimgmtsystem/env/lib/python3.12/site-packages/pymysql/connections.py", line 361, in __init__
    self.connect()
  File "/home/pearl/alumnimgmtsystem/env/lib/python3.12/site-packages/pymysql/connections.py", line 669, in connect
    self._request_authentication()
  File "/home/pearl/alumnimgmtsystem/env/lib/python3.12/site-packages/pymysql/connections.py", line 957, in _request_authentication
    auth_packet = self._read_packet()
                  ^^^^^^^^^^^^^^^^^^^
  File "/home/pearl/alumnimgmtsystem/env/lib/python3.12/site-packages/pymysql/connections.py", line 775, in _read_packet
    packet.raise_for_error()
  File "/home/pearl/alumnimgmtsystem/env/lib/python3.12/site-packages/pymysql/protocol.py", line 219, in raise_for_error
    err.raise_mysql_exception(self._data)
  File "/home/pearl/alumnimgmtsystem/env/lib/python3.12/site-packages/pymysql/err.py", line 150, in raise_mysql_exception
    raise errorclass(errno, errval)
pymysql.err.OperationalError: (1045, "Access denied for user '_9a54aa6450761df8'@'localhost' (using password: YES)")
2025-04-22 18:50:00,943 ERROR scheduler Exception in Enqueue Events for Site library.localhost
Traceback (most recent call last):
  File "/home/pearl/alumnimgmtsystem/apps/frappe/frappe/utils/scheduler.py", line 117, in enqueue_events_for_site
    if is_scheduler_inactive():
       ^^^^^^^^^^^^^^^^^^^^^^^
  File "/home/pearl/alumnimgmtsystem/apps/frappe/frappe/utils/scheduler.py", line 161, in is_scheduler_inactive
    if is_scheduler_disabled(verbose=verbose):
       ^^^^^^^^^^^^^^^^^^^^^^^^^^^^^^^^^^^^^^
  File "/home/pearl/alumnimgmtsystem/apps/frappe/frappe/utils/scheduler.py", line 174, in is_scheduler_disabled
    frappe.db.get_single_value("System Settings", "enable_scheduler")
  File "/home/pearl/alumnimgmtsystem/apps/frappe/frappe/database/database.py", line 884, in get_single_value
    ).run()
      ^^^^^
  File "/home/pearl/alumnimgmtsystem/apps/frappe/frappe/query_builder/utils.py", line 80, in execute_query
    result = frappe.db.sql(query, params, *args, **kwargs)  # nosemgrep
             ^^^^^^^^^^^^^^^^^^^^^^^^^^^^^^^^^^^^^^^^^^^^^
  File "/home/pearl/alumnimgmtsystem/apps/frappe/frappe/database/database.py", line 237, in sql
    self.connect()
  File "/home/pearl/alumnimgmtsystem/apps/frappe/frappe/database/database.py", line 135, in connect
    self.get_connection()
  File "/home/pearl/alumnimgmtsystem/apps/frappe/frappe/database/mariadb/database.py", line 105, in get_connection
    conn = self._get_connection()
           ^^^^^^^^^^^^^^^^^^^^^^
  File "/home/pearl/alumnimgmtsystem/apps/frappe/frappe/database/mariadb/database.py", line 111, in _get_connection
    return self.create_connection()
           ^^^^^^^^^^^^^^^^^^^^^^^^
  File "/home/pearl/alumnimgmtsystem/apps/frappe/frappe/database/mariadb/database.py", line 114, in create_connection
    return pymysql.connect(**self.get_connection_settings())
           ^^^^^^^^^^^^^^^^^^^^^^^^^^^^^^^^^^^^^^^^^^^^^^^^^
  File "/home/pearl/alumnimgmtsystem/env/lib/python3.12/site-packages/pymysql/connections.py", line 361, in __init__
    self.connect()
  File "/home/pearl/alumnimgmtsystem/env/lib/python3.12/site-packages/pymysql/connections.py", line 669, in connect
    self._request_authentication()
  File "/home/pearl/alumnimgmtsystem/env/lib/python3.12/site-packages/pymysql/connections.py", line 957, in _request_authentication
    auth_packet = self._read_packet()
                  ^^^^^^^^^^^^^^^^^^^
  File "/home/pearl/alumnimgmtsystem/env/lib/python3.12/site-packages/pymysql/connections.py", line 775, in _read_packet
    packet.raise_for_error()
  File "/home/pearl/alumnimgmtsystem/env/lib/python3.12/site-packages/pymysql/protocol.py", line 219, in raise_for_error
    err.raise_mysql_exception(self._data)
  File "/home/pearl/alumnimgmtsystem/env/lib/python3.12/site-packages/pymysql/err.py", line 150, in raise_mysql_exception
    raise errorclass(errno, errval)
pymysql.err.OperationalError: (1045, "Access denied for user '_9a54aa6450761df8'@'localhost' (using password: YES)")
2025-04-22 18:54:01,031 ERROR scheduler Exception in Enqueue Events for Site library.localhost
Traceback (most recent call last):
  File "/home/pearl/alumnimgmtsystem/apps/frappe/frappe/utils/scheduler.py", line 117, in enqueue_events_for_site
    if is_scheduler_inactive():
       ^^^^^^^^^^^^^^^^^^^^^^^
  File "/home/pearl/alumnimgmtsystem/apps/frappe/frappe/utils/scheduler.py", line 161, in is_scheduler_inactive
    if is_scheduler_disabled(verbose=verbose):
       ^^^^^^^^^^^^^^^^^^^^^^^^^^^^^^^^^^^^^^
  File "/home/pearl/alumnimgmtsystem/apps/frappe/frappe/utils/scheduler.py", line 174, in is_scheduler_disabled
    frappe.db.get_single_value("System Settings", "enable_scheduler")
  File "/home/pearl/alumnimgmtsystem/apps/frappe/frappe/database/database.py", line 884, in get_single_value
    ).run()
      ^^^^^
  File "/home/pearl/alumnimgmtsystem/apps/frappe/frappe/query_builder/utils.py", line 80, in execute_query
    result = frappe.db.sql(query, params, *args, **kwargs)  # nosemgrep
             ^^^^^^^^^^^^^^^^^^^^^^^^^^^^^^^^^^^^^^^^^^^^^
  File "/home/pearl/alumnimgmtsystem/apps/frappe/frappe/database/database.py", line 237, in sql
    self.connect()
  File "/home/pearl/alumnimgmtsystem/apps/frappe/frappe/database/database.py", line 135, in connect
    self.get_connection()
  File "/home/pearl/alumnimgmtsystem/apps/frappe/frappe/database/mariadb/database.py", line 105, in get_connection
    conn = self._get_connection()
           ^^^^^^^^^^^^^^^^^^^^^^
  File "/home/pearl/alumnimgmtsystem/apps/frappe/frappe/database/mariadb/database.py", line 111, in _get_connection
    return self.create_connection()
           ^^^^^^^^^^^^^^^^^^^^^^^^
  File "/home/pearl/alumnimgmtsystem/apps/frappe/frappe/database/mariadb/database.py", line 114, in create_connection
    return pymysql.connect(**self.get_connection_settings())
           ^^^^^^^^^^^^^^^^^^^^^^^^^^^^^^^^^^^^^^^^^^^^^^^^^
  File "/home/pearl/alumnimgmtsystem/env/lib/python3.12/site-packages/pymysql/connections.py", line 361, in __init__
    self.connect()
  File "/home/pearl/alumnimgmtsystem/env/lib/python3.12/site-packages/pymysql/connections.py", line 669, in connect
    self._request_authentication()
  File "/home/pearl/alumnimgmtsystem/env/lib/python3.12/site-packages/pymysql/connections.py", line 957, in _request_authentication
    auth_packet = self._read_packet()
                  ^^^^^^^^^^^^^^^^^^^
  File "/home/pearl/alumnimgmtsystem/env/lib/python3.12/site-packages/pymysql/connections.py", line 775, in _read_packet
    packet.raise_for_error()
  File "/home/pearl/alumnimgmtsystem/env/lib/python3.12/site-packages/pymysql/protocol.py", line 219, in raise_for_error
    err.raise_mysql_exception(self._data)
  File "/home/pearl/alumnimgmtsystem/env/lib/python3.12/site-packages/pymysql/err.py", line 150, in raise_mysql_exception
    raise errorclass(errno, errval)
pymysql.err.OperationalError: (1045, "Access denied for user '_9a54aa6450761df8'@'localhost' (using password: YES)")
2025-04-22 18:58:00,094 ERROR scheduler Exception in Enqueue Events for Site library.localhost
Traceback (most recent call last):
  File "/home/pearl/alumnimgmtsystem/apps/frappe/frappe/utils/scheduler.py", line 117, in enqueue_events_for_site
    if is_scheduler_inactive():
       ^^^^^^^^^^^^^^^^^^^^^^^
  File "/home/pearl/alumnimgmtsystem/apps/frappe/frappe/utils/scheduler.py", line 161, in is_scheduler_inactive
    if is_scheduler_disabled(verbose=verbose):
       ^^^^^^^^^^^^^^^^^^^^^^^^^^^^^^^^^^^^^^
  File "/home/pearl/alumnimgmtsystem/apps/frappe/frappe/utils/scheduler.py", line 174, in is_scheduler_disabled
    frappe.db.get_single_value("System Settings", "enable_scheduler")
  File "/home/pearl/alumnimgmtsystem/apps/frappe/frappe/database/database.py", line 884, in get_single_value
    ).run()
      ^^^^^
  File "/home/pearl/alumnimgmtsystem/apps/frappe/frappe/query_builder/utils.py", line 80, in execute_query
    result = frappe.db.sql(query, params, *args, **kwargs)  # nosemgrep
             ^^^^^^^^^^^^^^^^^^^^^^^^^^^^^^^^^^^^^^^^^^^^^
  File "/home/pearl/alumnimgmtsystem/apps/frappe/frappe/database/database.py", line 237, in sql
    self.connect()
  File "/home/pearl/alumnimgmtsystem/apps/frappe/frappe/database/database.py", line 135, in connect
    self.get_connection()
  File "/home/pearl/alumnimgmtsystem/apps/frappe/frappe/database/mariadb/database.py", line 105, in get_connection
    conn = self._get_connection()
           ^^^^^^^^^^^^^^^^^^^^^^
  File "/home/pearl/alumnimgmtsystem/apps/frappe/frappe/database/mariadb/database.py", line 111, in _get_connection
    return self.create_connection()
           ^^^^^^^^^^^^^^^^^^^^^^^^
  File "/home/pearl/alumnimgmtsystem/apps/frappe/frappe/database/mariadb/database.py", line 114, in create_connection
    return pymysql.connect(**self.get_connection_settings())
           ^^^^^^^^^^^^^^^^^^^^^^^^^^^^^^^^^^^^^^^^^^^^^^^^^
  File "/home/pearl/alumnimgmtsystem/env/lib/python3.12/site-packages/pymysql/connections.py", line 361, in __init__
    self.connect()
  File "/home/pearl/alumnimgmtsystem/env/lib/python3.12/site-packages/pymysql/connections.py", line 669, in connect
    self._request_authentication()
  File "/home/pearl/alumnimgmtsystem/env/lib/python3.12/site-packages/pymysql/connections.py", line 957, in _request_authentication
    auth_packet = self._read_packet()
                  ^^^^^^^^^^^^^^^^^^^
  File "/home/pearl/alumnimgmtsystem/env/lib/python3.12/site-packages/pymysql/connections.py", line 775, in _read_packet
    packet.raise_for_error()
  File "/home/pearl/alumnimgmtsystem/env/lib/python3.12/site-packages/pymysql/protocol.py", line 219, in raise_for_error
    err.raise_mysql_exception(self._data)
  File "/home/pearl/alumnimgmtsystem/env/lib/python3.12/site-packages/pymysql/err.py", line 150, in raise_mysql_exception
    raise errorclass(errno, errval)
pymysql.err.OperationalError: (1045, "Access denied for user '_9a54aa6450761df8'@'localhost' (using password: YES)")
2025-04-22 19:02:00,104 ERROR scheduler Exception in Enqueue Events for Site library.localhost
Traceback (most recent call last):
  File "/home/pearl/alumnimgmtsystem/apps/frappe/frappe/utils/scheduler.py", line 117, in enqueue_events_for_site
    if is_scheduler_inactive():
       ^^^^^^^^^^^^^^^^^^^^^^^
  File "/home/pearl/alumnimgmtsystem/apps/frappe/frappe/utils/scheduler.py", line 161, in is_scheduler_inactive
    if is_scheduler_disabled(verbose=verbose):
       ^^^^^^^^^^^^^^^^^^^^^^^^^^^^^^^^^^^^^^
  File "/home/pearl/alumnimgmtsystem/apps/frappe/frappe/utils/scheduler.py", line 174, in is_scheduler_disabled
    frappe.db.get_single_value("System Settings", "enable_scheduler")
  File "/home/pearl/alumnimgmtsystem/apps/frappe/frappe/database/database.py", line 884, in get_single_value
    ).run()
      ^^^^^
  File "/home/pearl/alumnimgmtsystem/apps/frappe/frappe/query_builder/utils.py", line 80, in execute_query
    result = frappe.db.sql(query, params, *args, **kwargs)  # nosemgrep
             ^^^^^^^^^^^^^^^^^^^^^^^^^^^^^^^^^^^^^^^^^^^^^
  File "/home/pearl/alumnimgmtsystem/apps/frappe/frappe/database/database.py", line 237, in sql
    self.connect()
  File "/home/pearl/alumnimgmtsystem/apps/frappe/frappe/database/database.py", line 135, in connect
    self.get_connection()
  File "/home/pearl/alumnimgmtsystem/apps/frappe/frappe/database/mariadb/database.py", line 105, in get_connection
    conn = self._get_connection()
           ^^^^^^^^^^^^^^^^^^^^^^
  File "/home/pearl/alumnimgmtsystem/apps/frappe/frappe/database/mariadb/database.py", line 111, in _get_connection
    return self.create_connection()
           ^^^^^^^^^^^^^^^^^^^^^^^^
  File "/home/pearl/alumnimgmtsystem/apps/frappe/frappe/database/mariadb/database.py", line 114, in create_connection
    return pymysql.connect(**self.get_connection_settings())
           ^^^^^^^^^^^^^^^^^^^^^^^^^^^^^^^^^^^^^^^^^^^^^^^^^
  File "/home/pearl/alumnimgmtsystem/env/lib/python3.12/site-packages/pymysql/connections.py", line 361, in __init__
    self.connect()
  File "/home/pearl/alumnimgmtsystem/env/lib/python3.12/site-packages/pymysql/connections.py", line 669, in connect
    self._request_authentication()
  File "/home/pearl/alumnimgmtsystem/env/lib/python3.12/site-packages/pymysql/connections.py", line 957, in _request_authentication
    auth_packet = self._read_packet()
                  ^^^^^^^^^^^^^^^^^^^
  File "/home/pearl/alumnimgmtsystem/env/lib/python3.12/site-packages/pymysql/connections.py", line 775, in _read_packet
    packet.raise_for_error()
  File "/home/pearl/alumnimgmtsystem/env/lib/python3.12/site-packages/pymysql/protocol.py", line 219, in raise_for_error
    err.raise_mysql_exception(self._data)
  File "/home/pearl/alumnimgmtsystem/env/lib/python3.12/site-packages/pymysql/err.py", line 150, in raise_mysql_exception
    raise errorclass(errno, errval)
pymysql.err.OperationalError: (1045, "Access denied for user '_9a54aa6450761df8'@'localhost' (using password: YES)")
2025-04-22 19:06:00,246 ERROR scheduler Exception in Enqueue Events for Site library.localhost
Traceback (most recent call last):
  File "/home/pearl/alumnimgmtsystem/apps/frappe/frappe/utils/scheduler.py", line 117, in enqueue_events_for_site
    if is_scheduler_inactive():
       ^^^^^^^^^^^^^^^^^^^^^^^
  File "/home/pearl/alumnimgmtsystem/apps/frappe/frappe/utils/scheduler.py", line 161, in is_scheduler_inactive
    if is_scheduler_disabled(verbose=verbose):
       ^^^^^^^^^^^^^^^^^^^^^^^^^^^^^^^^^^^^^^
  File "/home/pearl/alumnimgmtsystem/apps/frappe/frappe/utils/scheduler.py", line 174, in is_scheduler_disabled
    frappe.db.get_single_value("System Settings", "enable_scheduler")
  File "/home/pearl/alumnimgmtsystem/apps/frappe/frappe/database/database.py", line 884, in get_single_value
    ).run()
      ^^^^^
  File "/home/pearl/alumnimgmtsystem/apps/frappe/frappe/query_builder/utils.py", line 80, in execute_query
    result = frappe.db.sql(query, params, *args, **kwargs)  # nosemgrep
             ^^^^^^^^^^^^^^^^^^^^^^^^^^^^^^^^^^^^^^^^^^^^^
  File "/home/pearl/alumnimgmtsystem/apps/frappe/frappe/database/database.py", line 237, in sql
    self.connect()
  File "/home/pearl/alumnimgmtsystem/apps/frappe/frappe/database/database.py", line 135, in connect
    self.get_connection()
  File "/home/pearl/alumnimgmtsystem/apps/frappe/frappe/database/mariadb/database.py", line 105, in get_connection
    conn = self._get_connection()
           ^^^^^^^^^^^^^^^^^^^^^^
  File "/home/pearl/alumnimgmtsystem/apps/frappe/frappe/database/mariadb/database.py", line 111, in _get_connection
    return self.create_connection()
           ^^^^^^^^^^^^^^^^^^^^^^^^
  File "/home/pearl/alumnimgmtsystem/apps/frappe/frappe/database/mariadb/database.py", line 114, in create_connection
    return pymysql.connect(**self.get_connection_settings())
           ^^^^^^^^^^^^^^^^^^^^^^^^^^^^^^^^^^^^^^^^^^^^^^^^^
  File "/home/pearl/alumnimgmtsystem/env/lib/python3.12/site-packages/pymysql/connections.py", line 361, in __init__
    self.connect()
  File "/home/pearl/alumnimgmtsystem/env/lib/python3.12/site-packages/pymysql/connections.py", line 669, in connect
    self._request_authentication()
  File "/home/pearl/alumnimgmtsystem/env/lib/python3.12/site-packages/pymysql/connections.py", line 957, in _request_authentication
    auth_packet = self._read_packet()
                  ^^^^^^^^^^^^^^^^^^^
  File "/home/pearl/alumnimgmtsystem/env/lib/python3.12/site-packages/pymysql/connections.py", line 775, in _read_packet
    packet.raise_for_error()
  File "/home/pearl/alumnimgmtsystem/env/lib/python3.12/site-packages/pymysql/protocol.py", line 219, in raise_for_error
    err.raise_mysql_exception(self._data)
  File "/home/pearl/alumnimgmtsystem/env/lib/python3.12/site-packages/pymysql/err.py", line 150, in raise_mysql_exception
    raise errorclass(errno, errval)
pymysql.err.OperationalError: (1045, "Access denied for user '_9a54aa6450761df8'@'localhost' (using password: YES)")
2025-04-22 19:10:00,259 ERROR scheduler Exception in Enqueue Events for Site library.localhost
Traceback (most recent call last):
  File "/home/pearl/alumnimgmtsystem/apps/frappe/frappe/utils/scheduler.py", line 117, in enqueue_events_for_site
    if is_scheduler_inactive():
       ^^^^^^^^^^^^^^^^^^^^^^^
  File "/home/pearl/alumnimgmtsystem/apps/frappe/frappe/utils/scheduler.py", line 161, in is_scheduler_inactive
    if is_scheduler_disabled(verbose=verbose):
       ^^^^^^^^^^^^^^^^^^^^^^^^^^^^^^^^^^^^^^
  File "/home/pearl/alumnimgmtsystem/apps/frappe/frappe/utils/scheduler.py", line 174, in is_scheduler_disabled
    frappe.db.get_single_value("System Settings", "enable_scheduler")
  File "/home/pearl/alumnimgmtsystem/apps/frappe/frappe/database/database.py", line 884, in get_single_value
    ).run()
      ^^^^^
  File "/home/pearl/alumnimgmtsystem/apps/frappe/frappe/query_builder/utils.py", line 80, in execute_query
    result = frappe.db.sql(query, params, *args, **kwargs)  # nosemgrep
             ^^^^^^^^^^^^^^^^^^^^^^^^^^^^^^^^^^^^^^^^^^^^^
  File "/home/pearl/alumnimgmtsystem/apps/frappe/frappe/database/database.py", line 237, in sql
    self.connect()
  File "/home/pearl/alumnimgmtsystem/apps/frappe/frappe/database/database.py", line 135, in connect
    self.get_connection()
  File "/home/pearl/alumnimgmtsystem/apps/frappe/frappe/database/mariadb/database.py", line 105, in get_connection
    conn = self._get_connection()
           ^^^^^^^^^^^^^^^^^^^^^^
  File "/home/pearl/alumnimgmtsystem/apps/frappe/frappe/database/mariadb/database.py", line 111, in _get_connection
    return self.create_connection()
           ^^^^^^^^^^^^^^^^^^^^^^^^
  File "/home/pearl/alumnimgmtsystem/apps/frappe/frappe/database/mariadb/database.py", line 114, in create_connection
    return pymysql.connect(**self.get_connection_settings())
           ^^^^^^^^^^^^^^^^^^^^^^^^^^^^^^^^^^^^^^^^^^^^^^^^^
  File "/home/pearl/alumnimgmtsystem/env/lib/python3.12/site-packages/pymysql/connections.py", line 361, in __init__
    self.connect()
  File "/home/pearl/alumnimgmtsystem/env/lib/python3.12/site-packages/pymysql/connections.py", line 669, in connect
    self._request_authentication()
  File "/home/pearl/alumnimgmtsystem/env/lib/python3.12/site-packages/pymysql/connections.py", line 957, in _request_authentication
    auth_packet = self._read_packet()
                  ^^^^^^^^^^^^^^^^^^^
  File "/home/pearl/alumnimgmtsystem/env/lib/python3.12/site-packages/pymysql/connections.py", line 775, in _read_packet
    packet.raise_for_error()
  File "/home/pearl/alumnimgmtsystem/env/lib/python3.12/site-packages/pymysql/protocol.py", line 219, in raise_for_error
    err.raise_mysql_exception(self._data)
  File "/home/pearl/alumnimgmtsystem/env/lib/python3.12/site-packages/pymysql/err.py", line 150, in raise_mysql_exception
    raise errorclass(errno, errval)
pymysql.err.OperationalError: (1045, "Access denied for user '_9a54aa6450761df8'@'localhost' (using password: YES)")
2025-04-22 19:14:00,341 ERROR scheduler Exception in Enqueue Events for Site library.localhost
Traceback (most recent call last):
  File "/home/pearl/alumnimgmtsystem/apps/frappe/frappe/utils/scheduler.py", line 117, in enqueue_events_for_site
    if is_scheduler_inactive():
       ^^^^^^^^^^^^^^^^^^^^^^^
  File "/home/pearl/alumnimgmtsystem/apps/frappe/frappe/utils/scheduler.py", line 161, in is_scheduler_inactive
    if is_scheduler_disabled(verbose=verbose):
       ^^^^^^^^^^^^^^^^^^^^^^^^^^^^^^^^^^^^^^
  File "/home/pearl/alumnimgmtsystem/apps/frappe/frappe/utils/scheduler.py", line 174, in is_scheduler_disabled
    frappe.db.get_single_value("System Settings", "enable_scheduler")
  File "/home/pearl/alumnimgmtsystem/apps/frappe/frappe/database/database.py", line 884, in get_single_value
    ).run()
      ^^^^^
  File "/home/pearl/alumnimgmtsystem/apps/frappe/frappe/query_builder/utils.py", line 80, in execute_query
    result = frappe.db.sql(query, params, *args, **kwargs)  # nosemgrep
             ^^^^^^^^^^^^^^^^^^^^^^^^^^^^^^^^^^^^^^^^^^^^^
  File "/home/pearl/alumnimgmtsystem/apps/frappe/frappe/database/database.py", line 237, in sql
    self.connect()
  File "/home/pearl/alumnimgmtsystem/apps/frappe/frappe/database/database.py", line 135, in connect
    self.get_connection()
  File "/home/pearl/alumnimgmtsystem/apps/frappe/frappe/database/mariadb/database.py", line 105, in get_connection
    conn = self._get_connection()
           ^^^^^^^^^^^^^^^^^^^^^^
  File "/home/pearl/alumnimgmtsystem/apps/frappe/frappe/database/mariadb/database.py", line 111, in _get_connection
    return self.create_connection()
           ^^^^^^^^^^^^^^^^^^^^^^^^
  File "/home/pearl/alumnimgmtsystem/apps/frappe/frappe/database/mariadb/database.py", line 114, in create_connection
    return pymysql.connect(**self.get_connection_settings())
           ^^^^^^^^^^^^^^^^^^^^^^^^^^^^^^^^^^^^^^^^^^^^^^^^^
  File "/home/pearl/alumnimgmtsystem/env/lib/python3.12/site-packages/pymysql/connections.py", line 361, in __init__
    self.connect()
  File "/home/pearl/alumnimgmtsystem/env/lib/python3.12/site-packages/pymysql/connections.py", line 669, in connect
    self._request_authentication()
  File "/home/pearl/alumnimgmtsystem/env/lib/python3.12/site-packages/pymysql/connections.py", line 957, in _request_authentication
    auth_packet = self._read_packet()
                  ^^^^^^^^^^^^^^^^^^^
  File "/home/pearl/alumnimgmtsystem/env/lib/python3.12/site-packages/pymysql/connections.py", line 775, in _read_packet
    packet.raise_for_error()
  File "/home/pearl/alumnimgmtsystem/env/lib/python3.12/site-packages/pymysql/protocol.py", line 219, in raise_for_error
    err.raise_mysql_exception(self._data)
  File "/home/pearl/alumnimgmtsystem/env/lib/python3.12/site-packages/pymysql/err.py", line 150, in raise_mysql_exception
    raise errorclass(errno, errval)
pymysql.err.OperationalError: (1045, "Access denied for user '_9a54aa6450761df8'@'localhost' (using password: YES)")
2025-04-22 19:18:00,453 ERROR scheduler Exception in Enqueue Events for Site library.localhost
Traceback (most recent call last):
  File "/home/pearl/alumnimgmtsystem/apps/frappe/frappe/utils/scheduler.py", line 117, in enqueue_events_for_site
    if is_scheduler_inactive():
       ^^^^^^^^^^^^^^^^^^^^^^^
  File "/home/pearl/alumnimgmtsystem/apps/frappe/frappe/utils/scheduler.py", line 161, in is_scheduler_inactive
    if is_scheduler_disabled(verbose=verbose):
       ^^^^^^^^^^^^^^^^^^^^^^^^^^^^^^^^^^^^^^
  File "/home/pearl/alumnimgmtsystem/apps/frappe/frappe/utils/scheduler.py", line 174, in is_scheduler_disabled
    frappe.db.get_single_value("System Settings", "enable_scheduler")
  File "/home/pearl/alumnimgmtsystem/apps/frappe/frappe/database/database.py", line 884, in get_single_value
    ).run()
      ^^^^^
  File "/home/pearl/alumnimgmtsystem/apps/frappe/frappe/query_builder/utils.py", line 80, in execute_query
    result = frappe.db.sql(query, params, *args, **kwargs)  # nosemgrep
             ^^^^^^^^^^^^^^^^^^^^^^^^^^^^^^^^^^^^^^^^^^^^^
  File "/home/pearl/alumnimgmtsystem/apps/frappe/frappe/database/database.py", line 237, in sql
    self.connect()
  File "/home/pearl/alumnimgmtsystem/apps/frappe/frappe/database/database.py", line 135, in connect
    self.get_connection()
  File "/home/pearl/alumnimgmtsystem/apps/frappe/frappe/database/mariadb/database.py", line 105, in get_connection
    conn = self._get_connection()
           ^^^^^^^^^^^^^^^^^^^^^^
  File "/home/pearl/alumnimgmtsystem/apps/frappe/frappe/database/mariadb/database.py", line 111, in _get_connection
    return self.create_connection()
           ^^^^^^^^^^^^^^^^^^^^^^^^
  File "/home/pearl/alumnimgmtsystem/apps/frappe/frappe/database/mariadb/database.py", line 114, in create_connection
    return pymysql.connect(**self.get_connection_settings())
           ^^^^^^^^^^^^^^^^^^^^^^^^^^^^^^^^^^^^^^^^^^^^^^^^^
  File "/home/pearl/alumnimgmtsystem/env/lib/python3.12/site-packages/pymysql/connections.py", line 361, in __init__
    self.connect()
  File "/home/pearl/alumnimgmtsystem/env/lib/python3.12/site-packages/pymysql/connections.py", line 669, in connect
    self._request_authentication()
  File "/home/pearl/alumnimgmtsystem/env/lib/python3.12/site-packages/pymysql/connections.py", line 957, in _request_authentication
    auth_packet = self._read_packet()
                  ^^^^^^^^^^^^^^^^^^^
  File "/home/pearl/alumnimgmtsystem/env/lib/python3.12/site-packages/pymysql/connections.py", line 775, in _read_packet
    packet.raise_for_error()
  File "/home/pearl/alumnimgmtsystem/env/lib/python3.12/site-packages/pymysql/protocol.py", line 219, in raise_for_error
    err.raise_mysql_exception(self._data)
  File "/home/pearl/alumnimgmtsystem/env/lib/python3.12/site-packages/pymysql/err.py", line 150, in raise_mysql_exception
    raise errorclass(errno, errval)
pymysql.err.OperationalError: (1045, "Access denied for user '_9a54aa6450761df8'@'localhost' (using password: YES)")
2025-04-22 19:22:00,520 ERROR scheduler Exception in Enqueue Events for Site library.localhost
Traceback (most recent call last):
  File "/home/pearl/alumnimgmtsystem/apps/frappe/frappe/utils/scheduler.py", line 117, in enqueue_events_for_site
    if is_scheduler_inactive():
       ^^^^^^^^^^^^^^^^^^^^^^^
  File "/home/pearl/alumnimgmtsystem/apps/frappe/frappe/utils/scheduler.py", line 161, in is_scheduler_inactive
    if is_scheduler_disabled(verbose=verbose):
       ^^^^^^^^^^^^^^^^^^^^^^^^^^^^^^^^^^^^^^
  File "/home/pearl/alumnimgmtsystem/apps/frappe/frappe/utils/scheduler.py", line 174, in is_scheduler_disabled
    frappe.db.get_single_value("System Settings", "enable_scheduler")
  File "/home/pearl/alumnimgmtsystem/apps/frappe/frappe/database/database.py", line 884, in get_single_value
    ).run()
      ^^^^^
  File "/home/pearl/alumnimgmtsystem/apps/frappe/frappe/query_builder/utils.py", line 80, in execute_query
    result = frappe.db.sql(query, params, *args, **kwargs)  # nosemgrep
             ^^^^^^^^^^^^^^^^^^^^^^^^^^^^^^^^^^^^^^^^^^^^^
  File "/home/pearl/alumnimgmtsystem/apps/frappe/frappe/database/database.py", line 237, in sql
    self.connect()
  File "/home/pearl/alumnimgmtsystem/apps/frappe/frappe/database/database.py", line 135, in connect
    self.get_connection()
  File "/home/pearl/alumnimgmtsystem/apps/frappe/frappe/database/mariadb/database.py", line 105, in get_connection
    conn = self._get_connection()
           ^^^^^^^^^^^^^^^^^^^^^^
  File "/home/pearl/alumnimgmtsystem/apps/frappe/frappe/database/mariadb/database.py", line 111, in _get_connection
    return self.create_connection()
           ^^^^^^^^^^^^^^^^^^^^^^^^
  File "/home/pearl/alumnimgmtsystem/apps/frappe/frappe/database/mariadb/database.py", line 114, in create_connection
    return pymysql.connect(**self.get_connection_settings())
           ^^^^^^^^^^^^^^^^^^^^^^^^^^^^^^^^^^^^^^^^^^^^^^^^^
  File "/home/pearl/alumnimgmtsystem/env/lib/python3.12/site-packages/pymysql/connections.py", line 361, in __init__
    self.connect()
  File "/home/pearl/alumnimgmtsystem/env/lib/python3.12/site-packages/pymysql/connections.py", line 669, in connect
    self._request_authentication()
  File "/home/pearl/alumnimgmtsystem/env/lib/python3.12/site-packages/pymysql/connections.py", line 957, in _request_authentication
    auth_packet = self._read_packet()
                  ^^^^^^^^^^^^^^^^^^^
  File "/home/pearl/alumnimgmtsystem/env/lib/python3.12/site-packages/pymysql/connections.py", line 775, in _read_packet
    packet.raise_for_error()
  File "/home/pearl/alumnimgmtsystem/env/lib/python3.12/site-packages/pymysql/protocol.py", line 219, in raise_for_error
    err.raise_mysql_exception(self._data)
  File "/home/pearl/alumnimgmtsystem/env/lib/python3.12/site-packages/pymysql/err.py", line 150, in raise_mysql_exception
    raise errorclass(errno, errval)
pymysql.err.OperationalError: (1045, "Access denied for user '_9a54aa6450761df8'@'localhost' (using password: YES)")
2025-04-22 19:26:00,532 ERROR scheduler Exception in Enqueue Events for Site library.localhost
Traceback (most recent call last):
  File "/home/pearl/alumnimgmtsystem/apps/frappe/frappe/utils/scheduler.py", line 117, in enqueue_events_for_site
    if is_scheduler_inactive():
       ^^^^^^^^^^^^^^^^^^^^^^^
  File "/home/pearl/alumnimgmtsystem/apps/frappe/frappe/utils/scheduler.py", line 161, in is_scheduler_inactive
    if is_scheduler_disabled(verbose=verbose):
       ^^^^^^^^^^^^^^^^^^^^^^^^^^^^^^^^^^^^^^
  File "/home/pearl/alumnimgmtsystem/apps/frappe/frappe/utils/scheduler.py", line 174, in is_scheduler_disabled
    frappe.db.get_single_value("System Settings", "enable_scheduler")
  File "/home/pearl/alumnimgmtsystem/apps/frappe/frappe/database/database.py", line 884, in get_single_value
    ).run()
      ^^^^^
  File "/home/pearl/alumnimgmtsystem/apps/frappe/frappe/query_builder/utils.py", line 80, in execute_query
    result = frappe.db.sql(query, params, *args, **kwargs)  # nosemgrep
             ^^^^^^^^^^^^^^^^^^^^^^^^^^^^^^^^^^^^^^^^^^^^^
  File "/home/pearl/alumnimgmtsystem/apps/frappe/frappe/database/database.py", line 237, in sql
    self.connect()
  File "/home/pearl/alumnimgmtsystem/apps/frappe/frappe/database/database.py", line 135, in connect
    self.get_connection()
  File "/home/pearl/alumnimgmtsystem/apps/frappe/frappe/database/mariadb/database.py", line 105, in get_connection
    conn = self._get_connection()
           ^^^^^^^^^^^^^^^^^^^^^^
  File "/home/pearl/alumnimgmtsystem/apps/frappe/frappe/database/mariadb/database.py", line 111, in _get_connection
    return self.create_connection()
           ^^^^^^^^^^^^^^^^^^^^^^^^
  File "/home/pearl/alumnimgmtsystem/apps/frappe/frappe/database/mariadb/database.py", line 114, in create_connection
    return pymysql.connect(**self.get_connection_settings())
           ^^^^^^^^^^^^^^^^^^^^^^^^^^^^^^^^^^^^^^^^^^^^^^^^^
  File "/home/pearl/alumnimgmtsystem/env/lib/python3.12/site-packages/pymysql/connections.py", line 361, in __init__
    self.connect()
  File "/home/pearl/alumnimgmtsystem/env/lib/python3.12/site-packages/pymysql/connections.py", line 669, in connect
    self._request_authentication()
  File "/home/pearl/alumnimgmtsystem/env/lib/python3.12/site-packages/pymysql/connections.py", line 957, in _request_authentication
    auth_packet = self._read_packet()
                  ^^^^^^^^^^^^^^^^^^^
  File "/home/pearl/alumnimgmtsystem/env/lib/python3.12/site-packages/pymysql/connections.py", line 775, in _read_packet
    packet.raise_for_error()
  File "/home/pearl/alumnimgmtsystem/env/lib/python3.12/site-packages/pymysql/protocol.py", line 219, in raise_for_error
    err.raise_mysql_exception(self._data)
  File "/home/pearl/alumnimgmtsystem/env/lib/python3.12/site-packages/pymysql/err.py", line 150, in raise_mysql_exception
    raise errorclass(errno, errval)
pymysql.err.OperationalError: (1045, "Access denied for user '_9a54aa6450761df8'@'localhost' (using password: YES)")
2025-04-22 19:30:00,594 ERROR scheduler Exception in Enqueue Events for Site library.localhost
Traceback (most recent call last):
  File "/home/pearl/alumnimgmtsystem/apps/frappe/frappe/utils/scheduler.py", line 117, in enqueue_events_for_site
    if is_scheduler_inactive():
       ^^^^^^^^^^^^^^^^^^^^^^^
  File "/home/pearl/alumnimgmtsystem/apps/frappe/frappe/utils/scheduler.py", line 161, in is_scheduler_inactive
    if is_scheduler_disabled(verbose=verbose):
       ^^^^^^^^^^^^^^^^^^^^^^^^^^^^^^^^^^^^^^
  File "/home/pearl/alumnimgmtsystem/apps/frappe/frappe/utils/scheduler.py", line 174, in is_scheduler_disabled
    frappe.db.get_single_value("System Settings", "enable_scheduler")
  File "/home/pearl/alumnimgmtsystem/apps/frappe/frappe/database/database.py", line 884, in get_single_value
    ).run()
      ^^^^^
  File "/home/pearl/alumnimgmtsystem/apps/frappe/frappe/query_builder/utils.py", line 80, in execute_query
    result = frappe.db.sql(query, params, *args, **kwargs)  # nosemgrep
             ^^^^^^^^^^^^^^^^^^^^^^^^^^^^^^^^^^^^^^^^^^^^^
  File "/home/pearl/alumnimgmtsystem/apps/frappe/frappe/database/database.py", line 237, in sql
    self.connect()
  File "/home/pearl/alumnimgmtsystem/apps/frappe/frappe/database/database.py", line 135, in connect
    self.get_connection()
  File "/home/pearl/alumnimgmtsystem/apps/frappe/frappe/database/mariadb/database.py", line 105, in get_connection
    conn = self._get_connection()
           ^^^^^^^^^^^^^^^^^^^^^^
  File "/home/pearl/alumnimgmtsystem/apps/frappe/frappe/database/mariadb/database.py", line 111, in _get_connection
    return self.create_connection()
           ^^^^^^^^^^^^^^^^^^^^^^^^
  File "/home/pearl/alumnimgmtsystem/apps/frappe/frappe/database/mariadb/database.py", line 114, in create_connection
    return pymysql.connect(**self.get_connection_settings())
           ^^^^^^^^^^^^^^^^^^^^^^^^^^^^^^^^^^^^^^^^^^^^^^^^^
  File "/home/pearl/alumnimgmtsystem/env/lib/python3.12/site-packages/pymysql/connections.py", line 361, in __init__
    self.connect()
  File "/home/pearl/alumnimgmtsystem/env/lib/python3.12/site-packages/pymysql/connections.py", line 669, in connect
    self._request_authentication()
  File "/home/pearl/alumnimgmtsystem/env/lib/python3.12/site-packages/pymysql/connections.py", line 957, in _request_authentication
    auth_packet = self._read_packet()
                  ^^^^^^^^^^^^^^^^^^^
  File "/home/pearl/alumnimgmtsystem/env/lib/python3.12/site-packages/pymysql/connections.py", line 775, in _read_packet
    packet.raise_for_error()
  File "/home/pearl/alumnimgmtsystem/env/lib/python3.12/site-packages/pymysql/protocol.py", line 219, in raise_for_error
    err.raise_mysql_exception(self._data)
  File "/home/pearl/alumnimgmtsystem/env/lib/python3.12/site-packages/pymysql/err.py", line 150, in raise_mysql_exception
    raise errorclass(errno, errval)
pymysql.err.OperationalError: (1045, "Access denied for user '_9a54aa6450761df8'@'localhost' (using password: YES)")
2025-04-22 19:34:00,820 ERROR scheduler Exception in Enqueue Events for Site library.localhost
Traceback (most recent call last):
  File "/home/pearl/alumnimgmtsystem/apps/frappe/frappe/utils/scheduler.py", line 117, in enqueue_events_for_site
    if is_scheduler_inactive():
       ^^^^^^^^^^^^^^^^^^^^^^^
  File "/home/pearl/alumnimgmtsystem/apps/frappe/frappe/utils/scheduler.py", line 161, in is_scheduler_inactive
    if is_scheduler_disabled(verbose=verbose):
       ^^^^^^^^^^^^^^^^^^^^^^^^^^^^^^^^^^^^^^
  File "/home/pearl/alumnimgmtsystem/apps/frappe/frappe/utils/scheduler.py", line 174, in is_scheduler_disabled
    frappe.db.get_single_value("System Settings", "enable_scheduler")
  File "/home/pearl/alumnimgmtsystem/apps/frappe/frappe/database/database.py", line 884, in get_single_value
    ).run()
      ^^^^^
  File "/home/pearl/alumnimgmtsystem/apps/frappe/frappe/query_builder/utils.py", line 80, in execute_query
    result = frappe.db.sql(query, params, *args, **kwargs)  # nosemgrep
             ^^^^^^^^^^^^^^^^^^^^^^^^^^^^^^^^^^^^^^^^^^^^^
  File "/home/pearl/alumnimgmtsystem/apps/frappe/frappe/database/database.py", line 237, in sql
    self.connect()
  File "/home/pearl/alumnimgmtsystem/apps/frappe/frappe/database/database.py", line 135, in connect
    self.get_connection()
  File "/home/pearl/alumnimgmtsystem/apps/frappe/frappe/database/mariadb/database.py", line 105, in get_connection
    conn = self._get_connection()
           ^^^^^^^^^^^^^^^^^^^^^^
  File "/home/pearl/alumnimgmtsystem/apps/frappe/frappe/database/mariadb/database.py", line 111, in _get_connection
    return self.create_connection()
           ^^^^^^^^^^^^^^^^^^^^^^^^
  File "/home/pearl/alumnimgmtsystem/apps/frappe/frappe/database/mariadb/database.py", line 114, in create_connection
    return pymysql.connect(**self.get_connection_settings())
           ^^^^^^^^^^^^^^^^^^^^^^^^^^^^^^^^^^^^^^^^^^^^^^^^^
  File "/home/pearl/alumnimgmtsystem/env/lib/python3.12/site-packages/pymysql/connections.py", line 361, in __init__
    self.connect()
  File "/home/pearl/alumnimgmtsystem/env/lib/python3.12/site-packages/pymysql/connections.py", line 669, in connect
    self._request_authentication()
  File "/home/pearl/alumnimgmtsystem/env/lib/python3.12/site-packages/pymysql/connections.py", line 957, in _request_authentication
    auth_packet = self._read_packet()
                  ^^^^^^^^^^^^^^^^^^^
  File "/home/pearl/alumnimgmtsystem/env/lib/python3.12/site-packages/pymysql/connections.py", line 775, in _read_packet
    packet.raise_for_error()
  File "/home/pearl/alumnimgmtsystem/env/lib/python3.12/site-packages/pymysql/protocol.py", line 219, in raise_for_error
    err.raise_mysql_exception(self._data)
  File "/home/pearl/alumnimgmtsystem/env/lib/python3.12/site-packages/pymysql/err.py", line 150, in raise_mysql_exception
    raise errorclass(errno, errval)
pymysql.err.OperationalError: (1045, "Access denied for user '_9a54aa6450761df8'@'localhost' (using password: YES)")
2025-04-22 19:38:00,868 ERROR scheduler Exception in Enqueue Events for Site library.localhost
Traceback (most recent call last):
  File "/home/pearl/alumnimgmtsystem/apps/frappe/frappe/utils/scheduler.py", line 117, in enqueue_events_for_site
    if is_scheduler_inactive():
       ^^^^^^^^^^^^^^^^^^^^^^^
  File "/home/pearl/alumnimgmtsystem/apps/frappe/frappe/utils/scheduler.py", line 161, in is_scheduler_inactive
    if is_scheduler_disabled(verbose=verbose):
       ^^^^^^^^^^^^^^^^^^^^^^^^^^^^^^^^^^^^^^
  File "/home/pearl/alumnimgmtsystem/apps/frappe/frappe/utils/scheduler.py", line 174, in is_scheduler_disabled
    frappe.db.get_single_value("System Settings", "enable_scheduler")
  File "/home/pearl/alumnimgmtsystem/apps/frappe/frappe/database/database.py", line 884, in get_single_value
    ).run()
      ^^^^^
  File "/home/pearl/alumnimgmtsystem/apps/frappe/frappe/query_builder/utils.py", line 80, in execute_query
    result = frappe.db.sql(query, params, *args, **kwargs)  # nosemgrep
             ^^^^^^^^^^^^^^^^^^^^^^^^^^^^^^^^^^^^^^^^^^^^^
  File "/home/pearl/alumnimgmtsystem/apps/frappe/frappe/database/database.py", line 237, in sql
    self.connect()
  File "/home/pearl/alumnimgmtsystem/apps/frappe/frappe/database/database.py", line 135, in connect
    self.get_connection()
  File "/home/pearl/alumnimgmtsystem/apps/frappe/frappe/database/mariadb/database.py", line 105, in get_connection
    conn = self._get_connection()
           ^^^^^^^^^^^^^^^^^^^^^^
  File "/home/pearl/alumnimgmtsystem/apps/frappe/frappe/database/mariadb/database.py", line 111, in _get_connection
    return self.create_connection()
           ^^^^^^^^^^^^^^^^^^^^^^^^
  File "/home/pearl/alumnimgmtsystem/apps/frappe/frappe/database/mariadb/database.py", line 114, in create_connection
    return pymysql.connect(**self.get_connection_settings())
           ^^^^^^^^^^^^^^^^^^^^^^^^^^^^^^^^^^^^^^^^^^^^^^^^^
  File "/home/pearl/alumnimgmtsystem/env/lib/python3.12/site-packages/pymysql/connections.py", line 361, in __init__
    self.connect()
  File "/home/pearl/alumnimgmtsystem/env/lib/python3.12/site-packages/pymysql/connections.py", line 669, in connect
    self._request_authentication()
  File "/home/pearl/alumnimgmtsystem/env/lib/python3.12/site-packages/pymysql/connections.py", line 957, in _request_authentication
    auth_packet = self._read_packet()
                  ^^^^^^^^^^^^^^^^^^^
  File "/home/pearl/alumnimgmtsystem/env/lib/python3.12/site-packages/pymysql/connections.py", line 775, in _read_packet
    packet.raise_for_error()
  File "/home/pearl/alumnimgmtsystem/env/lib/python3.12/site-packages/pymysql/protocol.py", line 219, in raise_for_error
    err.raise_mysql_exception(self._data)
  File "/home/pearl/alumnimgmtsystem/env/lib/python3.12/site-packages/pymysql/err.py", line 150, in raise_mysql_exception
    raise errorclass(errno, errval)
pymysql.err.OperationalError: (1045, "Access denied for user '_9a54aa6450761df8'@'localhost' (using password: YES)")
2025-04-22 19:42:00,878 ERROR scheduler Exception in Enqueue Events for Site library.localhost
Traceback (most recent call last):
  File "/home/pearl/alumnimgmtsystem/apps/frappe/frappe/utils/scheduler.py", line 117, in enqueue_events_for_site
    if is_scheduler_inactive():
       ^^^^^^^^^^^^^^^^^^^^^^^
  File "/home/pearl/alumnimgmtsystem/apps/frappe/frappe/utils/scheduler.py", line 161, in is_scheduler_inactive
    if is_scheduler_disabled(verbose=verbose):
       ^^^^^^^^^^^^^^^^^^^^^^^^^^^^^^^^^^^^^^
  File "/home/pearl/alumnimgmtsystem/apps/frappe/frappe/utils/scheduler.py", line 174, in is_scheduler_disabled
    frappe.db.get_single_value("System Settings", "enable_scheduler")
  File "/home/pearl/alumnimgmtsystem/apps/frappe/frappe/database/database.py", line 884, in get_single_value
    ).run()
      ^^^^^
  File "/home/pearl/alumnimgmtsystem/apps/frappe/frappe/query_builder/utils.py", line 80, in execute_query
    result = frappe.db.sql(query, params, *args, **kwargs)  # nosemgrep
             ^^^^^^^^^^^^^^^^^^^^^^^^^^^^^^^^^^^^^^^^^^^^^
  File "/home/pearl/alumnimgmtsystem/apps/frappe/frappe/database/database.py", line 237, in sql
    self.connect()
  File "/home/pearl/alumnimgmtsystem/apps/frappe/frappe/database/database.py", line 135, in connect
    self.get_connection()
  File "/home/pearl/alumnimgmtsystem/apps/frappe/frappe/database/mariadb/database.py", line 105, in get_connection
    conn = self._get_connection()
           ^^^^^^^^^^^^^^^^^^^^^^
  File "/home/pearl/alumnimgmtsystem/apps/frappe/frappe/database/mariadb/database.py", line 111, in _get_connection
    return self.create_connection()
           ^^^^^^^^^^^^^^^^^^^^^^^^
  File "/home/pearl/alumnimgmtsystem/apps/frappe/frappe/database/mariadb/database.py", line 114, in create_connection
    return pymysql.connect(**self.get_connection_settings())
           ^^^^^^^^^^^^^^^^^^^^^^^^^^^^^^^^^^^^^^^^^^^^^^^^^
  File "/home/pearl/alumnimgmtsystem/env/lib/python3.12/site-packages/pymysql/connections.py", line 361, in __init__
    self.connect()
  File "/home/pearl/alumnimgmtsystem/env/lib/python3.12/site-packages/pymysql/connections.py", line 669, in connect
    self._request_authentication()
  File "/home/pearl/alumnimgmtsystem/env/lib/python3.12/site-packages/pymysql/connections.py", line 957, in _request_authentication
    auth_packet = self._read_packet()
                  ^^^^^^^^^^^^^^^^^^^
  File "/home/pearl/alumnimgmtsystem/env/lib/python3.12/site-packages/pymysql/connections.py", line 775, in _read_packet
    packet.raise_for_error()
  File "/home/pearl/alumnimgmtsystem/env/lib/python3.12/site-packages/pymysql/protocol.py", line 219, in raise_for_error
    err.raise_mysql_exception(self._data)
  File "/home/pearl/alumnimgmtsystem/env/lib/python3.12/site-packages/pymysql/err.py", line 150, in raise_mysql_exception
    raise errorclass(errno, errval)
pymysql.err.OperationalError: (1045, "Access denied for user '_9a54aa6450761df8'@'localhost' (using password: YES)")
2025-04-22 19:46:00,967 ERROR scheduler Exception in Enqueue Events for Site library.localhost
Traceback (most recent call last):
  File "/home/pearl/alumnimgmtsystem/apps/frappe/frappe/utils/scheduler.py", line 117, in enqueue_events_for_site
    if is_scheduler_inactive():
       ^^^^^^^^^^^^^^^^^^^^^^^
  File "/home/pearl/alumnimgmtsystem/apps/frappe/frappe/utils/scheduler.py", line 161, in is_scheduler_inactive
    if is_scheduler_disabled(verbose=verbose):
       ^^^^^^^^^^^^^^^^^^^^^^^^^^^^^^^^^^^^^^
  File "/home/pearl/alumnimgmtsystem/apps/frappe/frappe/utils/scheduler.py", line 174, in is_scheduler_disabled
    frappe.db.get_single_value("System Settings", "enable_scheduler")
  File "/home/pearl/alumnimgmtsystem/apps/frappe/frappe/database/database.py", line 884, in get_single_value
    ).run()
      ^^^^^
  File "/home/pearl/alumnimgmtsystem/apps/frappe/frappe/query_builder/utils.py", line 80, in execute_query
    result = frappe.db.sql(query, params, *args, **kwargs)  # nosemgrep
             ^^^^^^^^^^^^^^^^^^^^^^^^^^^^^^^^^^^^^^^^^^^^^
  File "/home/pearl/alumnimgmtsystem/apps/frappe/frappe/database/database.py", line 237, in sql
    self.connect()
  File "/home/pearl/alumnimgmtsystem/apps/frappe/frappe/database/database.py", line 135, in connect
    self.get_connection()
  File "/home/pearl/alumnimgmtsystem/apps/frappe/frappe/database/mariadb/database.py", line 105, in get_connection
    conn = self._get_connection()
           ^^^^^^^^^^^^^^^^^^^^^^
  File "/home/pearl/alumnimgmtsystem/apps/frappe/frappe/database/mariadb/database.py", line 111, in _get_connection
    return self.create_connection()
           ^^^^^^^^^^^^^^^^^^^^^^^^
  File "/home/pearl/alumnimgmtsystem/apps/frappe/frappe/database/mariadb/database.py", line 114, in create_connection
    return pymysql.connect(**self.get_connection_settings())
           ^^^^^^^^^^^^^^^^^^^^^^^^^^^^^^^^^^^^^^^^^^^^^^^^^
  File "/home/pearl/alumnimgmtsystem/env/lib/python3.12/site-packages/pymysql/connections.py", line 361, in __init__
    self.connect()
  File "/home/pearl/alumnimgmtsystem/env/lib/python3.12/site-packages/pymysql/connections.py", line 669, in connect
    self._request_authentication()
  File "/home/pearl/alumnimgmtsystem/env/lib/python3.12/site-packages/pymysql/connections.py", line 957, in _request_authentication
    auth_packet = self._read_packet()
                  ^^^^^^^^^^^^^^^^^^^
  File "/home/pearl/alumnimgmtsystem/env/lib/python3.12/site-packages/pymysql/connections.py", line 775, in _read_packet
    packet.raise_for_error()
  File "/home/pearl/alumnimgmtsystem/env/lib/python3.12/site-packages/pymysql/protocol.py", line 219, in raise_for_error
    err.raise_mysql_exception(self._data)
  File "/home/pearl/alumnimgmtsystem/env/lib/python3.12/site-packages/pymysql/err.py", line 150, in raise_mysql_exception
    raise errorclass(errno, errval)
pymysql.err.OperationalError: (1045, "Access denied for user '_9a54aa6450761df8'@'localhost' (using password: YES)")
2025-04-22 19:50:00,117 ERROR scheduler Exception in Enqueue Events for Site library.localhost
Traceback (most recent call last):
  File "/home/pearl/alumnimgmtsystem/apps/frappe/frappe/utils/scheduler.py", line 117, in enqueue_events_for_site
    if is_scheduler_inactive():
       ^^^^^^^^^^^^^^^^^^^^^^^
  File "/home/pearl/alumnimgmtsystem/apps/frappe/frappe/utils/scheduler.py", line 161, in is_scheduler_inactive
    if is_scheduler_disabled(verbose=verbose):
       ^^^^^^^^^^^^^^^^^^^^^^^^^^^^^^^^^^^^^^
  File "/home/pearl/alumnimgmtsystem/apps/frappe/frappe/utils/scheduler.py", line 174, in is_scheduler_disabled
    frappe.db.get_single_value("System Settings", "enable_scheduler")
  File "/home/pearl/alumnimgmtsystem/apps/frappe/frappe/database/database.py", line 884, in get_single_value
    ).run()
      ^^^^^
  File "/home/pearl/alumnimgmtsystem/apps/frappe/frappe/query_builder/utils.py", line 80, in execute_query
    result = frappe.db.sql(query, params, *args, **kwargs)  # nosemgrep
             ^^^^^^^^^^^^^^^^^^^^^^^^^^^^^^^^^^^^^^^^^^^^^
  File "/home/pearl/alumnimgmtsystem/apps/frappe/frappe/database/database.py", line 237, in sql
    self.connect()
  File "/home/pearl/alumnimgmtsystem/apps/frappe/frappe/database/database.py", line 135, in connect
    self.get_connection()
  File "/home/pearl/alumnimgmtsystem/apps/frappe/frappe/database/mariadb/database.py", line 105, in get_connection
    conn = self._get_connection()
           ^^^^^^^^^^^^^^^^^^^^^^
  File "/home/pearl/alumnimgmtsystem/apps/frappe/frappe/database/mariadb/database.py", line 111, in _get_connection
    return self.create_connection()
           ^^^^^^^^^^^^^^^^^^^^^^^^
  File "/home/pearl/alumnimgmtsystem/apps/frappe/frappe/database/mariadb/database.py", line 114, in create_connection
    return pymysql.connect(**self.get_connection_settings())
           ^^^^^^^^^^^^^^^^^^^^^^^^^^^^^^^^^^^^^^^^^^^^^^^^^
  File "/home/pearl/alumnimgmtsystem/env/lib/python3.12/site-packages/pymysql/connections.py", line 361, in __init__
    self.connect()
  File "/home/pearl/alumnimgmtsystem/env/lib/python3.12/site-packages/pymysql/connections.py", line 669, in connect
    self._request_authentication()
  File "/home/pearl/alumnimgmtsystem/env/lib/python3.12/site-packages/pymysql/connections.py", line 957, in _request_authentication
    auth_packet = self._read_packet()
                  ^^^^^^^^^^^^^^^^^^^
  File "/home/pearl/alumnimgmtsystem/env/lib/python3.12/site-packages/pymysql/connections.py", line 775, in _read_packet
    packet.raise_for_error()
  File "/home/pearl/alumnimgmtsystem/env/lib/python3.12/site-packages/pymysql/protocol.py", line 219, in raise_for_error
    err.raise_mysql_exception(self._data)
  File "/home/pearl/alumnimgmtsystem/env/lib/python3.12/site-packages/pymysql/err.py", line 150, in raise_mysql_exception
    raise errorclass(errno, errval)
pymysql.err.OperationalError: (1045, "Access denied for user '_9a54aa6450761df8'@'localhost' (using password: YES)")
2025-04-22 19:54:00,213 ERROR scheduler Exception in Enqueue Events for Site library.localhost
Traceback (most recent call last):
  File "/home/pearl/alumnimgmtsystem/apps/frappe/frappe/utils/scheduler.py", line 117, in enqueue_events_for_site
    if is_scheduler_inactive():
       ^^^^^^^^^^^^^^^^^^^^^^^
  File "/home/pearl/alumnimgmtsystem/apps/frappe/frappe/utils/scheduler.py", line 161, in is_scheduler_inactive
    if is_scheduler_disabled(verbose=verbose):
       ^^^^^^^^^^^^^^^^^^^^^^^^^^^^^^^^^^^^^^
  File "/home/pearl/alumnimgmtsystem/apps/frappe/frappe/utils/scheduler.py", line 174, in is_scheduler_disabled
    frappe.db.get_single_value("System Settings", "enable_scheduler")
  File "/home/pearl/alumnimgmtsystem/apps/frappe/frappe/database/database.py", line 884, in get_single_value
    ).run()
      ^^^^^
  File "/home/pearl/alumnimgmtsystem/apps/frappe/frappe/query_builder/utils.py", line 80, in execute_query
    result = frappe.db.sql(query, params, *args, **kwargs)  # nosemgrep
             ^^^^^^^^^^^^^^^^^^^^^^^^^^^^^^^^^^^^^^^^^^^^^
  File "/home/pearl/alumnimgmtsystem/apps/frappe/frappe/database/database.py", line 237, in sql
    self.connect()
  File "/home/pearl/alumnimgmtsystem/apps/frappe/frappe/database/database.py", line 135, in connect
    self.get_connection()
  File "/home/pearl/alumnimgmtsystem/apps/frappe/frappe/database/mariadb/database.py", line 105, in get_connection
    conn = self._get_connection()
           ^^^^^^^^^^^^^^^^^^^^^^
  File "/home/pearl/alumnimgmtsystem/apps/frappe/frappe/database/mariadb/database.py", line 111, in _get_connection
    return self.create_connection()
           ^^^^^^^^^^^^^^^^^^^^^^^^
  File "/home/pearl/alumnimgmtsystem/apps/frappe/frappe/database/mariadb/database.py", line 114, in create_connection
    return pymysql.connect(**self.get_connection_settings())
           ^^^^^^^^^^^^^^^^^^^^^^^^^^^^^^^^^^^^^^^^^^^^^^^^^
  File "/home/pearl/alumnimgmtsystem/env/lib/python3.12/site-packages/pymysql/connections.py", line 361, in __init__
    self.connect()
  File "/home/pearl/alumnimgmtsystem/env/lib/python3.12/site-packages/pymysql/connections.py", line 669, in connect
    self._request_authentication()
  File "/home/pearl/alumnimgmtsystem/env/lib/python3.12/site-packages/pymysql/connections.py", line 957, in _request_authentication
    auth_packet = self._read_packet()
                  ^^^^^^^^^^^^^^^^^^^
  File "/home/pearl/alumnimgmtsystem/env/lib/python3.12/site-packages/pymysql/connections.py", line 775, in _read_packet
    packet.raise_for_error()
  File "/home/pearl/alumnimgmtsystem/env/lib/python3.12/site-packages/pymysql/protocol.py", line 219, in raise_for_error
    err.raise_mysql_exception(self._data)
  File "/home/pearl/alumnimgmtsystem/env/lib/python3.12/site-packages/pymysql/err.py", line 150, in raise_mysql_exception
    raise errorclass(errno, errval)
pymysql.err.OperationalError: (1045, "Access denied for user '_9a54aa6450761df8'@'localhost' (using password: YES)")
2025-04-22 19:58:00,336 ERROR scheduler Exception in Enqueue Events for Site library.localhost
Traceback (most recent call last):
  File "/home/pearl/alumnimgmtsystem/apps/frappe/frappe/utils/scheduler.py", line 117, in enqueue_events_for_site
    if is_scheduler_inactive():
       ^^^^^^^^^^^^^^^^^^^^^^^
  File "/home/pearl/alumnimgmtsystem/apps/frappe/frappe/utils/scheduler.py", line 161, in is_scheduler_inactive
    if is_scheduler_disabled(verbose=verbose):
       ^^^^^^^^^^^^^^^^^^^^^^^^^^^^^^^^^^^^^^
  File "/home/pearl/alumnimgmtsystem/apps/frappe/frappe/utils/scheduler.py", line 174, in is_scheduler_disabled
    frappe.db.get_single_value("System Settings", "enable_scheduler")
  File "/home/pearl/alumnimgmtsystem/apps/frappe/frappe/database/database.py", line 884, in get_single_value
    ).run()
      ^^^^^
  File "/home/pearl/alumnimgmtsystem/apps/frappe/frappe/query_builder/utils.py", line 80, in execute_query
    result = frappe.db.sql(query, params, *args, **kwargs)  # nosemgrep
             ^^^^^^^^^^^^^^^^^^^^^^^^^^^^^^^^^^^^^^^^^^^^^
  File "/home/pearl/alumnimgmtsystem/apps/frappe/frappe/database/database.py", line 237, in sql
    self.connect()
  File "/home/pearl/alumnimgmtsystem/apps/frappe/frappe/database/database.py", line 135, in connect
    self.get_connection()
  File "/home/pearl/alumnimgmtsystem/apps/frappe/frappe/database/mariadb/database.py", line 105, in get_connection
    conn = self._get_connection()
           ^^^^^^^^^^^^^^^^^^^^^^
  File "/home/pearl/alumnimgmtsystem/apps/frappe/frappe/database/mariadb/database.py", line 111, in _get_connection
    return self.create_connection()
           ^^^^^^^^^^^^^^^^^^^^^^^^
  File "/home/pearl/alumnimgmtsystem/apps/frappe/frappe/database/mariadb/database.py", line 114, in create_connection
    return pymysql.connect(**self.get_connection_settings())
           ^^^^^^^^^^^^^^^^^^^^^^^^^^^^^^^^^^^^^^^^^^^^^^^^^
  File "/home/pearl/alumnimgmtsystem/env/lib/python3.12/site-packages/pymysql/connections.py", line 361, in __init__
    self.connect()
  File "/home/pearl/alumnimgmtsystem/env/lib/python3.12/site-packages/pymysql/connections.py", line 669, in connect
    self._request_authentication()
  File "/home/pearl/alumnimgmtsystem/env/lib/python3.12/site-packages/pymysql/connections.py", line 957, in _request_authentication
    auth_packet = self._read_packet()
                  ^^^^^^^^^^^^^^^^^^^
  File "/home/pearl/alumnimgmtsystem/env/lib/python3.12/site-packages/pymysql/connections.py", line 775, in _read_packet
    packet.raise_for_error()
  File "/home/pearl/alumnimgmtsystem/env/lib/python3.12/site-packages/pymysql/protocol.py", line 219, in raise_for_error
    err.raise_mysql_exception(self._data)
  File "/home/pearl/alumnimgmtsystem/env/lib/python3.12/site-packages/pymysql/err.py", line 150, in raise_mysql_exception
    raise errorclass(errno, errval)
pymysql.err.OperationalError: (1045, "Access denied for user '_9a54aa6450761df8'@'localhost' (using password: YES)")
2025-04-22 20:02:00,432 ERROR scheduler Exception in Enqueue Events for Site library.localhost
Traceback (most recent call last):
  File "/home/pearl/alumnimgmtsystem/apps/frappe/frappe/utils/scheduler.py", line 117, in enqueue_events_for_site
    if is_scheduler_inactive():
       ^^^^^^^^^^^^^^^^^^^^^^^
  File "/home/pearl/alumnimgmtsystem/apps/frappe/frappe/utils/scheduler.py", line 161, in is_scheduler_inactive
    if is_scheduler_disabled(verbose=verbose):
       ^^^^^^^^^^^^^^^^^^^^^^^^^^^^^^^^^^^^^^
  File "/home/pearl/alumnimgmtsystem/apps/frappe/frappe/utils/scheduler.py", line 174, in is_scheduler_disabled
    frappe.db.get_single_value("System Settings", "enable_scheduler")
  File "/home/pearl/alumnimgmtsystem/apps/frappe/frappe/database/database.py", line 884, in get_single_value
    ).run()
      ^^^^^
  File "/home/pearl/alumnimgmtsystem/apps/frappe/frappe/query_builder/utils.py", line 80, in execute_query
    result = frappe.db.sql(query, params, *args, **kwargs)  # nosemgrep
             ^^^^^^^^^^^^^^^^^^^^^^^^^^^^^^^^^^^^^^^^^^^^^
  File "/home/pearl/alumnimgmtsystem/apps/frappe/frappe/database/database.py", line 237, in sql
    self.connect()
  File "/home/pearl/alumnimgmtsystem/apps/frappe/frappe/database/database.py", line 135, in connect
    self.get_connection()
  File "/home/pearl/alumnimgmtsystem/apps/frappe/frappe/database/mariadb/database.py", line 105, in get_connection
    conn = self._get_connection()
           ^^^^^^^^^^^^^^^^^^^^^^
  File "/home/pearl/alumnimgmtsystem/apps/frappe/frappe/database/mariadb/database.py", line 111, in _get_connection
    return self.create_connection()
           ^^^^^^^^^^^^^^^^^^^^^^^^
  File "/home/pearl/alumnimgmtsystem/apps/frappe/frappe/database/mariadb/database.py", line 114, in create_connection
    return pymysql.connect(**self.get_connection_settings())
           ^^^^^^^^^^^^^^^^^^^^^^^^^^^^^^^^^^^^^^^^^^^^^^^^^
  File "/home/pearl/alumnimgmtsystem/env/lib/python3.12/site-packages/pymysql/connections.py", line 361, in __init__
    self.connect()
  File "/home/pearl/alumnimgmtsystem/env/lib/python3.12/site-packages/pymysql/connections.py", line 669, in connect
    self._request_authentication()
  File "/home/pearl/alumnimgmtsystem/env/lib/python3.12/site-packages/pymysql/connections.py", line 957, in _request_authentication
    auth_packet = self._read_packet()
                  ^^^^^^^^^^^^^^^^^^^
  File "/home/pearl/alumnimgmtsystem/env/lib/python3.12/site-packages/pymysql/connections.py", line 775, in _read_packet
    packet.raise_for_error()
  File "/home/pearl/alumnimgmtsystem/env/lib/python3.12/site-packages/pymysql/protocol.py", line 219, in raise_for_error
    err.raise_mysql_exception(self._data)
  File "/home/pearl/alumnimgmtsystem/env/lib/python3.12/site-packages/pymysql/err.py", line 150, in raise_mysql_exception
    raise errorclass(errno, errval)
pymysql.err.OperationalError: (1045, "Access denied for user '_9a54aa6450761df8'@'localhost' (using password: YES)")
2025-04-22 20:06:00,531 ERROR scheduler Exception in Enqueue Events for Site library.localhost
Traceback (most recent call last):
  File "/home/pearl/alumnimgmtsystem/apps/frappe/frappe/utils/scheduler.py", line 117, in enqueue_events_for_site
    if is_scheduler_inactive():
       ^^^^^^^^^^^^^^^^^^^^^^^
  File "/home/pearl/alumnimgmtsystem/apps/frappe/frappe/utils/scheduler.py", line 161, in is_scheduler_inactive
    if is_scheduler_disabled(verbose=verbose):
       ^^^^^^^^^^^^^^^^^^^^^^^^^^^^^^^^^^^^^^
  File "/home/pearl/alumnimgmtsystem/apps/frappe/frappe/utils/scheduler.py", line 174, in is_scheduler_disabled
    frappe.db.get_single_value("System Settings", "enable_scheduler")
  File "/home/pearl/alumnimgmtsystem/apps/frappe/frappe/database/database.py", line 884, in get_single_value
    ).run()
      ^^^^^
  File "/home/pearl/alumnimgmtsystem/apps/frappe/frappe/query_builder/utils.py", line 80, in execute_query
    result = frappe.db.sql(query, params, *args, **kwargs)  # nosemgrep
             ^^^^^^^^^^^^^^^^^^^^^^^^^^^^^^^^^^^^^^^^^^^^^
  File "/home/pearl/alumnimgmtsystem/apps/frappe/frappe/database/database.py", line 237, in sql
    self.connect()
  File "/home/pearl/alumnimgmtsystem/apps/frappe/frappe/database/database.py", line 135, in connect
    self.get_connection()
  File "/home/pearl/alumnimgmtsystem/apps/frappe/frappe/database/mariadb/database.py", line 105, in get_connection
    conn = self._get_connection()
           ^^^^^^^^^^^^^^^^^^^^^^
  File "/home/pearl/alumnimgmtsystem/apps/frappe/frappe/database/mariadb/database.py", line 111, in _get_connection
    return self.create_connection()
           ^^^^^^^^^^^^^^^^^^^^^^^^
  File "/home/pearl/alumnimgmtsystem/apps/frappe/frappe/database/mariadb/database.py", line 114, in create_connection
    return pymysql.connect(**self.get_connection_settings())
           ^^^^^^^^^^^^^^^^^^^^^^^^^^^^^^^^^^^^^^^^^^^^^^^^^
  File "/home/pearl/alumnimgmtsystem/env/lib/python3.12/site-packages/pymysql/connections.py", line 361, in __init__
    self.connect()
  File "/home/pearl/alumnimgmtsystem/env/lib/python3.12/site-packages/pymysql/connections.py", line 669, in connect
    self._request_authentication()
  File "/home/pearl/alumnimgmtsystem/env/lib/python3.12/site-packages/pymysql/connections.py", line 957, in _request_authentication
    auth_packet = self._read_packet()
                  ^^^^^^^^^^^^^^^^^^^
  File "/home/pearl/alumnimgmtsystem/env/lib/python3.12/site-packages/pymysql/connections.py", line 775, in _read_packet
    packet.raise_for_error()
  File "/home/pearl/alumnimgmtsystem/env/lib/python3.12/site-packages/pymysql/protocol.py", line 219, in raise_for_error
    err.raise_mysql_exception(self._data)
  File "/home/pearl/alumnimgmtsystem/env/lib/python3.12/site-packages/pymysql/err.py", line 150, in raise_mysql_exception
    raise errorclass(errno, errval)
pymysql.err.OperationalError: (1045, "Access denied for user '_9a54aa6450761df8'@'localhost' (using password: YES)")
2025-04-22 20:10:00,726 ERROR scheduler Exception in Enqueue Events for Site library.localhost
Traceback (most recent call last):
  File "/home/pearl/alumnimgmtsystem/apps/frappe/frappe/utils/scheduler.py", line 117, in enqueue_events_for_site
    if is_scheduler_inactive():
       ^^^^^^^^^^^^^^^^^^^^^^^
  File "/home/pearl/alumnimgmtsystem/apps/frappe/frappe/utils/scheduler.py", line 161, in is_scheduler_inactive
    if is_scheduler_disabled(verbose=verbose):
       ^^^^^^^^^^^^^^^^^^^^^^^^^^^^^^^^^^^^^^
  File "/home/pearl/alumnimgmtsystem/apps/frappe/frappe/utils/scheduler.py", line 174, in is_scheduler_disabled
    frappe.db.get_single_value("System Settings", "enable_scheduler")
  File "/home/pearl/alumnimgmtsystem/apps/frappe/frappe/database/database.py", line 884, in get_single_value
    ).run()
      ^^^^^
  File "/home/pearl/alumnimgmtsystem/apps/frappe/frappe/query_builder/utils.py", line 80, in execute_query
    result = frappe.db.sql(query, params, *args, **kwargs)  # nosemgrep
             ^^^^^^^^^^^^^^^^^^^^^^^^^^^^^^^^^^^^^^^^^^^^^
  File "/home/pearl/alumnimgmtsystem/apps/frappe/frappe/database/database.py", line 237, in sql
    self.connect()
  File "/home/pearl/alumnimgmtsystem/apps/frappe/frappe/database/database.py", line 135, in connect
    self.get_connection()
  File "/home/pearl/alumnimgmtsystem/apps/frappe/frappe/database/mariadb/database.py", line 105, in get_connection
    conn = self._get_connection()
           ^^^^^^^^^^^^^^^^^^^^^^
  File "/home/pearl/alumnimgmtsystem/apps/frappe/frappe/database/mariadb/database.py", line 111, in _get_connection
    return self.create_connection()
           ^^^^^^^^^^^^^^^^^^^^^^^^
  File "/home/pearl/alumnimgmtsystem/apps/frappe/frappe/database/mariadb/database.py", line 114, in create_connection
    return pymysql.connect(**self.get_connection_settings())
           ^^^^^^^^^^^^^^^^^^^^^^^^^^^^^^^^^^^^^^^^^^^^^^^^^
  File "/home/pearl/alumnimgmtsystem/env/lib/python3.12/site-packages/pymysql/connections.py", line 361, in __init__
    self.connect()
  File "/home/pearl/alumnimgmtsystem/env/lib/python3.12/site-packages/pymysql/connections.py", line 669, in connect
    self._request_authentication()
  File "/home/pearl/alumnimgmtsystem/env/lib/python3.12/site-packages/pymysql/connections.py", line 957, in _request_authentication
    auth_packet = self._read_packet()
                  ^^^^^^^^^^^^^^^^^^^
  File "/home/pearl/alumnimgmtsystem/env/lib/python3.12/site-packages/pymysql/connections.py", line 775, in _read_packet
    packet.raise_for_error()
  File "/home/pearl/alumnimgmtsystem/env/lib/python3.12/site-packages/pymysql/protocol.py", line 219, in raise_for_error
    err.raise_mysql_exception(self._data)
  File "/home/pearl/alumnimgmtsystem/env/lib/python3.12/site-packages/pymysql/err.py", line 150, in raise_mysql_exception
    raise errorclass(errno, errval)
pymysql.err.OperationalError: (1045, "Access denied for user '_9a54aa6450761df8'@'localhost' (using password: YES)")
2025-04-22 20:14:00,744 ERROR scheduler Exception in Enqueue Events for Site library.localhost
Traceback (most recent call last):
  File "/home/pearl/alumnimgmtsystem/apps/frappe/frappe/utils/scheduler.py", line 117, in enqueue_events_for_site
    if is_scheduler_inactive():
       ^^^^^^^^^^^^^^^^^^^^^^^
  File "/home/pearl/alumnimgmtsystem/apps/frappe/frappe/utils/scheduler.py", line 161, in is_scheduler_inactive
    if is_scheduler_disabled(verbose=verbose):
       ^^^^^^^^^^^^^^^^^^^^^^^^^^^^^^^^^^^^^^
  File "/home/pearl/alumnimgmtsystem/apps/frappe/frappe/utils/scheduler.py", line 174, in is_scheduler_disabled
    frappe.db.get_single_value("System Settings", "enable_scheduler")
  File "/home/pearl/alumnimgmtsystem/apps/frappe/frappe/database/database.py", line 884, in get_single_value
    ).run()
      ^^^^^
  File "/home/pearl/alumnimgmtsystem/apps/frappe/frappe/query_builder/utils.py", line 80, in execute_query
    result = frappe.db.sql(query, params, *args, **kwargs)  # nosemgrep
             ^^^^^^^^^^^^^^^^^^^^^^^^^^^^^^^^^^^^^^^^^^^^^
  File "/home/pearl/alumnimgmtsystem/apps/frappe/frappe/database/database.py", line 237, in sql
    self.connect()
  File "/home/pearl/alumnimgmtsystem/apps/frappe/frappe/database/database.py", line 135, in connect
    self.get_connection()
  File "/home/pearl/alumnimgmtsystem/apps/frappe/frappe/database/mariadb/database.py", line 105, in get_connection
    conn = self._get_connection()
           ^^^^^^^^^^^^^^^^^^^^^^
  File "/home/pearl/alumnimgmtsystem/apps/frappe/frappe/database/mariadb/database.py", line 111, in _get_connection
    return self.create_connection()
           ^^^^^^^^^^^^^^^^^^^^^^^^
  File "/home/pearl/alumnimgmtsystem/apps/frappe/frappe/database/mariadb/database.py", line 114, in create_connection
    return pymysql.connect(**self.get_connection_settings())
           ^^^^^^^^^^^^^^^^^^^^^^^^^^^^^^^^^^^^^^^^^^^^^^^^^
  File "/home/pearl/alumnimgmtsystem/env/lib/python3.12/site-packages/pymysql/connections.py", line 361, in __init__
    self.connect()
  File "/home/pearl/alumnimgmtsystem/env/lib/python3.12/site-packages/pymysql/connections.py", line 669, in connect
    self._request_authentication()
  File "/home/pearl/alumnimgmtsystem/env/lib/python3.12/site-packages/pymysql/connections.py", line 957, in _request_authentication
    auth_packet = self._read_packet()
                  ^^^^^^^^^^^^^^^^^^^
  File "/home/pearl/alumnimgmtsystem/env/lib/python3.12/site-packages/pymysql/connections.py", line 775, in _read_packet
    packet.raise_for_error()
  File "/home/pearl/alumnimgmtsystem/env/lib/python3.12/site-packages/pymysql/protocol.py", line 219, in raise_for_error
    err.raise_mysql_exception(self._data)
  File "/home/pearl/alumnimgmtsystem/env/lib/python3.12/site-packages/pymysql/err.py", line 150, in raise_mysql_exception
    raise errorclass(errno, errval)
pymysql.err.OperationalError: (1045, "Access denied for user '_9a54aa6450761df8'@'localhost' (using password: YES)")
