2025-04-19 15:10:00,578 ERROR scheduler Exception in Enqueue Events for Site library.localhost
Traceback (most recent call last):
  File "/home/pearl/alumnimgmtsystem/apps/frappe/frappe/utils/scheduler.py", line 117, in enqueue_events_for_site
    if is_scheduler_inactive():
       ^^^^^^^^^^^^^^^^^^^^^^^
  File "/home/pearl/alumnimgmtsystem/apps/frappe/frappe/utils/scheduler.py", line 161, in is_scheduler_inactive
    if is_scheduler_disabled(verbose=verbose):
       ^^^^^^^^^^^^^^^^^^^^^^^^^^^^^^^^^^^^^^
  File "/home/pearl/alumnimgmtsystem/apps/frappe/frappe/utils/scheduler.py", line 174, in is_scheduler_disabled
    frappe.db.get_single_value("System Settings", "enable_scheduler")
  File "/home/pearl/alumnimgmtsystem/apps/frappe/frappe/database/database.py", line 884, in get_single_value
    ).run()
      ^^^^^
  File "/home/pearl/alumnimgmtsystem/apps/frappe/frappe/query_builder/utils.py", line 80, in execute_query
    result = frappe.db.sql(query, params, *args, **kwargs)  # nosemgrep
             ^^^^^^^^^^^^^^^^^^^^^^^^^^^^^^^^^^^^^^^^^^^^^
  File "/home/pearl/alumnimgmtsystem/apps/frappe/frappe/database/database.py", line 237, in sql
    self.connect()
  File "/home/pearl/alumnimgmtsystem/apps/frappe/frappe/database/database.py", line 135, in connect
    self.get_connection()
  File "/home/pearl/alumnimgmtsystem/apps/frappe/frappe/database/mariadb/database.py", line 105, in get_connection
    conn = self._get_connection()
           ^^^^^^^^^^^^^^^^^^^^^^
  File "/home/pearl/alumnimgmtsystem/apps/frappe/frappe/database/mariadb/database.py", line 111, in _get_connection
    return self.create_connection()
           ^^^^^^^^^^^^^^^^^^^^^^^^
  File "/home/pearl/alumnimgmtsystem/apps/frappe/frappe/database/mariadb/database.py", line 114, in create_connection
    return pymysql.connect(**self.get_connection_settings())
           ^^^^^^^^^^^^^^^^^^^^^^^^^^^^^^^^^^^^^^^^^^^^^^^^^
  File "/home/pearl/alumnimgmtsystem/env/lib/python3.12/site-packages/pymysql/connections.py", line 361, in __init__
    self.connect()
  File "/home/pearl/alumnimgmtsystem/env/lib/python3.12/site-packages/pymysql/connections.py", line 669, in connect
    self._request_authentication()
  File "/home/pearl/alumnimgmtsystem/env/lib/python3.12/site-packages/pymysql/connections.py", line 957, in _request_authentication
    auth_packet = self._read_packet()
                  ^^^^^^^^^^^^^^^^^^^
  File "/home/pearl/alumnimgmtsystem/env/lib/python3.12/site-packages/pymysql/connections.py", line 775, in _read_packet
    packet.raise_for_error()
  File "/home/pearl/alumnimgmtsystem/env/lib/python3.12/site-packages/pymysql/protocol.py", line 219, in raise_for_error
    err.raise_mysql_exception(self._data)
  File "/home/pearl/alumnimgmtsystem/env/lib/python3.12/site-packages/pymysql/err.py", line 150, in raise_mysql_exception
    raise errorclass(errno, errval)
pymysql.err.OperationalError: (1045, "Access denied for user '_9a54aa6450761df8'@'localhost' (using password: YES)")
2025-04-19 15:14:00,736 ERROR scheduler Exception in Enqueue Events for Site library.localhost
Traceback (most recent call last):
  File "/home/pearl/alumnimgmtsystem/apps/frappe/frappe/utils/scheduler.py", line 117, in enqueue_events_for_site
    if is_scheduler_inactive():
       ^^^^^^^^^^^^^^^^^^^^^^^
  File "/home/pearl/alumnimgmtsystem/apps/frappe/frappe/utils/scheduler.py", line 161, in is_scheduler_inactive
    if is_scheduler_disabled(verbose=verbose):
       ^^^^^^^^^^^^^^^^^^^^^^^^^^^^^^^^^^^^^^
  File "/home/pearl/alumnimgmtsystem/apps/frappe/frappe/utils/scheduler.py", line 174, in is_scheduler_disabled
    frappe.db.get_single_value("System Settings", "enable_scheduler")
  File "/home/pearl/alumnimgmtsystem/apps/frappe/frappe/database/database.py", line 884, in get_single_value
    ).run()
      ^^^^^
  File "/home/pearl/alumnimgmtsystem/apps/frappe/frappe/query_builder/utils.py", line 80, in execute_query
    result = frappe.db.sql(query, params, *args, **kwargs)  # nosemgrep
             ^^^^^^^^^^^^^^^^^^^^^^^^^^^^^^^^^^^^^^^^^^^^^
  File "/home/pearl/alumnimgmtsystem/apps/frappe/frappe/database/database.py", line 237, in sql
    self.connect()
  File "/home/pearl/alumnimgmtsystem/apps/frappe/frappe/database/database.py", line 135, in connect
    self.get_connection()
  File "/home/pearl/alumnimgmtsystem/apps/frappe/frappe/database/mariadb/database.py", line 105, in get_connection
    conn = self._get_connection()
           ^^^^^^^^^^^^^^^^^^^^^^
  File "/home/pearl/alumnimgmtsystem/apps/frappe/frappe/database/mariadb/database.py", line 111, in _get_connection
    return self.create_connection()
           ^^^^^^^^^^^^^^^^^^^^^^^^
  File "/home/pearl/alumnimgmtsystem/apps/frappe/frappe/database/mariadb/database.py", line 114, in create_connection
    return pymysql.connect(**self.get_connection_settings())
           ^^^^^^^^^^^^^^^^^^^^^^^^^^^^^^^^^^^^^^^^^^^^^^^^^
  File "/home/pearl/alumnimgmtsystem/env/lib/python3.12/site-packages/pymysql/connections.py", line 361, in __init__
    self.connect()
  File "/home/pearl/alumnimgmtsystem/env/lib/python3.12/site-packages/pymysql/connections.py", line 669, in connect
    self._request_authentication()
  File "/home/pearl/alumnimgmtsystem/env/lib/python3.12/site-packages/pymysql/connections.py", line 957, in _request_authentication
    auth_packet = self._read_packet()
                  ^^^^^^^^^^^^^^^^^^^
  File "/home/pearl/alumnimgmtsystem/env/lib/python3.12/site-packages/pymysql/connections.py", line 775, in _read_packet
    packet.raise_for_error()
  File "/home/pearl/alumnimgmtsystem/env/lib/python3.12/site-packages/pymysql/protocol.py", line 219, in raise_for_error
    err.raise_mysql_exception(self._data)
  File "/home/pearl/alumnimgmtsystem/env/lib/python3.12/site-packages/pymysql/err.py", line 150, in raise_mysql_exception
    raise errorclass(errno, errval)
pymysql.err.OperationalError: (1045, "Access denied for user '_9a54aa6450761df8'@'localhost' (using password: YES)")
2025-04-19 15:20:11,614 ERROR scheduler Exception in Enqueue Events for Site library.localhost
Traceback (most recent call last):
  File "/home/pearl/alumnimgmtsystem/apps/frappe/frappe/utils/scheduler.py", line 117, in enqueue_events_for_site
    if is_scheduler_inactive():
       ^^^^^^^^^^^^^^^^^^^^^^^
  File "/home/pearl/alumnimgmtsystem/apps/frappe/frappe/utils/scheduler.py", line 161, in is_scheduler_inactive
    if is_scheduler_disabled(verbose=verbose):
       ^^^^^^^^^^^^^^^^^^^^^^^^^^^^^^^^^^^^^^
  File "/home/pearl/alumnimgmtsystem/apps/frappe/frappe/utils/scheduler.py", line 174, in is_scheduler_disabled
    frappe.db.get_single_value("System Settings", "enable_scheduler")
  File "/home/pearl/alumnimgmtsystem/apps/frappe/frappe/database/database.py", line 884, in get_single_value
    ).run()
      ^^^^^
  File "/home/pearl/alumnimgmtsystem/apps/frappe/frappe/query_builder/utils.py", line 80, in execute_query
    result = frappe.db.sql(query, params, *args, **kwargs)  # nosemgrep
             ^^^^^^^^^^^^^^^^^^^^^^^^^^^^^^^^^^^^^^^^^^^^^
  File "/home/pearl/alumnimgmtsystem/apps/frappe/frappe/database/database.py", line 237, in sql
    self.connect()
  File "/home/pearl/alumnimgmtsystem/apps/frappe/frappe/database/database.py", line 135, in connect
    self.get_connection()
  File "/home/pearl/alumnimgmtsystem/apps/frappe/frappe/database/mariadb/database.py", line 105, in get_connection
    conn = self._get_connection()
           ^^^^^^^^^^^^^^^^^^^^^^
  File "/home/pearl/alumnimgmtsystem/apps/frappe/frappe/database/mariadb/database.py", line 111, in _get_connection
    return self.create_connection()
           ^^^^^^^^^^^^^^^^^^^^^^^^
  File "/home/pearl/alumnimgmtsystem/apps/frappe/frappe/database/mariadb/database.py", line 114, in create_connection
    return pymysql.connect(**self.get_connection_settings())
           ^^^^^^^^^^^^^^^^^^^^^^^^^^^^^^^^^^^^^^^^^^^^^^^^^
  File "/home/pearl/alumnimgmtsystem/env/lib/python3.12/site-packages/pymysql/connections.py", line 361, in __init__
    self.connect()
  File "/home/pearl/alumnimgmtsystem/env/lib/python3.12/site-packages/pymysql/connections.py", line 669, in connect
    self._request_authentication()
  File "/home/pearl/alumnimgmtsystem/env/lib/python3.12/site-packages/pymysql/connections.py", line 957, in _request_authentication
    auth_packet = self._read_packet()
                  ^^^^^^^^^^^^^^^^^^^
  File "/home/pearl/alumnimgmtsystem/env/lib/python3.12/site-packages/pymysql/connections.py", line 775, in _read_packet
    packet.raise_for_error()
  File "/home/pearl/alumnimgmtsystem/env/lib/python3.12/site-packages/pymysql/protocol.py", line 219, in raise_for_error
    err.raise_mysql_exception(self._data)
  File "/home/pearl/alumnimgmtsystem/env/lib/python3.12/site-packages/pymysql/err.py", line 150, in raise_mysql_exception
    raise errorclass(errno, errval)
pymysql.err.OperationalError: (1045, "Access denied for user '_9a54aa6450761df8'@'localhost' (using password: YES)")
2025-04-19 15:22:00,692 ERROR scheduler Exception in Enqueue Events for Site library.localhost
Traceback (most recent call last):
  File "/home/pearl/alumnimgmtsystem/apps/frappe/frappe/utils/scheduler.py", line 117, in enqueue_events_for_site
    if is_scheduler_inactive():
       ^^^^^^^^^^^^^^^^^^^^^^^
  File "/home/pearl/alumnimgmtsystem/apps/frappe/frappe/utils/scheduler.py", line 161, in is_scheduler_inactive
    if is_scheduler_disabled(verbose=verbose):
       ^^^^^^^^^^^^^^^^^^^^^^^^^^^^^^^^^^^^^^
  File "/home/pearl/alumnimgmtsystem/apps/frappe/frappe/utils/scheduler.py", line 174, in is_scheduler_disabled
    frappe.db.get_single_value("System Settings", "enable_scheduler")
  File "/home/pearl/alumnimgmtsystem/apps/frappe/frappe/database/database.py", line 884, in get_single_value
    ).run()
      ^^^^^
  File "/home/pearl/alumnimgmtsystem/apps/frappe/frappe/query_builder/utils.py", line 80, in execute_query
    result = frappe.db.sql(query, params, *args, **kwargs)  # nosemgrep
             ^^^^^^^^^^^^^^^^^^^^^^^^^^^^^^^^^^^^^^^^^^^^^
  File "/home/pearl/alumnimgmtsystem/apps/frappe/frappe/database/database.py", line 237, in sql
    self.connect()
  File "/home/pearl/alumnimgmtsystem/apps/frappe/frappe/database/database.py", line 135, in connect
    self.get_connection()
  File "/home/pearl/alumnimgmtsystem/apps/frappe/frappe/database/mariadb/database.py", line 105, in get_connection
    conn = self._get_connection()
           ^^^^^^^^^^^^^^^^^^^^^^
  File "/home/pearl/alumnimgmtsystem/apps/frappe/frappe/database/mariadb/database.py", line 111, in _get_connection
    return self.create_connection()
           ^^^^^^^^^^^^^^^^^^^^^^^^
  File "/home/pearl/alumnimgmtsystem/apps/frappe/frappe/database/mariadb/database.py", line 114, in create_connection
    return pymysql.connect(**self.get_connection_settings())
           ^^^^^^^^^^^^^^^^^^^^^^^^^^^^^^^^^^^^^^^^^^^^^^^^^
  File "/home/pearl/alumnimgmtsystem/env/lib/python3.12/site-packages/pymysql/connections.py", line 361, in __init__
    self.connect()
  File "/home/pearl/alumnimgmtsystem/env/lib/python3.12/site-packages/pymysql/connections.py", line 669, in connect
    self._request_authentication()
  File "/home/pearl/alumnimgmtsystem/env/lib/python3.12/site-packages/pymysql/connections.py", line 957, in _request_authentication
    auth_packet = self._read_packet()
                  ^^^^^^^^^^^^^^^^^^^
  File "/home/pearl/alumnimgmtsystem/env/lib/python3.12/site-packages/pymysql/connections.py", line 775, in _read_packet
    packet.raise_for_error()
  File "/home/pearl/alumnimgmtsystem/env/lib/python3.12/site-packages/pymysql/protocol.py", line 219, in raise_for_error
    err.raise_mysql_exception(self._data)
  File "/home/pearl/alumnimgmtsystem/env/lib/python3.12/site-packages/pymysql/err.py", line 150, in raise_mysql_exception
    raise errorclass(errno, errval)
pymysql.err.OperationalError: (1045, "Access denied for user '_9a54aa6450761df8'@'localhost' (using password: YES)")
2025-04-19 15:26:00,828 ERROR scheduler Exception in Enqueue Events for Site library.localhost
Traceback (most recent call last):
  File "/home/pearl/alumnimgmtsystem/apps/frappe/frappe/utils/scheduler.py", line 117, in enqueue_events_for_site
    if is_scheduler_inactive():
       ^^^^^^^^^^^^^^^^^^^^^^^
  File "/home/pearl/alumnimgmtsystem/apps/frappe/frappe/utils/scheduler.py", line 161, in is_scheduler_inactive
    if is_scheduler_disabled(verbose=verbose):
       ^^^^^^^^^^^^^^^^^^^^^^^^^^^^^^^^^^^^^^
  File "/home/pearl/alumnimgmtsystem/apps/frappe/frappe/utils/scheduler.py", line 174, in is_scheduler_disabled
    frappe.db.get_single_value("System Settings", "enable_scheduler")
  File "/home/pearl/alumnimgmtsystem/apps/frappe/frappe/database/database.py", line 884, in get_single_value
    ).run()
      ^^^^^
  File "/home/pearl/alumnimgmtsystem/apps/frappe/frappe/query_builder/utils.py", line 80, in execute_query
    result = frappe.db.sql(query, params, *args, **kwargs)  # nosemgrep
             ^^^^^^^^^^^^^^^^^^^^^^^^^^^^^^^^^^^^^^^^^^^^^
  File "/home/pearl/alumnimgmtsystem/apps/frappe/frappe/database/database.py", line 237, in sql
    self.connect()
  File "/home/pearl/alumnimgmtsystem/apps/frappe/frappe/database/database.py", line 135, in connect
    self.get_connection()
  File "/home/pearl/alumnimgmtsystem/apps/frappe/frappe/database/mariadb/database.py", line 105, in get_connection
    conn = self._get_connection()
           ^^^^^^^^^^^^^^^^^^^^^^
  File "/home/pearl/alumnimgmtsystem/apps/frappe/frappe/database/mariadb/database.py", line 111, in _get_connection
    return self.create_connection()
           ^^^^^^^^^^^^^^^^^^^^^^^^
  File "/home/pearl/alumnimgmtsystem/apps/frappe/frappe/database/mariadb/database.py", line 114, in create_connection
    return pymysql.connect(**self.get_connection_settings())
           ^^^^^^^^^^^^^^^^^^^^^^^^^^^^^^^^^^^^^^^^^^^^^^^^^
  File "/home/pearl/alumnimgmtsystem/env/lib/python3.12/site-packages/pymysql/connections.py", line 361, in __init__
    self.connect()
  File "/home/pearl/alumnimgmtsystem/env/lib/python3.12/site-packages/pymysql/connections.py", line 669, in connect
    self._request_authentication()
  File "/home/pearl/alumnimgmtsystem/env/lib/python3.12/site-packages/pymysql/connections.py", line 957, in _request_authentication
    auth_packet = self._read_packet()
                  ^^^^^^^^^^^^^^^^^^^
  File "/home/pearl/alumnimgmtsystem/env/lib/python3.12/site-packages/pymysql/connections.py", line 775, in _read_packet
    packet.raise_for_error()
  File "/home/pearl/alumnimgmtsystem/env/lib/python3.12/site-packages/pymysql/protocol.py", line 219, in raise_for_error
    err.raise_mysql_exception(self._data)
  File "/home/pearl/alumnimgmtsystem/env/lib/python3.12/site-packages/pymysql/err.py", line 150, in raise_mysql_exception
    raise errorclass(errno, errval)
pymysql.err.OperationalError: (1045, "Access denied for user '_9a54aa6450761df8'@'localhost' (using password: YES)")
2025-04-19 15:30:00,840 ERROR scheduler Exception in Enqueue Events for Site library.localhost
Traceback (most recent call last):
  File "/home/pearl/alumnimgmtsystem/apps/frappe/frappe/utils/scheduler.py", line 117, in enqueue_events_for_site
    if is_scheduler_inactive():
       ^^^^^^^^^^^^^^^^^^^^^^^
  File "/home/pearl/alumnimgmtsystem/apps/frappe/frappe/utils/scheduler.py", line 161, in is_scheduler_inactive
    if is_scheduler_disabled(verbose=verbose):
       ^^^^^^^^^^^^^^^^^^^^^^^^^^^^^^^^^^^^^^
  File "/home/pearl/alumnimgmtsystem/apps/frappe/frappe/utils/scheduler.py", line 174, in is_scheduler_disabled
    frappe.db.get_single_value("System Settings", "enable_scheduler")
  File "/home/pearl/alumnimgmtsystem/apps/frappe/frappe/database/database.py", line 884, in get_single_value
    ).run()
      ^^^^^
  File "/home/pearl/alumnimgmtsystem/apps/frappe/frappe/query_builder/utils.py", line 80, in execute_query
    result = frappe.db.sql(query, params, *args, **kwargs)  # nosemgrep
             ^^^^^^^^^^^^^^^^^^^^^^^^^^^^^^^^^^^^^^^^^^^^^
  File "/home/pearl/alumnimgmtsystem/apps/frappe/frappe/database/database.py", line 237, in sql
    self.connect()
  File "/home/pearl/alumnimgmtsystem/apps/frappe/frappe/database/database.py", line 135, in connect
    self.get_connection()
  File "/home/pearl/alumnimgmtsystem/apps/frappe/frappe/database/mariadb/database.py", line 105, in get_connection
    conn = self._get_connection()
           ^^^^^^^^^^^^^^^^^^^^^^
  File "/home/pearl/alumnimgmtsystem/apps/frappe/frappe/database/mariadb/database.py", line 111, in _get_connection
    return self.create_connection()
           ^^^^^^^^^^^^^^^^^^^^^^^^
  File "/home/pearl/alumnimgmtsystem/apps/frappe/frappe/database/mariadb/database.py", line 114, in create_connection
    return pymysql.connect(**self.get_connection_settings())
           ^^^^^^^^^^^^^^^^^^^^^^^^^^^^^^^^^^^^^^^^^^^^^^^^^
  File "/home/pearl/alumnimgmtsystem/env/lib/python3.12/site-packages/pymysql/connections.py", line 361, in __init__
    self.connect()
  File "/home/pearl/alumnimgmtsystem/env/lib/python3.12/site-packages/pymysql/connections.py", line 669, in connect
    self._request_authentication()
  File "/home/pearl/alumnimgmtsystem/env/lib/python3.12/site-packages/pymysql/connections.py", line 957, in _request_authentication
    auth_packet = self._read_packet()
                  ^^^^^^^^^^^^^^^^^^^
  File "/home/pearl/alumnimgmtsystem/env/lib/python3.12/site-packages/pymysql/connections.py", line 775, in _read_packet
    packet.raise_for_error()
  File "/home/pearl/alumnimgmtsystem/env/lib/python3.12/site-packages/pymysql/protocol.py", line 219, in raise_for_error
    err.raise_mysql_exception(self._data)
  File "/home/pearl/alumnimgmtsystem/env/lib/python3.12/site-packages/pymysql/err.py", line 150, in raise_mysql_exception
    raise errorclass(errno, errval)
pymysql.err.OperationalError: (1045, "Access denied for user '_9a54aa6450761df8'@'localhost' (using password: YES)")
2025-04-19 15:34:00,975 ERROR scheduler Exception in Enqueue Events for Site library.localhost
Traceback (most recent call last):
  File "/home/pearl/alumnimgmtsystem/apps/frappe/frappe/utils/scheduler.py", line 117, in enqueue_events_for_site
    if is_scheduler_inactive():
       ^^^^^^^^^^^^^^^^^^^^^^^
  File "/home/pearl/alumnimgmtsystem/apps/frappe/frappe/utils/scheduler.py", line 161, in is_scheduler_inactive
    if is_scheduler_disabled(verbose=verbose):
       ^^^^^^^^^^^^^^^^^^^^^^^^^^^^^^^^^^^^^^
  File "/home/pearl/alumnimgmtsystem/apps/frappe/frappe/utils/scheduler.py", line 174, in is_scheduler_disabled
    frappe.db.get_single_value("System Settings", "enable_scheduler")
  File "/home/pearl/alumnimgmtsystem/apps/frappe/frappe/database/database.py", line 884, in get_single_value
    ).run()
      ^^^^^
  File "/home/pearl/alumnimgmtsystem/apps/frappe/frappe/query_builder/utils.py", line 80, in execute_query
    result = frappe.db.sql(query, params, *args, **kwargs)  # nosemgrep
             ^^^^^^^^^^^^^^^^^^^^^^^^^^^^^^^^^^^^^^^^^^^^^
  File "/home/pearl/alumnimgmtsystem/apps/frappe/frappe/database/database.py", line 237, in sql
    self.connect()
  File "/home/pearl/alumnimgmtsystem/apps/frappe/frappe/database/database.py", line 135, in connect
    self.get_connection()
  File "/home/pearl/alumnimgmtsystem/apps/frappe/frappe/database/mariadb/database.py", line 105, in get_connection
    conn = self._get_connection()
           ^^^^^^^^^^^^^^^^^^^^^^
  File "/home/pearl/alumnimgmtsystem/apps/frappe/frappe/database/mariadb/database.py", line 111, in _get_connection
    return self.create_connection()
           ^^^^^^^^^^^^^^^^^^^^^^^^
  File "/home/pearl/alumnimgmtsystem/apps/frappe/frappe/database/mariadb/database.py", line 114, in create_connection
    return pymysql.connect(**self.get_connection_settings())
           ^^^^^^^^^^^^^^^^^^^^^^^^^^^^^^^^^^^^^^^^^^^^^^^^^
  File "/home/pearl/alumnimgmtsystem/env/lib/python3.12/site-packages/pymysql/connections.py", line 361, in __init__
    self.connect()
  File "/home/pearl/alumnimgmtsystem/env/lib/python3.12/site-packages/pymysql/connections.py", line 669, in connect
    self._request_authentication()
  File "/home/pearl/alumnimgmtsystem/env/lib/python3.12/site-packages/pymysql/connections.py", line 957, in _request_authentication
    auth_packet = self._read_packet()
                  ^^^^^^^^^^^^^^^^^^^
  File "/home/pearl/alumnimgmtsystem/env/lib/python3.12/site-packages/pymysql/connections.py", line 775, in _read_packet
    packet.raise_for_error()
  File "/home/pearl/alumnimgmtsystem/env/lib/python3.12/site-packages/pymysql/protocol.py", line 219, in raise_for_error
    err.raise_mysql_exception(self._data)
  File "/home/pearl/alumnimgmtsystem/env/lib/python3.12/site-packages/pymysql/err.py", line 150, in raise_mysql_exception
    raise errorclass(errno, errval)
pymysql.err.OperationalError: (1045, "Access denied for user '_9a54aa6450761df8'@'localhost' (using password: YES)")
2025-04-19 15:38:00,135 ERROR scheduler Exception in Enqueue Events for Site library.localhost
Traceback (most recent call last):
  File "/home/pearl/alumnimgmtsystem/apps/frappe/frappe/utils/scheduler.py", line 117, in enqueue_events_for_site
    if is_scheduler_inactive():
       ^^^^^^^^^^^^^^^^^^^^^^^
  File "/home/pearl/alumnimgmtsystem/apps/frappe/frappe/utils/scheduler.py", line 161, in is_scheduler_inactive
    if is_scheduler_disabled(verbose=verbose):
       ^^^^^^^^^^^^^^^^^^^^^^^^^^^^^^^^^^^^^^
  File "/home/pearl/alumnimgmtsystem/apps/frappe/frappe/utils/scheduler.py", line 174, in is_scheduler_disabled
    frappe.db.get_single_value("System Settings", "enable_scheduler")
  File "/home/pearl/alumnimgmtsystem/apps/frappe/frappe/database/database.py", line 884, in get_single_value
    ).run()
      ^^^^^
  File "/home/pearl/alumnimgmtsystem/apps/frappe/frappe/query_builder/utils.py", line 80, in execute_query
    result = frappe.db.sql(query, params, *args, **kwargs)  # nosemgrep
             ^^^^^^^^^^^^^^^^^^^^^^^^^^^^^^^^^^^^^^^^^^^^^
  File "/home/pearl/alumnimgmtsystem/apps/frappe/frappe/database/database.py", line 237, in sql
    self.connect()
  File "/home/pearl/alumnimgmtsystem/apps/frappe/frappe/database/database.py", line 135, in connect
    self.get_connection()
  File "/home/pearl/alumnimgmtsystem/apps/frappe/frappe/database/mariadb/database.py", line 105, in get_connection
    conn = self._get_connection()
           ^^^^^^^^^^^^^^^^^^^^^^
  File "/home/pearl/alumnimgmtsystem/apps/frappe/frappe/database/mariadb/database.py", line 111, in _get_connection
    return self.create_connection()
           ^^^^^^^^^^^^^^^^^^^^^^^^
  File "/home/pearl/alumnimgmtsystem/apps/frappe/frappe/database/mariadb/database.py", line 114, in create_connection
    return pymysql.connect(**self.get_connection_settings())
           ^^^^^^^^^^^^^^^^^^^^^^^^^^^^^^^^^^^^^^^^^^^^^^^^^
  File "/home/pearl/alumnimgmtsystem/env/lib/python3.12/site-packages/pymysql/connections.py", line 361, in __init__
    self.connect()
  File "/home/pearl/alumnimgmtsystem/env/lib/python3.12/site-packages/pymysql/connections.py", line 669, in connect
    self._request_authentication()
  File "/home/pearl/alumnimgmtsystem/env/lib/python3.12/site-packages/pymysql/connections.py", line 957, in _request_authentication
    auth_packet = self._read_packet()
                  ^^^^^^^^^^^^^^^^^^^
  File "/home/pearl/alumnimgmtsystem/env/lib/python3.12/site-packages/pymysql/connections.py", line 775, in _read_packet
    packet.raise_for_error()
  File "/home/pearl/alumnimgmtsystem/env/lib/python3.12/site-packages/pymysql/protocol.py", line 219, in raise_for_error
    err.raise_mysql_exception(self._data)
  File "/home/pearl/alumnimgmtsystem/env/lib/python3.12/site-packages/pymysql/err.py", line 150, in raise_mysql_exception
    raise errorclass(errno, errval)
pymysql.err.OperationalError: (1045, "Access denied for user '_9a54aa6450761df8'@'localhost' (using password: YES)")
2025-04-19 15:42:00,144 ERROR scheduler Exception in Enqueue Events for Site library.localhost
Traceback (most recent call last):
  File "/home/pearl/alumnimgmtsystem/apps/frappe/frappe/utils/scheduler.py", line 117, in enqueue_events_for_site
    if is_scheduler_inactive():
       ^^^^^^^^^^^^^^^^^^^^^^^
  File "/home/pearl/alumnimgmtsystem/apps/frappe/frappe/utils/scheduler.py", line 161, in is_scheduler_inactive
    if is_scheduler_disabled(verbose=verbose):
       ^^^^^^^^^^^^^^^^^^^^^^^^^^^^^^^^^^^^^^
  File "/home/pearl/alumnimgmtsystem/apps/frappe/frappe/utils/scheduler.py", line 174, in is_scheduler_disabled
    frappe.db.get_single_value("System Settings", "enable_scheduler")
  File "/home/pearl/alumnimgmtsystem/apps/frappe/frappe/database/database.py", line 884, in get_single_value
    ).run()
      ^^^^^
  File "/home/pearl/alumnimgmtsystem/apps/frappe/frappe/query_builder/utils.py", line 80, in execute_query
    result = frappe.db.sql(query, params, *args, **kwargs)  # nosemgrep
             ^^^^^^^^^^^^^^^^^^^^^^^^^^^^^^^^^^^^^^^^^^^^^
  File "/home/pearl/alumnimgmtsystem/apps/frappe/frappe/database/database.py", line 237, in sql
    self.connect()
  File "/home/pearl/alumnimgmtsystem/apps/frappe/frappe/database/database.py", line 135, in connect
    self.get_connection()
  File "/home/pearl/alumnimgmtsystem/apps/frappe/frappe/database/mariadb/database.py", line 105, in get_connection
    conn = self._get_connection()
           ^^^^^^^^^^^^^^^^^^^^^^
  File "/home/pearl/alumnimgmtsystem/apps/frappe/frappe/database/mariadb/database.py", line 111, in _get_connection
    return self.create_connection()
           ^^^^^^^^^^^^^^^^^^^^^^^^
  File "/home/pearl/alumnimgmtsystem/apps/frappe/frappe/database/mariadb/database.py", line 114, in create_connection
    return pymysql.connect(**self.get_connection_settings())
           ^^^^^^^^^^^^^^^^^^^^^^^^^^^^^^^^^^^^^^^^^^^^^^^^^
  File "/home/pearl/alumnimgmtsystem/env/lib/python3.12/site-packages/pymysql/connections.py", line 361, in __init__
    self.connect()
  File "/home/pearl/alumnimgmtsystem/env/lib/python3.12/site-packages/pymysql/connections.py", line 669, in connect
    self._request_authentication()
  File "/home/pearl/alumnimgmtsystem/env/lib/python3.12/site-packages/pymysql/connections.py", line 957, in _request_authentication
    auth_packet = self._read_packet()
                  ^^^^^^^^^^^^^^^^^^^
  File "/home/pearl/alumnimgmtsystem/env/lib/python3.12/site-packages/pymysql/connections.py", line 775, in _read_packet
    packet.raise_for_error()
  File "/home/pearl/alumnimgmtsystem/env/lib/python3.12/site-packages/pymysql/protocol.py", line 219, in raise_for_error
    err.raise_mysql_exception(self._data)
  File "/home/pearl/alumnimgmtsystem/env/lib/python3.12/site-packages/pymysql/err.py", line 150, in raise_mysql_exception
    raise errorclass(errno, errval)
pymysql.err.OperationalError: (1045, "Access denied for user '_9a54aa6450761df8'@'localhost' (using password: YES)")
2025-04-19 15:46:00,243 ERROR scheduler Exception in Enqueue Events for Site library.localhost
Traceback (most recent call last):
  File "/home/pearl/alumnimgmtsystem/apps/frappe/frappe/utils/scheduler.py", line 117, in enqueue_events_for_site
    if is_scheduler_inactive():
       ^^^^^^^^^^^^^^^^^^^^^^^
  File "/home/pearl/alumnimgmtsystem/apps/frappe/frappe/utils/scheduler.py", line 161, in is_scheduler_inactive
    if is_scheduler_disabled(verbose=verbose):
       ^^^^^^^^^^^^^^^^^^^^^^^^^^^^^^^^^^^^^^
  File "/home/pearl/alumnimgmtsystem/apps/frappe/frappe/utils/scheduler.py", line 174, in is_scheduler_disabled
    frappe.db.get_single_value("System Settings", "enable_scheduler")
  File "/home/pearl/alumnimgmtsystem/apps/frappe/frappe/database/database.py", line 884, in get_single_value
    ).run()
      ^^^^^
  File "/home/pearl/alumnimgmtsystem/apps/frappe/frappe/query_builder/utils.py", line 80, in execute_query
    result = frappe.db.sql(query, params, *args, **kwargs)  # nosemgrep
             ^^^^^^^^^^^^^^^^^^^^^^^^^^^^^^^^^^^^^^^^^^^^^
  File "/home/pearl/alumnimgmtsystem/apps/frappe/frappe/database/database.py", line 237, in sql
    self.connect()
  File "/home/pearl/alumnimgmtsystem/apps/frappe/frappe/database/database.py", line 135, in connect
    self.get_connection()
  File "/home/pearl/alumnimgmtsystem/apps/frappe/frappe/database/mariadb/database.py", line 105, in get_connection
    conn = self._get_connection()
           ^^^^^^^^^^^^^^^^^^^^^^
  File "/home/pearl/alumnimgmtsystem/apps/frappe/frappe/database/mariadb/database.py", line 111, in _get_connection
    return self.create_connection()
           ^^^^^^^^^^^^^^^^^^^^^^^^
  File "/home/pearl/alumnimgmtsystem/apps/frappe/frappe/database/mariadb/database.py", line 114, in create_connection
    return pymysql.connect(**self.get_connection_settings())
           ^^^^^^^^^^^^^^^^^^^^^^^^^^^^^^^^^^^^^^^^^^^^^^^^^
  File "/home/pearl/alumnimgmtsystem/env/lib/python3.12/site-packages/pymysql/connections.py", line 361, in __init__
    self.connect()
  File "/home/pearl/alumnimgmtsystem/env/lib/python3.12/site-packages/pymysql/connections.py", line 669, in connect
    self._request_authentication()
  File "/home/pearl/alumnimgmtsystem/env/lib/python3.12/site-packages/pymysql/connections.py", line 957, in _request_authentication
    auth_packet = self._read_packet()
                  ^^^^^^^^^^^^^^^^^^^
  File "/home/pearl/alumnimgmtsystem/env/lib/python3.12/site-packages/pymysql/connections.py", line 775, in _read_packet
    packet.raise_for_error()
  File "/home/pearl/alumnimgmtsystem/env/lib/python3.12/site-packages/pymysql/protocol.py", line 219, in raise_for_error
    err.raise_mysql_exception(self._data)
  File "/home/pearl/alumnimgmtsystem/env/lib/python3.12/site-packages/pymysql/err.py", line 150, in raise_mysql_exception
    raise errorclass(errno, errval)
pymysql.err.OperationalError: (1045, "Access denied for user '_9a54aa6450761df8'@'localhost' (using password: YES)")
2025-04-19 15:50:00,303 ERROR scheduler Exception in Enqueue Events for Site library.localhost
Traceback (most recent call last):
  File "/home/pearl/alumnimgmtsystem/apps/frappe/frappe/utils/scheduler.py", line 117, in enqueue_events_for_site
    if is_scheduler_inactive():
       ^^^^^^^^^^^^^^^^^^^^^^^
  File "/home/pearl/alumnimgmtsystem/apps/frappe/frappe/utils/scheduler.py", line 161, in is_scheduler_inactive
    if is_scheduler_disabled(verbose=verbose):
       ^^^^^^^^^^^^^^^^^^^^^^^^^^^^^^^^^^^^^^
  File "/home/pearl/alumnimgmtsystem/apps/frappe/frappe/utils/scheduler.py", line 174, in is_scheduler_disabled
    frappe.db.get_single_value("System Settings", "enable_scheduler")
  File "/home/pearl/alumnimgmtsystem/apps/frappe/frappe/database/database.py", line 884, in get_single_value
    ).run()
      ^^^^^
  File "/home/pearl/alumnimgmtsystem/apps/frappe/frappe/query_builder/utils.py", line 80, in execute_query
    result = frappe.db.sql(query, params, *args, **kwargs)  # nosemgrep
             ^^^^^^^^^^^^^^^^^^^^^^^^^^^^^^^^^^^^^^^^^^^^^
  File "/home/pearl/alumnimgmtsystem/apps/frappe/frappe/database/database.py", line 237, in sql
    self.connect()
  File "/home/pearl/alumnimgmtsystem/apps/frappe/frappe/database/database.py", line 135, in connect
    self.get_connection()
  File "/home/pearl/alumnimgmtsystem/apps/frappe/frappe/database/mariadb/database.py", line 105, in get_connection
    conn = self._get_connection()
           ^^^^^^^^^^^^^^^^^^^^^^
  File "/home/pearl/alumnimgmtsystem/apps/frappe/frappe/database/mariadb/database.py", line 111, in _get_connection
    return self.create_connection()
           ^^^^^^^^^^^^^^^^^^^^^^^^
  File "/home/pearl/alumnimgmtsystem/apps/frappe/frappe/database/mariadb/database.py", line 114, in create_connection
    return pymysql.connect(**self.get_connection_settings())
           ^^^^^^^^^^^^^^^^^^^^^^^^^^^^^^^^^^^^^^^^^^^^^^^^^
  File "/home/pearl/alumnimgmtsystem/env/lib/python3.12/site-packages/pymysql/connections.py", line 361, in __init__
    self.connect()
  File "/home/pearl/alumnimgmtsystem/env/lib/python3.12/site-packages/pymysql/connections.py", line 669, in connect
    self._request_authentication()
  File "/home/pearl/alumnimgmtsystem/env/lib/python3.12/site-packages/pymysql/connections.py", line 957, in _request_authentication
    auth_packet = self._read_packet()
                  ^^^^^^^^^^^^^^^^^^^
  File "/home/pearl/alumnimgmtsystem/env/lib/python3.12/site-packages/pymysql/connections.py", line 775, in _read_packet
    packet.raise_for_error()
  File "/home/pearl/alumnimgmtsystem/env/lib/python3.12/site-packages/pymysql/protocol.py", line 219, in raise_for_error
    err.raise_mysql_exception(self._data)
  File "/home/pearl/alumnimgmtsystem/env/lib/python3.12/site-packages/pymysql/err.py", line 150, in raise_mysql_exception
    raise errorclass(errno, errval)
pymysql.err.OperationalError: (1045, "Access denied for user '_9a54aa6450761df8'@'localhost' (using password: YES)")
2025-04-19 15:54:01,040 ERROR scheduler Exception in Enqueue Events for Site library.localhost
Traceback (most recent call last):
  File "/home/pearl/alumnimgmtsystem/apps/frappe/frappe/utils/scheduler.py", line 117, in enqueue_events_for_site
    if is_scheduler_inactive():
       ^^^^^^^^^^^^^^^^^^^^^^^
  File "/home/pearl/alumnimgmtsystem/apps/frappe/frappe/utils/scheduler.py", line 161, in is_scheduler_inactive
    if is_scheduler_disabled(verbose=verbose):
       ^^^^^^^^^^^^^^^^^^^^^^^^^^^^^^^^^^^^^^
  File "/home/pearl/alumnimgmtsystem/apps/frappe/frappe/utils/scheduler.py", line 174, in is_scheduler_disabled
    frappe.db.get_single_value("System Settings", "enable_scheduler")
  File "/home/pearl/alumnimgmtsystem/apps/frappe/frappe/database/database.py", line 884, in get_single_value
    ).run()
      ^^^^^
  File "/home/pearl/alumnimgmtsystem/apps/frappe/frappe/query_builder/utils.py", line 80, in execute_query
    result = frappe.db.sql(query, params, *args, **kwargs)  # nosemgrep
             ^^^^^^^^^^^^^^^^^^^^^^^^^^^^^^^^^^^^^^^^^^^^^
  File "/home/pearl/alumnimgmtsystem/apps/frappe/frappe/database/database.py", line 237, in sql
    self.connect()
  File "/home/pearl/alumnimgmtsystem/apps/frappe/frappe/database/database.py", line 135, in connect
    self.get_connection()
  File "/home/pearl/alumnimgmtsystem/apps/frappe/frappe/database/mariadb/database.py", line 105, in get_connection
    conn = self._get_connection()
           ^^^^^^^^^^^^^^^^^^^^^^
  File "/home/pearl/alumnimgmtsystem/apps/frappe/frappe/database/mariadb/database.py", line 111, in _get_connection
    return self.create_connection()
           ^^^^^^^^^^^^^^^^^^^^^^^^
  File "/home/pearl/alumnimgmtsystem/apps/frappe/frappe/database/mariadb/database.py", line 114, in create_connection
    return pymysql.connect(**self.get_connection_settings())
           ^^^^^^^^^^^^^^^^^^^^^^^^^^^^^^^^^^^^^^^^^^^^^^^^^
  File "/home/pearl/alumnimgmtsystem/env/lib/python3.12/site-packages/pymysql/connections.py", line 361, in __init__
    self.connect()
  File "/home/pearl/alumnimgmtsystem/env/lib/python3.12/site-packages/pymysql/connections.py", line 669, in connect
    self._request_authentication()
  File "/home/pearl/alumnimgmtsystem/env/lib/python3.12/site-packages/pymysql/connections.py", line 957, in _request_authentication
    auth_packet = self._read_packet()
                  ^^^^^^^^^^^^^^^^^^^
  File "/home/pearl/alumnimgmtsystem/env/lib/python3.12/site-packages/pymysql/connections.py", line 775, in _read_packet
    packet.raise_for_error()
  File "/home/pearl/alumnimgmtsystem/env/lib/python3.12/site-packages/pymysql/protocol.py", line 219, in raise_for_error
    err.raise_mysql_exception(self._data)
  File "/home/pearl/alumnimgmtsystem/env/lib/python3.12/site-packages/pymysql/err.py", line 150, in raise_mysql_exception
    raise errorclass(errno, errval)
pymysql.err.OperationalError: (1045, "Access denied for user '_9a54aa6450761df8'@'localhost' (using password: YES)")
2025-04-19 15:58:00,149 ERROR scheduler Exception in Enqueue Events for Site library.localhost
Traceback (most recent call last):
  File "/home/pearl/alumnimgmtsystem/apps/frappe/frappe/utils/scheduler.py", line 117, in enqueue_events_for_site
    if is_scheduler_inactive():
       ^^^^^^^^^^^^^^^^^^^^^^^
  File "/home/pearl/alumnimgmtsystem/apps/frappe/frappe/utils/scheduler.py", line 161, in is_scheduler_inactive
    if is_scheduler_disabled(verbose=verbose):
       ^^^^^^^^^^^^^^^^^^^^^^^^^^^^^^^^^^^^^^
  File "/home/pearl/alumnimgmtsystem/apps/frappe/frappe/utils/scheduler.py", line 174, in is_scheduler_disabled
    frappe.db.get_single_value("System Settings", "enable_scheduler")
  File "/home/pearl/alumnimgmtsystem/apps/frappe/frappe/database/database.py", line 884, in get_single_value
    ).run()
      ^^^^^
  File "/home/pearl/alumnimgmtsystem/apps/frappe/frappe/query_builder/utils.py", line 80, in execute_query
    result = frappe.db.sql(query, params, *args, **kwargs)  # nosemgrep
             ^^^^^^^^^^^^^^^^^^^^^^^^^^^^^^^^^^^^^^^^^^^^^
  File "/home/pearl/alumnimgmtsystem/apps/frappe/frappe/database/database.py", line 237, in sql
    self.connect()
  File "/home/pearl/alumnimgmtsystem/apps/frappe/frappe/database/database.py", line 135, in connect
    self.get_connection()
  File "/home/pearl/alumnimgmtsystem/apps/frappe/frappe/database/mariadb/database.py", line 105, in get_connection
    conn = self._get_connection()
           ^^^^^^^^^^^^^^^^^^^^^^
  File "/home/pearl/alumnimgmtsystem/apps/frappe/frappe/database/mariadb/database.py", line 111, in _get_connection
    return self.create_connection()
           ^^^^^^^^^^^^^^^^^^^^^^^^
  File "/home/pearl/alumnimgmtsystem/apps/frappe/frappe/database/mariadb/database.py", line 114, in create_connection
    return pymysql.connect(**self.get_connection_settings())
           ^^^^^^^^^^^^^^^^^^^^^^^^^^^^^^^^^^^^^^^^^^^^^^^^^
  File "/home/pearl/alumnimgmtsystem/env/lib/python3.12/site-packages/pymysql/connections.py", line 361, in __init__
    self.connect()
  File "/home/pearl/alumnimgmtsystem/env/lib/python3.12/site-packages/pymysql/connections.py", line 669, in connect
    self._request_authentication()
  File "/home/pearl/alumnimgmtsystem/env/lib/python3.12/site-packages/pymysql/connections.py", line 957, in _request_authentication
    auth_packet = self._read_packet()
                  ^^^^^^^^^^^^^^^^^^^
  File "/home/pearl/alumnimgmtsystem/env/lib/python3.12/site-packages/pymysql/connections.py", line 775, in _read_packet
    packet.raise_for_error()
  File "/home/pearl/alumnimgmtsystem/env/lib/python3.12/site-packages/pymysql/protocol.py", line 219, in raise_for_error
    err.raise_mysql_exception(self._data)
  File "/home/pearl/alumnimgmtsystem/env/lib/python3.12/site-packages/pymysql/err.py", line 150, in raise_mysql_exception
    raise errorclass(errno, errval)
pymysql.err.OperationalError: (1045, "Access denied for user '_9a54aa6450761df8'@'localhost' (using password: YES)")
2025-04-19 16:02:00,398 ERROR scheduler Exception in Enqueue Events for Site library.localhost
Traceback (most recent call last):
  File "/home/pearl/alumnimgmtsystem/apps/frappe/frappe/utils/scheduler.py", line 117, in enqueue_events_for_site
    if is_scheduler_inactive():
       ^^^^^^^^^^^^^^^^^^^^^^^
  File "/home/pearl/alumnimgmtsystem/apps/frappe/frappe/utils/scheduler.py", line 161, in is_scheduler_inactive
    if is_scheduler_disabled(verbose=verbose):
       ^^^^^^^^^^^^^^^^^^^^^^^^^^^^^^^^^^^^^^
  File "/home/pearl/alumnimgmtsystem/apps/frappe/frappe/utils/scheduler.py", line 174, in is_scheduler_disabled
    frappe.db.get_single_value("System Settings", "enable_scheduler")
  File "/home/pearl/alumnimgmtsystem/apps/frappe/frappe/database/database.py", line 884, in get_single_value
    ).run()
      ^^^^^
  File "/home/pearl/alumnimgmtsystem/apps/frappe/frappe/query_builder/utils.py", line 80, in execute_query
    result = frappe.db.sql(query, params, *args, **kwargs)  # nosemgrep
             ^^^^^^^^^^^^^^^^^^^^^^^^^^^^^^^^^^^^^^^^^^^^^
  File "/home/pearl/alumnimgmtsystem/apps/frappe/frappe/database/database.py", line 237, in sql
    self.connect()
  File "/home/pearl/alumnimgmtsystem/apps/frappe/frappe/database/database.py", line 135, in connect
    self.get_connection()
  File "/home/pearl/alumnimgmtsystem/apps/frappe/frappe/database/mariadb/database.py", line 105, in get_connection
    conn = self._get_connection()
           ^^^^^^^^^^^^^^^^^^^^^^
  File "/home/pearl/alumnimgmtsystem/apps/frappe/frappe/database/mariadb/database.py", line 111, in _get_connection
    return self.create_connection()
           ^^^^^^^^^^^^^^^^^^^^^^^^
  File "/home/pearl/alumnimgmtsystem/apps/frappe/frappe/database/mariadb/database.py", line 114, in create_connection
    return pymysql.connect(**self.get_connection_settings())
           ^^^^^^^^^^^^^^^^^^^^^^^^^^^^^^^^^^^^^^^^^^^^^^^^^
  File "/home/pearl/alumnimgmtsystem/env/lib/python3.12/site-packages/pymysql/connections.py", line 361, in __init__
    self.connect()
  File "/home/pearl/alumnimgmtsystem/env/lib/python3.12/site-packages/pymysql/connections.py", line 669, in connect
    self._request_authentication()
  File "/home/pearl/alumnimgmtsystem/env/lib/python3.12/site-packages/pymysql/connections.py", line 957, in _request_authentication
    auth_packet = self._read_packet()
                  ^^^^^^^^^^^^^^^^^^^
  File "/home/pearl/alumnimgmtsystem/env/lib/python3.12/site-packages/pymysql/connections.py", line 775, in _read_packet
    packet.raise_for_error()
  File "/home/pearl/alumnimgmtsystem/env/lib/python3.12/site-packages/pymysql/protocol.py", line 219, in raise_for_error
    err.raise_mysql_exception(self._data)
  File "/home/pearl/alumnimgmtsystem/env/lib/python3.12/site-packages/pymysql/err.py", line 150, in raise_mysql_exception
    raise errorclass(errno, errval)
pymysql.err.OperationalError: (1045, "Access denied for user '_9a54aa6450761df8'@'localhost' (using password: YES)")
2025-04-19 16:06:00,487 ERROR scheduler Exception in Enqueue Events for Site library.localhost
Traceback (most recent call last):
  File "/home/pearl/alumnimgmtsystem/apps/frappe/frappe/utils/scheduler.py", line 117, in enqueue_events_for_site
    if is_scheduler_inactive():
       ^^^^^^^^^^^^^^^^^^^^^^^
  File "/home/pearl/alumnimgmtsystem/apps/frappe/frappe/utils/scheduler.py", line 161, in is_scheduler_inactive
    if is_scheduler_disabled(verbose=verbose):
       ^^^^^^^^^^^^^^^^^^^^^^^^^^^^^^^^^^^^^^
  File "/home/pearl/alumnimgmtsystem/apps/frappe/frappe/utils/scheduler.py", line 174, in is_scheduler_disabled
    frappe.db.get_single_value("System Settings", "enable_scheduler")
  File "/home/pearl/alumnimgmtsystem/apps/frappe/frappe/database/database.py", line 884, in get_single_value
    ).run()
      ^^^^^
  File "/home/pearl/alumnimgmtsystem/apps/frappe/frappe/query_builder/utils.py", line 80, in execute_query
    result = frappe.db.sql(query, params, *args, **kwargs)  # nosemgrep
             ^^^^^^^^^^^^^^^^^^^^^^^^^^^^^^^^^^^^^^^^^^^^^
  File "/home/pearl/alumnimgmtsystem/apps/frappe/frappe/database/database.py", line 237, in sql
    self.connect()
  File "/home/pearl/alumnimgmtsystem/apps/frappe/frappe/database/database.py", line 135, in connect
    self.get_connection()
  File "/home/pearl/alumnimgmtsystem/apps/frappe/frappe/database/mariadb/database.py", line 105, in get_connection
    conn = self._get_connection()
           ^^^^^^^^^^^^^^^^^^^^^^
  File "/home/pearl/alumnimgmtsystem/apps/frappe/frappe/database/mariadb/database.py", line 111, in _get_connection
    return self.create_connection()
           ^^^^^^^^^^^^^^^^^^^^^^^^
  File "/home/pearl/alumnimgmtsystem/apps/frappe/frappe/database/mariadb/database.py", line 114, in create_connection
    return pymysql.connect(**self.get_connection_settings())
           ^^^^^^^^^^^^^^^^^^^^^^^^^^^^^^^^^^^^^^^^^^^^^^^^^
  File "/home/pearl/alumnimgmtsystem/env/lib/python3.12/site-packages/pymysql/connections.py", line 361, in __init__
    self.connect()
  File "/home/pearl/alumnimgmtsystem/env/lib/python3.12/site-packages/pymysql/connections.py", line 669, in connect
    self._request_authentication()
  File "/home/pearl/alumnimgmtsystem/env/lib/python3.12/site-packages/pymysql/connections.py", line 957, in _request_authentication
    auth_packet = self._read_packet()
                  ^^^^^^^^^^^^^^^^^^^
  File "/home/pearl/alumnimgmtsystem/env/lib/python3.12/site-packages/pymysql/connections.py", line 775, in _read_packet
    packet.raise_for_error()
  File "/home/pearl/alumnimgmtsystem/env/lib/python3.12/site-packages/pymysql/protocol.py", line 219, in raise_for_error
    err.raise_mysql_exception(self._data)
  File "/home/pearl/alumnimgmtsystem/env/lib/python3.12/site-packages/pymysql/err.py", line 150, in raise_mysql_exception
    raise errorclass(errno, errval)
pymysql.err.OperationalError: (1045, "Access denied for user '_9a54aa6450761df8'@'localhost' (using password: YES)")
2025-04-19 16:10:00,638 ERROR scheduler Exception in Enqueue Events for Site library.localhost
Traceback (most recent call last):
  File "/home/pearl/alumnimgmtsystem/apps/frappe/frappe/utils/scheduler.py", line 117, in enqueue_events_for_site
    if is_scheduler_inactive():
       ^^^^^^^^^^^^^^^^^^^^^^^
  File "/home/pearl/alumnimgmtsystem/apps/frappe/frappe/utils/scheduler.py", line 161, in is_scheduler_inactive
    if is_scheduler_disabled(verbose=verbose):
       ^^^^^^^^^^^^^^^^^^^^^^^^^^^^^^^^^^^^^^
  File "/home/pearl/alumnimgmtsystem/apps/frappe/frappe/utils/scheduler.py", line 174, in is_scheduler_disabled
    frappe.db.get_single_value("System Settings", "enable_scheduler")
  File "/home/pearl/alumnimgmtsystem/apps/frappe/frappe/database/database.py", line 884, in get_single_value
    ).run()
      ^^^^^
  File "/home/pearl/alumnimgmtsystem/apps/frappe/frappe/query_builder/utils.py", line 80, in execute_query
    result = frappe.db.sql(query, params, *args, **kwargs)  # nosemgrep
             ^^^^^^^^^^^^^^^^^^^^^^^^^^^^^^^^^^^^^^^^^^^^^
  File "/home/pearl/alumnimgmtsystem/apps/frappe/frappe/database/database.py", line 237, in sql
    self.connect()
  File "/home/pearl/alumnimgmtsystem/apps/frappe/frappe/database/database.py", line 135, in connect
    self.get_connection()
  File "/home/pearl/alumnimgmtsystem/apps/frappe/frappe/database/mariadb/database.py", line 105, in get_connection
    conn = self._get_connection()
           ^^^^^^^^^^^^^^^^^^^^^^
  File "/home/pearl/alumnimgmtsystem/apps/frappe/frappe/database/mariadb/database.py", line 111, in _get_connection
    return self.create_connection()
           ^^^^^^^^^^^^^^^^^^^^^^^^
  File "/home/pearl/alumnimgmtsystem/apps/frappe/frappe/database/mariadb/database.py", line 114, in create_connection
    return pymysql.connect(**self.get_connection_settings())
           ^^^^^^^^^^^^^^^^^^^^^^^^^^^^^^^^^^^^^^^^^^^^^^^^^
  File "/home/pearl/alumnimgmtsystem/env/lib/python3.12/site-packages/pymysql/connections.py", line 361, in __init__
    self.connect()
  File "/home/pearl/alumnimgmtsystem/env/lib/python3.12/site-packages/pymysql/connections.py", line 669, in connect
    self._request_authentication()
  File "/home/pearl/alumnimgmtsystem/env/lib/python3.12/site-packages/pymysql/connections.py", line 957, in _request_authentication
    auth_packet = self._read_packet()
                  ^^^^^^^^^^^^^^^^^^^
  File "/home/pearl/alumnimgmtsystem/env/lib/python3.12/site-packages/pymysql/connections.py", line 775, in _read_packet
    packet.raise_for_error()
  File "/home/pearl/alumnimgmtsystem/env/lib/python3.12/site-packages/pymysql/protocol.py", line 219, in raise_for_error
    err.raise_mysql_exception(self._data)
  File "/home/pearl/alumnimgmtsystem/env/lib/python3.12/site-packages/pymysql/err.py", line 150, in raise_mysql_exception
    raise errorclass(errno, errval)
pymysql.err.OperationalError: (1045, "Access denied for user '_9a54aa6450761df8'@'localhost' (using password: YES)")
2025-04-19 16:14:00,723 ERROR scheduler Exception in Enqueue Events for Site library.localhost
Traceback (most recent call last):
  File "/home/pearl/alumnimgmtsystem/apps/frappe/frappe/utils/scheduler.py", line 117, in enqueue_events_for_site
    if is_scheduler_inactive():
       ^^^^^^^^^^^^^^^^^^^^^^^
  File "/home/pearl/alumnimgmtsystem/apps/frappe/frappe/utils/scheduler.py", line 161, in is_scheduler_inactive
    if is_scheduler_disabled(verbose=verbose):
       ^^^^^^^^^^^^^^^^^^^^^^^^^^^^^^^^^^^^^^
  File "/home/pearl/alumnimgmtsystem/apps/frappe/frappe/utils/scheduler.py", line 174, in is_scheduler_disabled
    frappe.db.get_single_value("System Settings", "enable_scheduler")
  File "/home/pearl/alumnimgmtsystem/apps/frappe/frappe/database/database.py", line 884, in get_single_value
    ).run()
      ^^^^^
  File "/home/pearl/alumnimgmtsystem/apps/frappe/frappe/query_builder/utils.py", line 80, in execute_query
    result = frappe.db.sql(query, params, *args, **kwargs)  # nosemgrep
             ^^^^^^^^^^^^^^^^^^^^^^^^^^^^^^^^^^^^^^^^^^^^^
  File "/home/pearl/alumnimgmtsystem/apps/frappe/frappe/database/database.py", line 237, in sql
    self.connect()
  File "/home/pearl/alumnimgmtsystem/apps/frappe/frappe/database/database.py", line 135, in connect
    self.get_connection()
  File "/home/pearl/alumnimgmtsystem/apps/frappe/frappe/database/mariadb/database.py", line 105, in get_connection
    conn = self._get_connection()
           ^^^^^^^^^^^^^^^^^^^^^^
  File "/home/pearl/alumnimgmtsystem/apps/frappe/frappe/database/mariadb/database.py", line 111, in _get_connection
    return self.create_connection()
           ^^^^^^^^^^^^^^^^^^^^^^^^
  File "/home/pearl/alumnimgmtsystem/apps/frappe/frappe/database/mariadb/database.py", line 114, in create_connection
    return pymysql.connect(**self.get_connection_settings())
           ^^^^^^^^^^^^^^^^^^^^^^^^^^^^^^^^^^^^^^^^^^^^^^^^^
  File "/home/pearl/alumnimgmtsystem/env/lib/python3.12/site-packages/pymysql/connections.py", line 361, in __init__
    self.connect()
  File "/home/pearl/alumnimgmtsystem/env/lib/python3.12/site-packages/pymysql/connections.py", line 669, in connect
    self._request_authentication()
  File "/home/pearl/alumnimgmtsystem/env/lib/python3.12/site-packages/pymysql/connections.py", line 957, in _request_authentication
    auth_packet = self._read_packet()
                  ^^^^^^^^^^^^^^^^^^^
  File "/home/pearl/alumnimgmtsystem/env/lib/python3.12/site-packages/pymysql/connections.py", line 775, in _read_packet
    packet.raise_for_error()
  File "/home/pearl/alumnimgmtsystem/env/lib/python3.12/site-packages/pymysql/protocol.py", line 219, in raise_for_error
    err.raise_mysql_exception(self._data)
  File "/home/pearl/alumnimgmtsystem/env/lib/python3.12/site-packages/pymysql/err.py", line 150, in raise_mysql_exception
    raise errorclass(errno, errval)
pymysql.err.OperationalError: (1045, "Access denied for user '_9a54aa6450761df8'@'localhost' (using password: YES)")
2025-04-19 16:18:00,849 ERROR scheduler Exception in Enqueue Events for Site library.localhost
Traceback (most recent call last):
  File "/home/pearl/alumnimgmtsystem/apps/frappe/frappe/utils/scheduler.py", line 117, in enqueue_events_for_site
    if is_scheduler_inactive():
       ^^^^^^^^^^^^^^^^^^^^^^^
  File "/home/pearl/alumnimgmtsystem/apps/frappe/frappe/utils/scheduler.py", line 161, in is_scheduler_inactive
    if is_scheduler_disabled(verbose=verbose):
       ^^^^^^^^^^^^^^^^^^^^^^^^^^^^^^^^^^^^^^
  File "/home/pearl/alumnimgmtsystem/apps/frappe/frappe/utils/scheduler.py", line 174, in is_scheduler_disabled
    frappe.db.get_single_value("System Settings", "enable_scheduler")
  File "/home/pearl/alumnimgmtsystem/apps/frappe/frappe/database/database.py", line 884, in get_single_value
    ).run()
      ^^^^^
  File "/home/pearl/alumnimgmtsystem/apps/frappe/frappe/query_builder/utils.py", line 80, in execute_query
    result = frappe.db.sql(query, params, *args, **kwargs)  # nosemgrep
             ^^^^^^^^^^^^^^^^^^^^^^^^^^^^^^^^^^^^^^^^^^^^^
  File "/home/pearl/alumnimgmtsystem/apps/frappe/frappe/database/database.py", line 237, in sql
    self.connect()
  File "/home/pearl/alumnimgmtsystem/apps/frappe/frappe/database/database.py", line 135, in connect
    self.get_connection()
  File "/home/pearl/alumnimgmtsystem/apps/frappe/frappe/database/mariadb/database.py", line 105, in get_connection
    conn = self._get_connection()
           ^^^^^^^^^^^^^^^^^^^^^^
  File "/home/pearl/alumnimgmtsystem/apps/frappe/frappe/database/mariadb/database.py", line 111, in _get_connection
    return self.create_connection()
           ^^^^^^^^^^^^^^^^^^^^^^^^
  File "/home/pearl/alumnimgmtsystem/apps/frappe/frappe/database/mariadb/database.py", line 114, in create_connection
    return pymysql.connect(**self.get_connection_settings())
           ^^^^^^^^^^^^^^^^^^^^^^^^^^^^^^^^^^^^^^^^^^^^^^^^^
  File "/home/pearl/alumnimgmtsystem/env/lib/python3.12/site-packages/pymysql/connections.py", line 361, in __init__
    self.connect()
  File "/home/pearl/alumnimgmtsystem/env/lib/python3.12/site-packages/pymysql/connections.py", line 669, in connect
    self._request_authentication()
  File "/home/pearl/alumnimgmtsystem/env/lib/python3.12/site-packages/pymysql/connections.py", line 957, in _request_authentication
    auth_packet = self._read_packet()
                  ^^^^^^^^^^^^^^^^^^^
  File "/home/pearl/alumnimgmtsystem/env/lib/python3.12/site-packages/pymysql/connections.py", line 775, in _read_packet
    packet.raise_for_error()
  File "/home/pearl/alumnimgmtsystem/env/lib/python3.12/site-packages/pymysql/protocol.py", line 219, in raise_for_error
    err.raise_mysql_exception(self._data)
  File "/home/pearl/alumnimgmtsystem/env/lib/python3.12/site-packages/pymysql/err.py", line 150, in raise_mysql_exception
    raise errorclass(errno, errval)
pymysql.err.OperationalError: (1045, "Access denied for user '_9a54aa6450761df8'@'localhost' (using password: YES)")
2025-04-19 16:22:00,861 ERROR scheduler Exception in Enqueue Events for Site library.localhost
Traceback (most recent call last):
  File "/home/pearl/alumnimgmtsystem/apps/frappe/frappe/utils/scheduler.py", line 117, in enqueue_events_for_site
    if is_scheduler_inactive():
       ^^^^^^^^^^^^^^^^^^^^^^^
  File "/home/pearl/alumnimgmtsystem/apps/frappe/frappe/utils/scheduler.py", line 161, in is_scheduler_inactive
    if is_scheduler_disabled(verbose=verbose):
       ^^^^^^^^^^^^^^^^^^^^^^^^^^^^^^^^^^^^^^
  File "/home/pearl/alumnimgmtsystem/apps/frappe/frappe/utils/scheduler.py", line 174, in is_scheduler_disabled
    frappe.db.get_single_value("System Settings", "enable_scheduler")
  File "/home/pearl/alumnimgmtsystem/apps/frappe/frappe/database/database.py", line 884, in get_single_value
    ).run()
      ^^^^^
  File "/home/pearl/alumnimgmtsystem/apps/frappe/frappe/query_builder/utils.py", line 80, in execute_query
    result = frappe.db.sql(query, params, *args, **kwargs)  # nosemgrep
             ^^^^^^^^^^^^^^^^^^^^^^^^^^^^^^^^^^^^^^^^^^^^^
  File "/home/pearl/alumnimgmtsystem/apps/frappe/frappe/database/database.py", line 237, in sql
    self.connect()
  File "/home/pearl/alumnimgmtsystem/apps/frappe/frappe/database/database.py", line 135, in connect
    self.get_connection()
  File "/home/pearl/alumnimgmtsystem/apps/frappe/frappe/database/mariadb/database.py", line 105, in get_connection
    conn = self._get_connection()
           ^^^^^^^^^^^^^^^^^^^^^^
  File "/home/pearl/alumnimgmtsystem/apps/frappe/frappe/database/mariadb/database.py", line 111, in _get_connection
    return self.create_connection()
           ^^^^^^^^^^^^^^^^^^^^^^^^
  File "/home/pearl/alumnimgmtsystem/apps/frappe/frappe/database/mariadb/database.py", line 114, in create_connection
    return pymysql.connect(**self.get_connection_settings())
           ^^^^^^^^^^^^^^^^^^^^^^^^^^^^^^^^^^^^^^^^^^^^^^^^^
  File "/home/pearl/alumnimgmtsystem/env/lib/python3.12/site-packages/pymysql/connections.py", line 361, in __init__
    self.connect()
  File "/home/pearl/alumnimgmtsystem/env/lib/python3.12/site-packages/pymysql/connections.py", line 669, in connect
    self._request_authentication()
  File "/home/pearl/alumnimgmtsystem/env/lib/python3.12/site-packages/pymysql/connections.py", line 957, in _request_authentication
    auth_packet = self._read_packet()
                  ^^^^^^^^^^^^^^^^^^^
  File "/home/pearl/alumnimgmtsystem/env/lib/python3.12/site-packages/pymysql/connections.py", line 775, in _read_packet
    packet.raise_for_error()
  File "/home/pearl/alumnimgmtsystem/env/lib/python3.12/site-packages/pymysql/protocol.py", line 219, in raise_for_error
    err.raise_mysql_exception(self._data)
  File "/home/pearl/alumnimgmtsystem/env/lib/python3.12/site-packages/pymysql/err.py", line 150, in raise_mysql_exception
    raise errorclass(errno, errval)
pymysql.err.OperationalError: (1045, "Access denied for user '_9a54aa6450761df8'@'localhost' (using password: YES)")
2025-04-19 16:26:01,126 ERROR scheduler Exception in Enqueue Events for Site library.localhost
Traceback (most recent call last):
  File "/home/pearl/alumnimgmtsystem/apps/frappe/frappe/utils/scheduler.py", line 117, in enqueue_events_for_site
    if is_scheduler_inactive():
       ^^^^^^^^^^^^^^^^^^^^^^^
  File "/home/pearl/alumnimgmtsystem/apps/frappe/frappe/utils/scheduler.py", line 161, in is_scheduler_inactive
    if is_scheduler_disabled(verbose=verbose):
       ^^^^^^^^^^^^^^^^^^^^^^^^^^^^^^^^^^^^^^
  File "/home/pearl/alumnimgmtsystem/apps/frappe/frappe/utils/scheduler.py", line 174, in is_scheduler_disabled
    frappe.db.get_single_value("System Settings", "enable_scheduler")
  File "/home/pearl/alumnimgmtsystem/apps/frappe/frappe/database/database.py", line 884, in get_single_value
    ).run()
      ^^^^^
  File "/home/pearl/alumnimgmtsystem/apps/frappe/frappe/query_builder/utils.py", line 80, in execute_query
    result = frappe.db.sql(query, params, *args, **kwargs)  # nosemgrep
             ^^^^^^^^^^^^^^^^^^^^^^^^^^^^^^^^^^^^^^^^^^^^^
  File "/home/pearl/alumnimgmtsystem/apps/frappe/frappe/database/database.py", line 237, in sql
    self.connect()
  File "/home/pearl/alumnimgmtsystem/apps/frappe/frappe/database/database.py", line 135, in connect
    self.get_connection()
  File "/home/pearl/alumnimgmtsystem/apps/frappe/frappe/database/mariadb/database.py", line 105, in get_connection
    conn = self._get_connection()
           ^^^^^^^^^^^^^^^^^^^^^^
  File "/home/pearl/alumnimgmtsystem/apps/frappe/frappe/database/mariadb/database.py", line 111, in _get_connection
    return self.create_connection()
           ^^^^^^^^^^^^^^^^^^^^^^^^
  File "/home/pearl/alumnimgmtsystem/apps/frappe/frappe/database/mariadb/database.py", line 114, in create_connection
    return pymysql.connect(**self.get_connection_settings())
           ^^^^^^^^^^^^^^^^^^^^^^^^^^^^^^^^^^^^^^^^^^^^^^^^^
  File "/home/pearl/alumnimgmtsystem/env/lib/python3.12/site-packages/pymysql/connections.py", line 361, in __init__
    self.connect()
  File "/home/pearl/alumnimgmtsystem/env/lib/python3.12/site-packages/pymysql/connections.py", line 669, in connect
    self._request_authentication()
  File "/home/pearl/alumnimgmtsystem/env/lib/python3.12/site-packages/pymysql/connections.py", line 957, in _request_authentication
    auth_packet = self._read_packet()
                  ^^^^^^^^^^^^^^^^^^^
  File "/home/pearl/alumnimgmtsystem/env/lib/python3.12/site-packages/pymysql/connections.py", line 775, in _read_packet
    packet.raise_for_error()
  File "/home/pearl/alumnimgmtsystem/env/lib/python3.12/site-packages/pymysql/protocol.py", line 219, in raise_for_error
    err.raise_mysql_exception(self._data)
  File "/home/pearl/alumnimgmtsystem/env/lib/python3.12/site-packages/pymysql/err.py", line 150, in raise_mysql_exception
    raise errorclass(errno, errval)
pymysql.err.OperationalError: (1045, "Access denied for user '_9a54aa6450761df8'@'localhost' (using password: YES)")
2025-04-19 16:30:00,198 ERROR scheduler Exception in Enqueue Events for Site library.localhost
Traceback (most recent call last):
  File "/home/pearl/alumnimgmtsystem/apps/frappe/frappe/utils/scheduler.py", line 117, in enqueue_events_for_site
    if is_scheduler_inactive():
       ^^^^^^^^^^^^^^^^^^^^^^^
  File "/home/pearl/alumnimgmtsystem/apps/frappe/frappe/utils/scheduler.py", line 161, in is_scheduler_inactive
    if is_scheduler_disabled(verbose=verbose):
       ^^^^^^^^^^^^^^^^^^^^^^^^^^^^^^^^^^^^^^
  File "/home/pearl/alumnimgmtsystem/apps/frappe/frappe/utils/scheduler.py", line 174, in is_scheduler_disabled
    frappe.db.get_single_value("System Settings", "enable_scheduler")
  File "/home/pearl/alumnimgmtsystem/apps/frappe/frappe/database/database.py", line 884, in get_single_value
    ).run()
      ^^^^^
  File "/home/pearl/alumnimgmtsystem/apps/frappe/frappe/query_builder/utils.py", line 80, in execute_query
    result = frappe.db.sql(query, params, *args, **kwargs)  # nosemgrep
             ^^^^^^^^^^^^^^^^^^^^^^^^^^^^^^^^^^^^^^^^^^^^^
  File "/home/pearl/alumnimgmtsystem/apps/frappe/frappe/database/database.py", line 237, in sql
    self.connect()
  File "/home/pearl/alumnimgmtsystem/apps/frappe/frappe/database/database.py", line 135, in connect
    self.get_connection()
  File "/home/pearl/alumnimgmtsystem/apps/frappe/frappe/database/mariadb/database.py", line 105, in get_connection
    conn = self._get_connection()
           ^^^^^^^^^^^^^^^^^^^^^^
  File "/home/pearl/alumnimgmtsystem/apps/frappe/frappe/database/mariadb/database.py", line 111, in _get_connection
    return self.create_connection()
           ^^^^^^^^^^^^^^^^^^^^^^^^
  File "/home/pearl/alumnimgmtsystem/apps/frappe/frappe/database/mariadb/database.py", line 114, in create_connection
    return pymysql.connect(**self.get_connection_settings())
           ^^^^^^^^^^^^^^^^^^^^^^^^^^^^^^^^^^^^^^^^^^^^^^^^^
  File "/home/pearl/alumnimgmtsystem/env/lib/python3.12/site-packages/pymysql/connections.py", line 361, in __init__
    self.connect()
  File "/home/pearl/alumnimgmtsystem/env/lib/python3.12/site-packages/pymysql/connections.py", line 669, in connect
    self._request_authentication()
  File "/home/pearl/alumnimgmtsystem/env/lib/python3.12/site-packages/pymysql/connections.py", line 957, in _request_authentication
    auth_packet = self._read_packet()
                  ^^^^^^^^^^^^^^^^^^^
  File "/home/pearl/alumnimgmtsystem/env/lib/python3.12/site-packages/pymysql/connections.py", line 775, in _read_packet
    packet.raise_for_error()
  File "/home/pearl/alumnimgmtsystem/env/lib/python3.12/site-packages/pymysql/protocol.py", line 219, in raise_for_error
    err.raise_mysql_exception(self._data)
  File "/home/pearl/alumnimgmtsystem/env/lib/python3.12/site-packages/pymysql/err.py", line 150, in raise_mysql_exception
    raise errorclass(errno, errval)
pymysql.err.OperationalError: (1045, "Access denied for user '_9a54aa6450761df8'@'localhost' (using password: YES)")
2025-04-19 16:34:00,237 ERROR scheduler Exception in Enqueue Events for Site library.localhost
Traceback (most recent call last):
  File "/home/pearl/alumnimgmtsystem/apps/frappe/frappe/utils/scheduler.py", line 117, in enqueue_events_for_site
    if is_scheduler_inactive():
       ^^^^^^^^^^^^^^^^^^^^^^^
  File "/home/pearl/alumnimgmtsystem/apps/frappe/frappe/utils/scheduler.py", line 161, in is_scheduler_inactive
    if is_scheduler_disabled(verbose=verbose):
       ^^^^^^^^^^^^^^^^^^^^^^^^^^^^^^^^^^^^^^
  File "/home/pearl/alumnimgmtsystem/apps/frappe/frappe/utils/scheduler.py", line 174, in is_scheduler_disabled
    frappe.db.get_single_value("System Settings", "enable_scheduler")
  File "/home/pearl/alumnimgmtsystem/apps/frappe/frappe/database/database.py", line 884, in get_single_value
    ).run()
      ^^^^^
  File "/home/pearl/alumnimgmtsystem/apps/frappe/frappe/query_builder/utils.py", line 80, in execute_query
    result = frappe.db.sql(query, params, *args, **kwargs)  # nosemgrep
             ^^^^^^^^^^^^^^^^^^^^^^^^^^^^^^^^^^^^^^^^^^^^^
  File "/home/pearl/alumnimgmtsystem/apps/frappe/frappe/database/database.py", line 237, in sql
    self.connect()
  File "/home/pearl/alumnimgmtsystem/apps/frappe/frappe/database/database.py", line 135, in connect
    self.get_connection()
  File "/home/pearl/alumnimgmtsystem/apps/frappe/frappe/database/mariadb/database.py", line 105, in get_connection
    conn = self._get_connection()
           ^^^^^^^^^^^^^^^^^^^^^^
  File "/home/pearl/alumnimgmtsystem/apps/frappe/frappe/database/mariadb/database.py", line 111, in _get_connection
    return self.create_connection()
           ^^^^^^^^^^^^^^^^^^^^^^^^
  File "/home/pearl/alumnimgmtsystem/apps/frappe/frappe/database/mariadb/database.py", line 114, in create_connection
    return pymysql.connect(**self.get_connection_settings())
           ^^^^^^^^^^^^^^^^^^^^^^^^^^^^^^^^^^^^^^^^^^^^^^^^^
  File "/home/pearl/alumnimgmtsystem/env/lib/python3.12/site-packages/pymysql/connections.py", line 361, in __init__
    self.connect()
  File "/home/pearl/alumnimgmtsystem/env/lib/python3.12/site-packages/pymysql/connections.py", line 669, in connect
    self._request_authentication()
  File "/home/pearl/alumnimgmtsystem/env/lib/python3.12/site-packages/pymysql/connections.py", line 957, in _request_authentication
    auth_packet = self._read_packet()
                  ^^^^^^^^^^^^^^^^^^^
  File "/home/pearl/alumnimgmtsystem/env/lib/python3.12/site-packages/pymysql/connections.py", line 775, in _read_packet
    packet.raise_for_error()
  File "/home/pearl/alumnimgmtsystem/env/lib/python3.12/site-packages/pymysql/protocol.py", line 219, in raise_for_error
    err.raise_mysql_exception(self._data)
  File "/home/pearl/alumnimgmtsystem/env/lib/python3.12/site-packages/pymysql/err.py", line 150, in raise_mysql_exception
    raise errorclass(errno, errval)
pymysql.err.OperationalError: (1045, "Access denied for user '_9a54aa6450761df8'@'localhost' (using password: YES)")
2025-04-19 16:38:00,400 ERROR scheduler Exception in Enqueue Events for Site library.localhost
Traceback (most recent call last):
  File "/home/pearl/alumnimgmtsystem/apps/frappe/frappe/utils/scheduler.py", line 117, in enqueue_events_for_site
    if is_scheduler_inactive():
       ^^^^^^^^^^^^^^^^^^^^^^^
  File "/home/pearl/alumnimgmtsystem/apps/frappe/frappe/utils/scheduler.py", line 161, in is_scheduler_inactive
    if is_scheduler_disabled(verbose=verbose):
       ^^^^^^^^^^^^^^^^^^^^^^^^^^^^^^^^^^^^^^
  File "/home/pearl/alumnimgmtsystem/apps/frappe/frappe/utils/scheduler.py", line 174, in is_scheduler_disabled
    frappe.db.get_single_value("System Settings", "enable_scheduler")
  File "/home/pearl/alumnimgmtsystem/apps/frappe/frappe/database/database.py", line 884, in get_single_value
    ).run()
      ^^^^^
  File "/home/pearl/alumnimgmtsystem/apps/frappe/frappe/query_builder/utils.py", line 80, in execute_query
    result = frappe.db.sql(query, params, *args, **kwargs)  # nosemgrep
             ^^^^^^^^^^^^^^^^^^^^^^^^^^^^^^^^^^^^^^^^^^^^^
  File "/home/pearl/alumnimgmtsystem/apps/frappe/frappe/database/database.py", line 237, in sql
    self.connect()
  File "/home/pearl/alumnimgmtsystem/apps/frappe/frappe/database/database.py", line 135, in connect
    self.get_connection()
  File "/home/pearl/alumnimgmtsystem/apps/frappe/frappe/database/mariadb/database.py", line 105, in get_connection
    conn = self._get_connection()
           ^^^^^^^^^^^^^^^^^^^^^^
  File "/home/pearl/alumnimgmtsystem/apps/frappe/frappe/database/mariadb/database.py", line 111, in _get_connection
    return self.create_connection()
           ^^^^^^^^^^^^^^^^^^^^^^^^
  File "/home/pearl/alumnimgmtsystem/apps/frappe/frappe/database/mariadb/database.py", line 114, in create_connection
    return pymysql.connect(**self.get_connection_settings())
           ^^^^^^^^^^^^^^^^^^^^^^^^^^^^^^^^^^^^^^^^^^^^^^^^^
  File "/home/pearl/alumnimgmtsystem/env/lib/python3.12/site-packages/pymysql/connections.py", line 361, in __init__
    self.connect()
  File "/home/pearl/alumnimgmtsystem/env/lib/python3.12/site-packages/pymysql/connections.py", line 669, in connect
    self._request_authentication()
  File "/home/pearl/alumnimgmtsystem/env/lib/python3.12/site-packages/pymysql/connections.py", line 957, in _request_authentication
    auth_packet = self._read_packet()
                  ^^^^^^^^^^^^^^^^^^^
  File "/home/pearl/alumnimgmtsystem/env/lib/python3.12/site-packages/pymysql/connections.py", line 775, in _read_packet
    packet.raise_for_error()
  File "/home/pearl/alumnimgmtsystem/env/lib/python3.12/site-packages/pymysql/protocol.py", line 219, in raise_for_error
    err.raise_mysql_exception(self._data)
  File "/home/pearl/alumnimgmtsystem/env/lib/python3.12/site-packages/pymysql/err.py", line 150, in raise_mysql_exception
    raise errorclass(errno, errval)
pymysql.err.OperationalError: (1045, "Access denied for user '_9a54aa6450761df8'@'localhost' (using password: YES)")
2025-04-19 16:42:00,599 ERROR scheduler Exception in Enqueue Events for Site library.localhost
Traceback (most recent call last):
  File "/home/pearl/alumnimgmtsystem/apps/frappe/frappe/utils/scheduler.py", line 117, in enqueue_events_for_site
    if is_scheduler_inactive():
       ^^^^^^^^^^^^^^^^^^^^^^^
  File "/home/pearl/alumnimgmtsystem/apps/frappe/frappe/utils/scheduler.py", line 161, in is_scheduler_inactive
    if is_scheduler_disabled(verbose=verbose):
       ^^^^^^^^^^^^^^^^^^^^^^^^^^^^^^^^^^^^^^
  File "/home/pearl/alumnimgmtsystem/apps/frappe/frappe/utils/scheduler.py", line 174, in is_scheduler_disabled
    frappe.db.get_single_value("System Settings", "enable_scheduler")
  File "/home/pearl/alumnimgmtsystem/apps/frappe/frappe/database/database.py", line 884, in get_single_value
    ).run()
      ^^^^^
  File "/home/pearl/alumnimgmtsystem/apps/frappe/frappe/query_builder/utils.py", line 80, in execute_query
    result = frappe.db.sql(query, params, *args, **kwargs)  # nosemgrep
             ^^^^^^^^^^^^^^^^^^^^^^^^^^^^^^^^^^^^^^^^^^^^^
  File "/home/pearl/alumnimgmtsystem/apps/frappe/frappe/database/database.py", line 237, in sql
    self.connect()
  File "/home/pearl/alumnimgmtsystem/apps/frappe/frappe/database/database.py", line 135, in connect
    self.get_connection()
  File "/home/pearl/alumnimgmtsystem/apps/frappe/frappe/database/mariadb/database.py", line 105, in get_connection
    conn = self._get_connection()
           ^^^^^^^^^^^^^^^^^^^^^^
  File "/home/pearl/alumnimgmtsystem/apps/frappe/frappe/database/mariadb/database.py", line 111, in _get_connection
    return self.create_connection()
           ^^^^^^^^^^^^^^^^^^^^^^^^
  File "/home/pearl/alumnimgmtsystem/apps/frappe/frappe/database/mariadb/database.py", line 114, in create_connection
    return pymysql.connect(**self.get_connection_settings())
           ^^^^^^^^^^^^^^^^^^^^^^^^^^^^^^^^^^^^^^^^^^^^^^^^^
  File "/home/pearl/alumnimgmtsystem/env/lib/python3.12/site-packages/pymysql/connections.py", line 361, in __init__
    self.connect()
  File "/home/pearl/alumnimgmtsystem/env/lib/python3.12/site-packages/pymysql/connections.py", line 669, in connect
    self._request_authentication()
  File "/home/pearl/alumnimgmtsystem/env/lib/python3.12/site-packages/pymysql/connections.py", line 957, in _request_authentication
    auth_packet = self._read_packet()
                  ^^^^^^^^^^^^^^^^^^^
  File "/home/pearl/alumnimgmtsystem/env/lib/python3.12/site-packages/pymysql/connections.py", line 775, in _read_packet
    packet.raise_for_error()
  File "/home/pearl/alumnimgmtsystem/env/lib/python3.12/site-packages/pymysql/protocol.py", line 219, in raise_for_error
    err.raise_mysql_exception(self._data)
  File "/home/pearl/alumnimgmtsystem/env/lib/python3.12/site-packages/pymysql/err.py", line 150, in raise_mysql_exception
    raise errorclass(errno, errval)
pymysql.err.OperationalError: (1045, "Access denied for user '_9a54aa6450761df8'@'localhost' (using password: YES)")
2025-04-19 16:46:00,204 ERROR scheduler Exception in Enqueue Events for Site library.localhost
Traceback (most recent call last):
  File "/home/pearl/alumnimgmtsystem/apps/frappe/frappe/utils/scheduler.py", line 117, in enqueue_events_for_site
    if is_scheduler_inactive():
       ^^^^^^^^^^^^^^^^^^^^^^^
  File "/home/pearl/alumnimgmtsystem/apps/frappe/frappe/utils/scheduler.py", line 161, in is_scheduler_inactive
    if is_scheduler_disabled(verbose=verbose):
       ^^^^^^^^^^^^^^^^^^^^^^^^^^^^^^^^^^^^^^
  File "/home/pearl/alumnimgmtsystem/apps/frappe/frappe/utils/scheduler.py", line 174, in is_scheduler_disabled
    frappe.db.get_single_value("System Settings", "enable_scheduler")
  File "/home/pearl/alumnimgmtsystem/apps/frappe/frappe/database/database.py", line 884, in get_single_value
    ).run()
      ^^^^^
  File "/home/pearl/alumnimgmtsystem/apps/frappe/frappe/query_builder/utils.py", line 80, in execute_query
    result = frappe.db.sql(query, params, *args, **kwargs)  # nosemgrep
             ^^^^^^^^^^^^^^^^^^^^^^^^^^^^^^^^^^^^^^^^^^^^^
  File "/home/pearl/alumnimgmtsystem/apps/frappe/frappe/database/database.py", line 237, in sql
    self.connect()
  File "/home/pearl/alumnimgmtsystem/apps/frappe/frappe/database/database.py", line 135, in connect
    self.get_connection()
  File "/home/pearl/alumnimgmtsystem/apps/frappe/frappe/database/mariadb/database.py", line 105, in get_connection
    conn = self._get_connection()
           ^^^^^^^^^^^^^^^^^^^^^^
  File "/home/pearl/alumnimgmtsystem/apps/frappe/frappe/database/mariadb/database.py", line 111, in _get_connection
    return self.create_connection()
           ^^^^^^^^^^^^^^^^^^^^^^^^
  File "/home/pearl/alumnimgmtsystem/apps/frappe/frappe/database/mariadb/database.py", line 114, in create_connection
    return pymysql.connect(**self.get_connection_settings())
           ^^^^^^^^^^^^^^^^^^^^^^^^^^^^^^^^^^^^^^^^^^^^^^^^^
  File "/home/pearl/alumnimgmtsystem/env/lib/python3.12/site-packages/pymysql/connections.py", line 361, in __init__
    self.connect()
  File "/home/pearl/alumnimgmtsystem/env/lib/python3.12/site-packages/pymysql/connections.py", line 669, in connect
    self._request_authentication()
  File "/home/pearl/alumnimgmtsystem/env/lib/python3.12/site-packages/pymysql/connections.py", line 957, in _request_authentication
    auth_packet = self._read_packet()
                  ^^^^^^^^^^^^^^^^^^^
  File "/home/pearl/alumnimgmtsystem/env/lib/python3.12/site-packages/pymysql/connections.py", line 775, in _read_packet
    packet.raise_for_error()
  File "/home/pearl/alumnimgmtsystem/env/lib/python3.12/site-packages/pymysql/protocol.py", line 219, in raise_for_error
    err.raise_mysql_exception(self._data)
  File "/home/pearl/alumnimgmtsystem/env/lib/python3.12/site-packages/pymysql/err.py", line 150, in raise_mysql_exception
    raise errorclass(errno, errval)
pymysql.err.OperationalError: (1045, "Access denied for user '_9a54aa6450761df8'@'localhost' (using password: YES)")
2025-04-19 16:50:00,499 ERROR scheduler Exception in Enqueue Events for Site library.localhost
Traceback (most recent call last):
  File "/home/pearl/alumnimgmtsystem/apps/frappe/frappe/utils/scheduler.py", line 117, in enqueue_events_for_site
    if is_scheduler_inactive():
       ^^^^^^^^^^^^^^^^^^^^^^^
  File "/home/pearl/alumnimgmtsystem/apps/frappe/frappe/utils/scheduler.py", line 161, in is_scheduler_inactive
    if is_scheduler_disabled(verbose=verbose):
       ^^^^^^^^^^^^^^^^^^^^^^^^^^^^^^^^^^^^^^
  File "/home/pearl/alumnimgmtsystem/apps/frappe/frappe/utils/scheduler.py", line 174, in is_scheduler_disabled
    frappe.db.get_single_value("System Settings", "enable_scheduler")
  File "/home/pearl/alumnimgmtsystem/apps/frappe/frappe/database/database.py", line 884, in get_single_value
    ).run()
      ^^^^^
  File "/home/pearl/alumnimgmtsystem/apps/frappe/frappe/query_builder/utils.py", line 80, in execute_query
    result = frappe.db.sql(query, params, *args, **kwargs)  # nosemgrep
             ^^^^^^^^^^^^^^^^^^^^^^^^^^^^^^^^^^^^^^^^^^^^^
  File "/home/pearl/alumnimgmtsystem/apps/frappe/frappe/database/database.py", line 237, in sql
    self.connect()
  File "/home/pearl/alumnimgmtsystem/apps/frappe/frappe/database/database.py", line 135, in connect
    self.get_connection()
  File "/home/pearl/alumnimgmtsystem/apps/frappe/frappe/database/mariadb/database.py", line 105, in get_connection
    conn = self._get_connection()
           ^^^^^^^^^^^^^^^^^^^^^^
  File "/home/pearl/alumnimgmtsystem/apps/frappe/frappe/database/mariadb/database.py", line 111, in _get_connection
    return self.create_connection()
           ^^^^^^^^^^^^^^^^^^^^^^^^
  File "/home/pearl/alumnimgmtsystem/apps/frappe/frappe/database/mariadb/database.py", line 114, in create_connection
    return pymysql.connect(**self.get_connection_settings())
           ^^^^^^^^^^^^^^^^^^^^^^^^^^^^^^^^^^^^^^^^^^^^^^^^^
  File "/home/pearl/alumnimgmtsystem/env/lib/python3.12/site-packages/pymysql/connections.py", line 361, in __init__
    self.connect()
  File "/home/pearl/alumnimgmtsystem/env/lib/python3.12/site-packages/pymysql/connections.py", line 669, in connect
    self._request_authentication()
  File "/home/pearl/alumnimgmtsystem/env/lib/python3.12/site-packages/pymysql/connections.py", line 957, in _request_authentication
    auth_packet = self._read_packet()
                  ^^^^^^^^^^^^^^^^^^^
  File "/home/pearl/alumnimgmtsystem/env/lib/python3.12/site-packages/pymysql/connections.py", line 775, in _read_packet
    packet.raise_for_error()
  File "/home/pearl/alumnimgmtsystem/env/lib/python3.12/site-packages/pymysql/protocol.py", line 219, in raise_for_error
    err.raise_mysql_exception(self._data)
  File "/home/pearl/alumnimgmtsystem/env/lib/python3.12/site-packages/pymysql/err.py", line 150, in raise_mysql_exception
    raise errorclass(errno, errval)
pymysql.err.OperationalError: (1045, "Access denied for user '_9a54aa6450761df8'@'localhost' (using password: YES)")
2025-04-19 16:54:00,662 ERROR scheduler Exception in Enqueue Events for Site library.localhost
Traceback (most recent call last):
  File "/home/pearl/alumnimgmtsystem/apps/frappe/frappe/utils/scheduler.py", line 117, in enqueue_events_for_site
    if is_scheduler_inactive():
       ^^^^^^^^^^^^^^^^^^^^^^^
  File "/home/pearl/alumnimgmtsystem/apps/frappe/frappe/utils/scheduler.py", line 161, in is_scheduler_inactive
    if is_scheduler_disabled(verbose=verbose):
       ^^^^^^^^^^^^^^^^^^^^^^^^^^^^^^^^^^^^^^
  File "/home/pearl/alumnimgmtsystem/apps/frappe/frappe/utils/scheduler.py", line 174, in is_scheduler_disabled
    frappe.db.get_single_value("System Settings", "enable_scheduler")
  File "/home/pearl/alumnimgmtsystem/apps/frappe/frappe/database/database.py", line 884, in get_single_value
    ).run()
      ^^^^^
  File "/home/pearl/alumnimgmtsystem/apps/frappe/frappe/query_builder/utils.py", line 80, in execute_query
    result = frappe.db.sql(query, params, *args, **kwargs)  # nosemgrep
             ^^^^^^^^^^^^^^^^^^^^^^^^^^^^^^^^^^^^^^^^^^^^^
  File "/home/pearl/alumnimgmtsystem/apps/frappe/frappe/database/database.py", line 237, in sql
    self.connect()
  File "/home/pearl/alumnimgmtsystem/apps/frappe/frappe/database/database.py", line 135, in connect
    self.get_connection()
  File "/home/pearl/alumnimgmtsystem/apps/frappe/frappe/database/mariadb/database.py", line 105, in get_connection
    conn = self._get_connection()
           ^^^^^^^^^^^^^^^^^^^^^^
  File "/home/pearl/alumnimgmtsystem/apps/frappe/frappe/database/mariadb/database.py", line 111, in _get_connection
    return self.create_connection()
           ^^^^^^^^^^^^^^^^^^^^^^^^
  File "/home/pearl/alumnimgmtsystem/apps/frappe/frappe/database/mariadb/database.py", line 114, in create_connection
    return pymysql.connect(**self.get_connection_settings())
           ^^^^^^^^^^^^^^^^^^^^^^^^^^^^^^^^^^^^^^^^^^^^^^^^^
  File "/home/pearl/alumnimgmtsystem/env/lib/python3.12/site-packages/pymysql/connections.py", line 361, in __init__
    self.connect()
  File "/home/pearl/alumnimgmtsystem/env/lib/python3.12/site-packages/pymysql/connections.py", line 669, in connect
    self._request_authentication()
  File "/home/pearl/alumnimgmtsystem/env/lib/python3.12/site-packages/pymysql/connections.py", line 957, in _request_authentication
    auth_packet = self._read_packet()
                  ^^^^^^^^^^^^^^^^^^^
  File "/home/pearl/alumnimgmtsystem/env/lib/python3.12/site-packages/pymysql/connections.py", line 775, in _read_packet
    packet.raise_for_error()
  File "/home/pearl/alumnimgmtsystem/env/lib/python3.12/site-packages/pymysql/protocol.py", line 219, in raise_for_error
    err.raise_mysql_exception(self._data)
  File "/home/pearl/alumnimgmtsystem/env/lib/python3.12/site-packages/pymysql/err.py", line 150, in raise_mysql_exception
    raise errorclass(errno, errval)
pymysql.err.OperationalError: (1045, "Access denied for user '_9a54aa6450761df8'@'localhost' (using password: YES)")
2025-04-19 16:58:00,748 ERROR scheduler Exception in Enqueue Events for Site library.localhost
Traceback (most recent call last):
  File "/home/pearl/alumnimgmtsystem/apps/frappe/frappe/utils/scheduler.py", line 117, in enqueue_events_for_site
    if is_scheduler_inactive():
       ^^^^^^^^^^^^^^^^^^^^^^^
  File "/home/pearl/alumnimgmtsystem/apps/frappe/frappe/utils/scheduler.py", line 161, in is_scheduler_inactive
    if is_scheduler_disabled(verbose=verbose):
       ^^^^^^^^^^^^^^^^^^^^^^^^^^^^^^^^^^^^^^
  File "/home/pearl/alumnimgmtsystem/apps/frappe/frappe/utils/scheduler.py", line 174, in is_scheduler_disabled
    frappe.db.get_single_value("System Settings", "enable_scheduler")
  File "/home/pearl/alumnimgmtsystem/apps/frappe/frappe/database/database.py", line 884, in get_single_value
    ).run()
      ^^^^^
  File "/home/pearl/alumnimgmtsystem/apps/frappe/frappe/query_builder/utils.py", line 80, in execute_query
    result = frappe.db.sql(query, params, *args, **kwargs)  # nosemgrep
             ^^^^^^^^^^^^^^^^^^^^^^^^^^^^^^^^^^^^^^^^^^^^^
  File "/home/pearl/alumnimgmtsystem/apps/frappe/frappe/database/database.py", line 237, in sql
    self.connect()
  File "/home/pearl/alumnimgmtsystem/apps/frappe/frappe/database/database.py", line 135, in connect
    self.get_connection()
  File "/home/pearl/alumnimgmtsystem/apps/frappe/frappe/database/mariadb/database.py", line 105, in get_connection
    conn = self._get_connection()
           ^^^^^^^^^^^^^^^^^^^^^^
  File "/home/pearl/alumnimgmtsystem/apps/frappe/frappe/database/mariadb/database.py", line 111, in _get_connection
    return self.create_connection()
           ^^^^^^^^^^^^^^^^^^^^^^^^
  File "/home/pearl/alumnimgmtsystem/apps/frappe/frappe/database/mariadb/database.py", line 114, in create_connection
    return pymysql.connect(**self.get_connection_settings())
           ^^^^^^^^^^^^^^^^^^^^^^^^^^^^^^^^^^^^^^^^^^^^^^^^^
  File "/home/pearl/alumnimgmtsystem/env/lib/python3.12/site-packages/pymysql/connections.py", line 361, in __init__
    self.connect()
  File "/home/pearl/alumnimgmtsystem/env/lib/python3.12/site-packages/pymysql/connections.py", line 669, in connect
    self._request_authentication()
  File "/home/pearl/alumnimgmtsystem/env/lib/python3.12/site-packages/pymysql/connections.py", line 957, in _request_authentication
    auth_packet = self._read_packet()
                  ^^^^^^^^^^^^^^^^^^^
  File "/home/pearl/alumnimgmtsystem/env/lib/python3.12/site-packages/pymysql/connections.py", line 775, in _read_packet
    packet.raise_for_error()
  File "/home/pearl/alumnimgmtsystem/env/lib/python3.12/site-packages/pymysql/protocol.py", line 219, in raise_for_error
    err.raise_mysql_exception(self._data)
  File "/home/pearl/alumnimgmtsystem/env/lib/python3.12/site-packages/pymysql/err.py", line 150, in raise_mysql_exception
    raise errorclass(errno, errval)
pymysql.err.OperationalError: (1045, "Access denied for user '_9a54aa6450761df8'@'localhost' (using password: YES)")
2025-04-19 17:02:00,642 ERROR scheduler Exception in Enqueue Events for Site library.localhost
Traceback (most recent call last):
  File "/home/pearl/alumnimgmtsystem/apps/frappe/frappe/utils/scheduler.py", line 117, in enqueue_events_for_site
    if is_scheduler_inactive():
       ^^^^^^^^^^^^^^^^^^^^^^^
  File "/home/pearl/alumnimgmtsystem/apps/frappe/frappe/utils/scheduler.py", line 161, in is_scheduler_inactive
    if is_scheduler_disabled(verbose=verbose):
       ^^^^^^^^^^^^^^^^^^^^^^^^^^^^^^^^^^^^^^
  File "/home/pearl/alumnimgmtsystem/apps/frappe/frappe/utils/scheduler.py", line 174, in is_scheduler_disabled
    frappe.db.get_single_value("System Settings", "enable_scheduler")
  File "/home/pearl/alumnimgmtsystem/apps/frappe/frappe/database/database.py", line 884, in get_single_value
    ).run()
      ^^^^^
  File "/home/pearl/alumnimgmtsystem/apps/frappe/frappe/query_builder/utils.py", line 80, in execute_query
    result = frappe.db.sql(query, params, *args, **kwargs)  # nosemgrep
             ^^^^^^^^^^^^^^^^^^^^^^^^^^^^^^^^^^^^^^^^^^^^^
  File "/home/pearl/alumnimgmtsystem/apps/frappe/frappe/database/database.py", line 237, in sql
    self.connect()
  File "/home/pearl/alumnimgmtsystem/apps/frappe/frappe/database/database.py", line 135, in connect
    self.get_connection()
  File "/home/pearl/alumnimgmtsystem/apps/frappe/frappe/database/mariadb/database.py", line 105, in get_connection
    conn = self._get_connection()
           ^^^^^^^^^^^^^^^^^^^^^^
  File "/home/pearl/alumnimgmtsystem/apps/frappe/frappe/database/mariadb/database.py", line 111, in _get_connection
    return self.create_connection()
           ^^^^^^^^^^^^^^^^^^^^^^^^
  File "/home/pearl/alumnimgmtsystem/apps/frappe/frappe/database/mariadb/database.py", line 114, in create_connection
    return pymysql.connect(**self.get_connection_settings())
           ^^^^^^^^^^^^^^^^^^^^^^^^^^^^^^^^^^^^^^^^^^^^^^^^^
  File "/home/pearl/alumnimgmtsystem/env/lib/python3.12/site-packages/pymysql/connections.py", line 361, in __init__
    self.connect()
  File "/home/pearl/alumnimgmtsystem/env/lib/python3.12/site-packages/pymysql/connections.py", line 669, in connect
    self._request_authentication()
  File "/home/pearl/alumnimgmtsystem/env/lib/python3.12/site-packages/pymysql/connections.py", line 957, in _request_authentication
    auth_packet = self._read_packet()
                  ^^^^^^^^^^^^^^^^^^^
  File "/home/pearl/alumnimgmtsystem/env/lib/python3.12/site-packages/pymysql/connections.py", line 775, in _read_packet
    packet.raise_for_error()
  File "/home/pearl/alumnimgmtsystem/env/lib/python3.12/site-packages/pymysql/protocol.py", line 219, in raise_for_error
    err.raise_mysql_exception(self._data)
  File "/home/pearl/alumnimgmtsystem/env/lib/python3.12/site-packages/pymysql/err.py", line 150, in raise_mysql_exception
    raise errorclass(errno, errval)
pymysql.err.OperationalError: (1045, "Access denied for user '_9a54aa6450761df8'@'localhost' (using password: YES)")
2025-04-19 17:06:00,133 ERROR scheduler Exception in Enqueue Events for Site library.localhost
Traceback (most recent call last):
  File "/home/pearl/alumnimgmtsystem/apps/frappe/frappe/utils/scheduler.py", line 117, in enqueue_events_for_site
    if is_scheduler_inactive():
       ^^^^^^^^^^^^^^^^^^^^^^^
  File "/home/pearl/alumnimgmtsystem/apps/frappe/frappe/utils/scheduler.py", line 161, in is_scheduler_inactive
    if is_scheduler_disabled(verbose=verbose):
       ^^^^^^^^^^^^^^^^^^^^^^^^^^^^^^^^^^^^^^
  File "/home/pearl/alumnimgmtsystem/apps/frappe/frappe/utils/scheduler.py", line 174, in is_scheduler_disabled
    frappe.db.get_single_value("System Settings", "enable_scheduler")
  File "/home/pearl/alumnimgmtsystem/apps/frappe/frappe/database/database.py", line 884, in get_single_value
    ).run()
      ^^^^^
  File "/home/pearl/alumnimgmtsystem/apps/frappe/frappe/query_builder/utils.py", line 80, in execute_query
    result = frappe.db.sql(query, params, *args, **kwargs)  # nosemgrep
             ^^^^^^^^^^^^^^^^^^^^^^^^^^^^^^^^^^^^^^^^^^^^^
  File "/home/pearl/alumnimgmtsystem/apps/frappe/frappe/database/database.py", line 237, in sql
    self.connect()
  File "/home/pearl/alumnimgmtsystem/apps/frappe/frappe/database/database.py", line 135, in connect
    self.get_connection()
  File "/home/pearl/alumnimgmtsystem/apps/frappe/frappe/database/mariadb/database.py", line 105, in get_connection
    conn = self._get_connection()
           ^^^^^^^^^^^^^^^^^^^^^^
  File "/home/pearl/alumnimgmtsystem/apps/frappe/frappe/database/mariadb/database.py", line 111, in _get_connection
    return self.create_connection()
           ^^^^^^^^^^^^^^^^^^^^^^^^
  File "/home/pearl/alumnimgmtsystem/apps/frappe/frappe/database/mariadb/database.py", line 114, in create_connection
    return pymysql.connect(**self.get_connection_settings())
           ^^^^^^^^^^^^^^^^^^^^^^^^^^^^^^^^^^^^^^^^^^^^^^^^^
  File "/home/pearl/alumnimgmtsystem/env/lib/python3.12/site-packages/pymysql/connections.py", line 361, in __init__
    self.connect()
  File "/home/pearl/alumnimgmtsystem/env/lib/python3.12/site-packages/pymysql/connections.py", line 669, in connect
    self._request_authentication()
  File "/home/pearl/alumnimgmtsystem/env/lib/python3.12/site-packages/pymysql/connections.py", line 957, in _request_authentication
    auth_packet = self._read_packet()
                  ^^^^^^^^^^^^^^^^^^^
  File "/home/pearl/alumnimgmtsystem/env/lib/python3.12/site-packages/pymysql/connections.py", line 775, in _read_packet
    packet.raise_for_error()
  File "/home/pearl/alumnimgmtsystem/env/lib/python3.12/site-packages/pymysql/protocol.py", line 219, in raise_for_error
    err.raise_mysql_exception(self._data)
  File "/home/pearl/alumnimgmtsystem/env/lib/python3.12/site-packages/pymysql/err.py", line 150, in raise_mysql_exception
    raise errorclass(errno, errval)
pymysql.err.OperationalError: (1045, "Access denied for user '_9a54aa6450761df8'@'localhost' (using password: YES)")
2025-04-19 17:10:01,535 ERROR scheduler Exception in Enqueue Events for Site library.localhost
Traceback (most recent call last):
  File "/home/pearl/alumnimgmtsystem/apps/frappe/frappe/utils/scheduler.py", line 117, in enqueue_events_for_site
    if is_scheduler_inactive():
       ^^^^^^^^^^^^^^^^^^^^^^^
  File "/home/pearl/alumnimgmtsystem/apps/frappe/frappe/utils/scheduler.py", line 161, in is_scheduler_inactive
    if is_scheduler_disabled(verbose=verbose):
       ^^^^^^^^^^^^^^^^^^^^^^^^^^^^^^^^^^^^^^
  File "/home/pearl/alumnimgmtsystem/apps/frappe/frappe/utils/scheduler.py", line 174, in is_scheduler_disabled
    frappe.db.get_single_value("System Settings", "enable_scheduler")
  File "/home/pearl/alumnimgmtsystem/apps/frappe/frappe/database/database.py", line 884, in get_single_value
    ).run()
      ^^^^^
  File "/home/pearl/alumnimgmtsystem/apps/frappe/frappe/query_builder/utils.py", line 80, in execute_query
    result = frappe.db.sql(query, params, *args, **kwargs)  # nosemgrep
             ^^^^^^^^^^^^^^^^^^^^^^^^^^^^^^^^^^^^^^^^^^^^^
  File "/home/pearl/alumnimgmtsystem/apps/frappe/frappe/database/database.py", line 237, in sql
    self.connect()
  File "/home/pearl/alumnimgmtsystem/apps/frappe/frappe/database/database.py", line 135, in connect
    self.get_connection()
  File "/home/pearl/alumnimgmtsystem/apps/frappe/frappe/database/mariadb/database.py", line 105, in get_connection
    conn = self._get_connection()
           ^^^^^^^^^^^^^^^^^^^^^^
  File "/home/pearl/alumnimgmtsystem/apps/frappe/frappe/database/mariadb/database.py", line 111, in _get_connection
    return self.create_connection()
           ^^^^^^^^^^^^^^^^^^^^^^^^
  File "/home/pearl/alumnimgmtsystem/apps/frappe/frappe/database/mariadb/database.py", line 114, in create_connection
    return pymysql.connect(**self.get_connection_settings())
           ^^^^^^^^^^^^^^^^^^^^^^^^^^^^^^^^^^^^^^^^^^^^^^^^^
  File "/home/pearl/alumnimgmtsystem/env/lib/python3.12/site-packages/pymysql/connections.py", line 361, in __init__
    self.connect()
  File "/home/pearl/alumnimgmtsystem/env/lib/python3.12/site-packages/pymysql/connections.py", line 669, in connect
    self._request_authentication()
  File "/home/pearl/alumnimgmtsystem/env/lib/python3.12/site-packages/pymysql/connections.py", line 957, in _request_authentication
    auth_packet = self._read_packet()
                  ^^^^^^^^^^^^^^^^^^^
  File "/home/pearl/alumnimgmtsystem/env/lib/python3.12/site-packages/pymysql/connections.py", line 775, in _read_packet
    packet.raise_for_error()
  File "/home/pearl/alumnimgmtsystem/env/lib/python3.12/site-packages/pymysql/protocol.py", line 219, in raise_for_error
    err.raise_mysql_exception(self._data)
  File "/home/pearl/alumnimgmtsystem/env/lib/python3.12/site-packages/pymysql/err.py", line 150, in raise_mysql_exception
    raise errorclass(errno, errval)
pymysql.err.OperationalError: (1045, "Access denied for user '_9a54aa6450761df8'@'localhost' (using password: YES)")
2025-04-19 17:14:00,618 ERROR scheduler Exception in Enqueue Events for Site library.localhost
Traceback (most recent call last):
  File "/home/pearl/alumnimgmtsystem/apps/frappe/frappe/utils/scheduler.py", line 117, in enqueue_events_for_site
    if is_scheduler_inactive():
       ^^^^^^^^^^^^^^^^^^^^^^^
  File "/home/pearl/alumnimgmtsystem/apps/frappe/frappe/utils/scheduler.py", line 161, in is_scheduler_inactive
    if is_scheduler_disabled(verbose=verbose):
       ^^^^^^^^^^^^^^^^^^^^^^^^^^^^^^^^^^^^^^
  File "/home/pearl/alumnimgmtsystem/apps/frappe/frappe/utils/scheduler.py", line 174, in is_scheduler_disabled
    frappe.db.get_single_value("System Settings", "enable_scheduler")
  File "/home/pearl/alumnimgmtsystem/apps/frappe/frappe/database/database.py", line 884, in get_single_value
    ).run()
      ^^^^^
  File "/home/pearl/alumnimgmtsystem/apps/frappe/frappe/query_builder/utils.py", line 80, in execute_query
    result = frappe.db.sql(query, params, *args, **kwargs)  # nosemgrep
             ^^^^^^^^^^^^^^^^^^^^^^^^^^^^^^^^^^^^^^^^^^^^^
  File "/home/pearl/alumnimgmtsystem/apps/frappe/frappe/database/database.py", line 237, in sql
    self.connect()
  File "/home/pearl/alumnimgmtsystem/apps/frappe/frappe/database/database.py", line 135, in connect
    self.get_connection()
  File "/home/pearl/alumnimgmtsystem/apps/frappe/frappe/database/mariadb/database.py", line 105, in get_connection
    conn = self._get_connection()
           ^^^^^^^^^^^^^^^^^^^^^^
  File "/home/pearl/alumnimgmtsystem/apps/frappe/frappe/database/mariadb/database.py", line 111, in _get_connection
    return self.create_connection()
           ^^^^^^^^^^^^^^^^^^^^^^^^
  File "/home/pearl/alumnimgmtsystem/apps/frappe/frappe/database/mariadb/database.py", line 114, in create_connection
    return pymysql.connect(**self.get_connection_settings())
           ^^^^^^^^^^^^^^^^^^^^^^^^^^^^^^^^^^^^^^^^^^^^^^^^^
  File "/home/pearl/alumnimgmtsystem/env/lib/python3.12/site-packages/pymysql/connections.py", line 361, in __init__
    self.connect()
  File "/home/pearl/alumnimgmtsystem/env/lib/python3.12/site-packages/pymysql/connections.py", line 669, in connect
    self._request_authentication()
  File "/home/pearl/alumnimgmtsystem/env/lib/python3.12/site-packages/pymysql/connections.py", line 957, in _request_authentication
    auth_packet = self._read_packet()
                  ^^^^^^^^^^^^^^^^^^^
  File "/home/pearl/alumnimgmtsystem/env/lib/python3.12/site-packages/pymysql/connections.py", line 775, in _read_packet
    packet.raise_for_error()
  File "/home/pearl/alumnimgmtsystem/env/lib/python3.12/site-packages/pymysql/protocol.py", line 219, in raise_for_error
    err.raise_mysql_exception(self._data)
  File "/home/pearl/alumnimgmtsystem/env/lib/python3.12/site-packages/pymysql/err.py", line 150, in raise_mysql_exception
    raise errorclass(errno, errval)
pymysql.err.OperationalError: (1045, "Access denied for user '_9a54aa6450761df8'@'localhost' (using password: YES)")
2025-04-19 17:18:01,129 ERROR scheduler Exception in Enqueue Events for Site library.localhost
Traceback (most recent call last):
  File "/home/pearl/alumnimgmtsystem/apps/frappe/frappe/utils/scheduler.py", line 117, in enqueue_events_for_site
    if is_scheduler_inactive():
       ^^^^^^^^^^^^^^^^^^^^^^^
  File "/home/pearl/alumnimgmtsystem/apps/frappe/frappe/utils/scheduler.py", line 161, in is_scheduler_inactive
    if is_scheduler_disabled(verbose=verbose):
       ^^^^^^^^^^^^^^^^^^^^^^^^^^^^^^^^^^^^^^
  File "/home/pearl/alumnimgmtsystem/apps/frappe/frappe/utils/scheduler.py", line 174, in is_scheduler_disabled
    frappe.db.get_single_value("System Settings", "enable_scheduler")
  File "/home/pearl/alumnimgmtsystem/apps/frappe/frappe/database/database.py", line 884, in get_single_value
    ).run()
      ^^^^^
  File "/home/pearl/alumnimgmtsystem/apps/frappe/frappe/query_builder/utils.py", line 80, in execute_query
    result = frappe.db.sql(query, params, *args, **kwargs)  # nosemgrep
             ^^^^^^^^^^^^^^^^^^^^^^^^^^^^^^^^^^^^^^^^^^^^^
  File "/home/pearl/alumnimgmtsystem/apps/frappe/frappe/database/database.py", line 237, in sql
    self.connect()
  File "/home/pearl/alumnimgmtsystem/apps/frappe/frappe/database/database.py", line 135, in connect
    self.get_connection()
  File "/home/pearl/alumnimgmtsystem/apps/frappe/frappe/database/mariadb/database.py", line 105, in get_connection
    conn = self._get_connection()
           ^^^^^^^^^^^^^^^^^^^^^^
  File "/home/pearl/alumnimgmtsystem/apps/frappe/frappe/database/mariadb/database.py", line 111, in _get_connection
    return self.create_connection()
           ^^^^^^^^^^^^^^^^^^^^^^^^
  File "/home/pearl/alumnimgmtsystem/apps/frappe/frappe/database/mariadb/database.py", line 114, in create_connection
    return pymysql.connect(**self.get_connection_settings())
           ^^^^^^^^^^^^^^^^^^^^^^^^^^^^^^^^^^^^^^^^^^^^^^^^^
  File "/home/pearl/alumnimgmtsystem/env/lib/python3.12/site-packages/pymysql/connections.py", line 361, in __init__
    self.connect()
  File "/home/pearl/alumnimgmtsystem/env/lib/python3.12/site-packages/pymysql/connections.py", line 669, in connect
    self._request_authentication()
  File "/home/pearl/alumnimgmtsystem/env/lib/python3.12/site-packages/pymysql/connections.py", line 957, in _request_authentication
    auth_packet = self._read_packet()
                  ^^^^^^^^^^^^^^^^^^^
  File "/home/pearl/alumnimgmtsystem/env/lib/python3.12/site-packages/pymysql/connections.py", line 775, in _read_packet
    packet.raise_for_error()
  File "/home/pearl/alumnimgmtsystem/env/lib/python3.12/site-packages/pymysql/protocol.py", line 219, in raise_for_error
    err.raise_mysql_exception(self._data)
  File "/home/pearl/alumnimgmtsystem/env/lib/python3.12/site-packages/pymysql/err.py", line 150, in raise_mysql_exception
    raise errorclass(errno, errval)
pymysql.err.OperationalError: (1045, "Access denied for user '_9a54aa6450761df8'@'localhost' (using password: YES)")
2025-04-19 18:58:00,936 ERROR scheduler Skipped queueing frappe.email.queue.flush because it was found in queue for alumnimgmt.localhost
